Workbook
Name SailCrest: SailCrest!$A$1:$Y$135
Name SailCrest_BCCN: SailCrest_BCCN!$A$1:$Y$135
Name SailPattern: SailPattern!$A$1:$AE$80
Name SailPatternColor: SailPatternColor!$A$1:$X$129
Name ShipAnchorColor: ShipAnchorColor!$A$1:$R$99
Name ShipBodyFirstColor: ShipBodyFirstColor!$A$1:$X$99
Name ShipBodySecondColor: ShipBodySecondColor!$A$1:$X$99
Name ShipBodyShape: ShipBodyShape!$A$1:$AX$382
Name ShipFigureheadColor: ShipFigureheadColor!$A$1:$R$99
Name ShipFxShape: ShipFxShape!$A$1:$W$94
Name ShipPartShape: ShipFxShape!$A$1:$M$94
Name ShipPartShape: ShipPartShape!$A$1:$AA$836
Name ShipRamColor: ShipRamColor!$A$1:$R$99
Name ShipWakeFX: ShipWakeFX!$A$1:$L$24

Sheet ShipBodyShape
A1: id | C1: meshName | E1: meshDensity | F1: buoyancyRadius | G1: buoyancyOffsetZ["sail"] | H1: buoyancyOffsetZ["display"] | I1: parts["0"] | K1: parts["1"] | M1: parts["2"] | O1: parts["3"] | Q1: parts["4"] | S1: parts["5"] | U1: parts["6"] | W1: parts["7"] | Y1: parts["8"] | AA1: parts["9"] | AC1: parts["10"] | AE1: parts["11"] | AG1: parts["12"] | AI1: parts["13"] | AJ1: colorTint | AK1: color1 | AL1: color2 | AM1: materials[0]["index"] | AN1: materials[0]["name"] | AO1: materials[1]["index"] | AP1: materials[1]["name"] | AQ1: materials[2]["index"] | AR1: materials[2]["name"] | AS1: materials[3]["index"] | AT1: materials[3]["name"] | AU1: wakePlayer | AV1: wakeNPC | AW1: wakeCutscene | AX1: overrideMeshScale
A2: key:45000000~45999999 | C2: string | E2: number | F2: number | G2: number | H2: number | I2: number | K2: number | M2: number | O2: number | Q2: number | S2: number | U2: number | W2: number | Y2: number | AA2: number | AC2: number | AE2: number | AG2: number | AI2: number | AJ2: number | AK2: number | AL2: number | AM2: number | AN2: string | AO2: number | AP2: string | AQ2: number | AR2: string | AS2: number | AT2: string | AU2: number | AV2: number | AW2: number | AX2: number
A3: :required | B3: - | C3: 1 | D3: - | E3: - | F3: - | G3: - | H3: - | I3: - | J3: - | K3: - | L3: - | M3: - | N3: - | O3: - | P3: - | Q3: - | R3: - | S3: - | T3: - | U3: - | W3: - | Y3: - | AA3: - | AC3: - | AE3: - | AG3: - | AI3: - | AJ3: - | AK3: - | AL3: - | AM3: - | AN3: - | AO3: - | AP3: - | AQ3: - | AR3: - | AS3: - | AT3: - | AU3: - | AV3: - | AW3: - | AX3: -
A4: :requireedInObject | B4: - | C4: - | D4: - | E4: - | F4: - | G4: - | H4: - | I4: 1 | J4: - | K4: 1 | L4: - | M4: 1 | N4: - | O4: 1 | P4: - | Q4: 1 | R4: - | S4: 1 | T4: - | U4: 1 | W4: 1 | Y4: 1 | AA4: 1 | AC4: 1 | AE4: 1 | AG4: 1 | AI4: 1 | AJ4: - | AK4: - | AL4: - | AM4: 1 | AN4: 1 | AO4: 1 | AP4: 1 | AQ4: 1 | AR4: 1 | AS4: 1 | AT4: 1 | AU4: - | AV4: - | AW4: - | AX4: -
A5: :min | B5: - | C5: - | D5: - | E5: 10 | F5: 10 | G5: - | H5: - | I5: - | J5: - | K5: - | L5: - | M5: - | N5: - | O5: - | P5: - | Q5: - | R5: - | S5: - | T5: - | U5: - | W5: - | Y5: - | AA5: - | AC5: - | AE5: - | AG5: - | AI5: - | AJ5: - | AK5: - | AL5: - | AM5: - | AN5: - | AO5: - | AP5: - | AQ5: - | AR5: - | AS5: - | AT5: - | AU5: - | AV5: - | AW5: - | AX5: -
A6: :max | B6: - | C6: - | D6: - | E6: 1000 | F6: 1000 | G6: - | H6: - | I6: - | J6: - | K6: - | L6: - | M6: - | N6: - | O6: - | P6: - | Q6: - | R6: - | S6: - | T6: - | U6: - | W6: - | Y6: - | AA6: - | AC6: - | AE6: - | AG6: - | AI6: - | AJ6: - | AK6: - | AL6: - | AM6: - | AN6: - | AO6: - | AP6: - | AQ6: - | AR6: - | AS6: - | AT6: - | AU6: - | AV6: - | AW6: - | AX6: -
A7: :enum | B7: - | C7: - | D7: - | E7: - | F7: - | G7: - | H7: - | I7: - | J7: - | K7: - | L7: - | M7: - | N7: - | O7: - | P7: - | Q7: - | R7: - | S7: - | T7: - | U7: - | W7: - | Y7: - | AA7: - | AC7: - | AE7: - | AG7: - | AI7: - | AJ7: - | AK7: - | AL7: - | AM7: - | AN7: - | AO7: - | AP7: - | AQ7: - | AR7: - | AS7: - | AT7: - | AU7: - | AV7: - | AW7: - | AX7: -
A8: :links | B8: - | C8: - | D8: - | E8: - | F8: - | G8: - | H8: - | I8: "ShipPartShape" | J8: - | K8: "ShipPartShape" | L8: - | M8: "ShipPartShape" | N8: - | O8: "ShipPartShape" | P8: - | Q8: "ShipPartShape" | R8: - | S8: "ShipPartShape" | T8: - | U8: "ShipPartShape" | W8: "ShipPartShape" | Y8: "ShipPartShape" | AA8: "ShipPartShape" | AC8: "ShipPartShape" | AE8: "ShipPartShape" | AG8: "ShipPartShape" | AI8: "ShipPartShape" | AJ8: - | AK8: - | AL8: - | AM8: - | AN8: - | AO8: - | AP8: - | AQ8: - | AR8: - | AS8: - | AT8: - | AU8: "ShipWakeFX" | AV8: "ShipWakeFX" | AW8: "ShipWakeFX" | AX8: -
A9: :asset | B9: - | C9: 1 | D9: - | E9: - | F9: - | G9: - | H9: - | I9: - | J9: - | K9: - | L9: - | M9: - | N9: - | O9: - | P9: - | Q9: - | R9: - | S9: - | T9: - | U9: - | W9: - | Y9: - | AA9: - | AC9: - | AE9: - | AG9: - | AI9: - | AJ9: - | AK9: - | AL9: - | AM9: - | AN9: 1 | AO9: - | AP9: 1 | AQ9: - | AR9: 1 | AS9: - | AT9: 1 | AU9: - | AV9: - | AW9: - | AX9: -
A10: 45000000 | B10: 중 캐러벨 | C10: SK_Ship_Caravel_Body | D10: 캐러벨흰색돛 | E10: 700 | F10: 100 | G10: 10 | H10: -40 | I10: =IFERROR(INDEX(ShipPartShape!$A:$A,MATCH(D10,ShipPartShape!$B:$B,0)),"-") -> 46000001 | J10: 램프_기본 | K10: =IFERROR(INDEX(ShipPartShape!$A:$A,MATCH(J10,ShipPartShape!$B:$B,0)),"-") -> 46700001 | L10: 대포_기본 | M10: =IFERROR(INDEX(ShipPartShape!$A:$A,MATCH(L10,ShipPartShape!$B:$B,0)),"-") -> 46300001 | O10: =IFERROR(INDEX(ShipPartShape!$A:$A,MATCH(N10,ShipPartShape!$B:$B,0)),"-") -> - | Q10: =IFERROR(INDEX(ShipPartShape!$A:$A,MATCH(P10,ShipPartShape!$B:$B,0)),"-") -> - | S10: =IFERROR(INDEX(ShipPartShape!$A:$A,MATCH(R10,ShipPartShape!$B:$B,0)),"-") -> - | T10: 선박외형장식_C | U10: =IFERROR(INDEX(ShipPartShape!$A:$A,MATCH(T10,ShipPartShape!$B:$B,0)),"-") -> 46600003 | V10: 선박외형장식_D | W10: =IFERROR(INDEX(ShipPartShape!$A:$A,MATCH(V10,ShipPartShape!$B:$B,0)),"-") -> 46600004 | X10: 선박외형장식_E | Y10: =IFERROR(INDEX(ShipPartShape!$A:$A,MATCH(X10,ShipPartShape!$B:$B,0)),"-") -> 46600005 | Z10: 선박외형장식_G | AA10: =IFERROR(INDEX(ShipPartShape!$A:$A,MATCH(Z10,ShipPartShape!$B:$B,0)),"-") -> 46600007 | AC10: =IFERROR(INDEX(ShipPartShape!$A:$A,MATCH(AB10,ShipPartShape!$B:$B,0)),"-") -> - | AE10: =IFERROR(INDEX(ShipPartShape!$A:$A,MATCH(AD10,ShipPartShape!$B:$B,0)),"-") -> - | AG10: =IFERROR(INDEX(ShipPartShape!$A:$A,MATCH(AF10,ShipPartShape!$B:$B,0)),"-") -> - | AI10: =IFERROR(INDEX(ShipPartShape!$A:$A,MATCH(AH10,ShipPartShape!$B:$B,0)),"-") -> - | AJ10: - | AK10: - | AL10: - | AM10: - | AN10: - | AO10: - | AP10: - | AQ10: - | AR10: - | AS10: - | AT10: - | AU10: 47600016 | AV10: - | AW10: - | AX10: -
A11: =A10+1 -> 45000001 | B11: 중 캐러벨_적선 | C11: SK_Ship_Caravel_Body | D11: 캐러벨적색돛 | E11: 700 | F11: 100 | G11: - | H11: - | I11: =IFERROR(INDEX(ShipPartShape!$A:$A,MATCH(D11,ShipPartShape!$B:$B,0)),"-") -> 46000002 | J11: 대포_기본 | K11: =IFERROR(INDEX(ShipPartShape!$A:$A,MATCH(J11,ShipPartShape!$B:$B,0)),"-") -> 46300001 | L11: 램프_기본 | M11: =IFERROR(INDEX(ShipPartShape!$A:$A,MATCH(L11,ShipPartShape!$B:$B,0)),"-") -> 46700001 | O11: =IFERROR(INDEX(ShipPartShape!$A:$A,MATCH(N11,ShipPartShape!$B:$B,0)),"-") -> - | Q11: =IFERROR(INDEX(ShipPartShape!$A:$A,MATCH(P11,ShipPartShape!$B:$B,0)),"-") -> - | S11: =IFERROR(INDEX(ShipPartShape!$A:$A,MATCH(R11,ShipPartShape!$B:$B,0)),"-") -> - | U11: =IFERROR(INDEX(ShipPartShape!$A:$A,MATCH(T11,ShipPartShape!$B:$B,0)),"-") -> - | W11: =IFERROR(INDEX(ShipPartShape!$A:$A,MATCH(V11,ShipPartShape!$B:$B,0)),"-") -> - | Y11: =IFERROR(INDEX(ShipPartShape!$A:$A,MATCH(X11,ShipPartShape!$B:$B,0)),"-") -> - | AA11: =IFERROR(INDEX(ShipPartShape!$A:$A,MATCH(Z11,ShipPartShape!$B:$B,0)),"-") -> - | AC11: =IFERROR(INDEX(ShipPartShape!$A:$A,MATCH(AB11,ShipPartShape!$B:$B,0)),"-") -> - | AE11: =IFERROR(INDEX(ShipPartShape!$A:$A,MATCH(AD11,ShipPartShape!$B:$B,0)),"-") -> - | AG11: =IFERROR(INDEX(ShipPartShape!$A:$A,MATCH(AF11,ShipPartShape!$B:$B,0)),"-") -> - | AI11: =IFERROR(INDEX(ShipPartShape!$A:$A,MATCH(AH11,ShipPartShape!$B:$B,0)),"-") -> - | AJ11: - | AK11: - | AL11: - | AM11: - | AN11: - | AO11: - | AP11: - | AQ11: - | AR11: - | AS11: - | AT11: - | AU11: 47600016 | AV11: - | AW11: - | AX11: -
A12: =A11+1 -> 45000002 | B12: 중 캐러벨_유령선 | C12: SK_Ship_Caravel_Body | D12: 캐러벨유령선돛 | E12: 700 | F12: 100 | G12: - | H12: - | I12: =IFERROR(INDEX(ShipPartShape!$A:$A,MATCH(D12,ShipPartShape!$B:$B,0)),"-") -> 46000003 | J12: 독수리상 | K12: =IFERROR(INDEX(ShipPartShape!$A:$A,MATCH(J12,ShipPartShape!$B:$B,0)),"-") -> 46100002 | L12: 충각_기본 | M12: =IFERROR(INDEX(ShipPartShape!$A:$A,MATCH(L12,ShipPartShape!$B:$B,0)),"-") -> 46200001 | N12: 대포_기본 | O12: =IFERROR(INDEX(ShipPartShape!$A:$A,MATCH(N12,ShipPartShape!$B:$B,0)),"-") -> 46300001 | Q12: =IFERROR(INDEX(ShipPartShape!$A:$A,MATCH(P12,ShipPartShape!$B:$B,0)),"-") -> - | S12: =IFERROR(INDEX(ShipPartShape!$A:$A,MATCH(R12,ShipPartShape!$B:$B,0)),"-") -> - | U12: =IFERROR(INDEX(ShipPartShape!$A:$A,MATCH(T12,ShipPartShape!$B:$B,0)),"-") -> - | W12: =IFERROR(INDEX(ShipPartShape!$A:$A,MATCH(V12,ShipPartShape!$B:$B,0)),"-") -> - | Y12: =IFERROR(INDEX(ShipPartShape!$A:$A,MATCH(X12,ShipPartShape!$B:$B,0)),"-") -> - | AA12: =IFERROR(INDEX(ShipPartShape!$A:$A,MATCH(Z12,ShipPartShape!$B:$B,0)),"-") -> - | AC12: =IFERROR(INDEX(ShipPartShape!$A:$A,MATCH(AB12,ShipPartShape!$B:$B,0)),"-") -> - | AE12: =IFERROR(INDEX(ShipPartShape!$A:$A,MATCH(AD12,ShipPartShape!$B:$B,0)),"-") -> - | AG12: =IFERROR(INDEX(ShipPartShape!$A:$A,MATCH(AF12,ShipPartShape!$B:$B,0)),"-") -> - | AI12: =IFERROR(INDEX(ShipPartShape!$A:$A,MATCH(AH12,ShipPartShape!$B:$B,0)),"-") -> - | AJ12: - | AK12: - | AL12: - | AM12: - | AN12: - | AO12: - | AP12: - | AQ12: - | AR12: - | AS12: - | AT12: - | AU12: 47600016 | AV12: - | AW12: - | AX12: -
A13: =A12+1 -> 45000003 | B13: 중 캐러벨2 | C13: SK_Ship_Caravel_Body | D13: 캐러벨적백돛 | E13: 700 | F13: 100 | G13: - | H13: - | I13: =IFERROR(INDEX(ShipPartShape!$A:$A,MATCH(D13,ShipPartShape!$B:$B,0)),"-") -> 46000004 | J13: 충각_기본 | K13: =IFERROR(INDEX(ShipPartShape!$A:$A,MATCH(J13,ShipPartShape!$B:$B,0)),"-") -> 46200001 | L13: 대포_기본 | M13: =IFERROR(INDEX(ShipPartShape!$A:$A,MATCH(L13,ShipPartShape!$B:$B,0)),"-") -> 46300001 | N13: 램프_기본 | O13: =IFERROR(INDEX(ShipPartShape!$A:$A,MATCH(N13,ShipPartShape!$B:$B,0)),"-") -> 46700001 | Q13: =IFERROR(INDEX(ShipPartShape!$A:$A,MATCH(P13,ShipPartShape!$B:$B,0)),"-") -> - | S13: =IFERROR(INDEX(ShipPartShape!$A:$A,MATCH(R13,ShipPartShape!$B:$B,0)),"-") -> - | U13: =IFERROR(INDEX(ShipPartShape!$A:$A,MATCH(T13,ShipPartShape!$B:$B,0)),"-") -> - | W13: =IFERROR(INDEX(ShipPartShape!$A:$A,MATCH(V13,ShipPartShape!$B:$B,0)),"-") -> - | Y13: =IFERROR(INDEX(ShipPartShape!$A:$A,MATCH(X13,ShipPartShape!$B:$B,0)),"-") -> - | AA13: =IFERROR(INDEX(ShipPartShape!$A:$A,MATCH(Z13,ShipPartShape!$B:$B,0)),"-") -> - | AC13: =IFERROR(INDEX(ShipPartShape!$A:$A,MATCH(AB13,ShipPartShape!$B:$B,0)),"-") -> - | AE13: =IFERROR(INDEX(ShipPartShape!$A:$A,MATCH(AD13,ShipPartShape!$B:$B,0)),"-") -> - | AG13: =IFERROR(INDEX(ShipPartShape!$A:$A,MATCH(AF13,ShipPartShape!$B:$B,0)),"-") -> - | AI13: =IFERROR(INDEX(ShipPartShape!$A:$A,MATCH(AH13,ShipPartShape!$B:$B,0)),"-") -> - | AJ13: - | AK13: - | AL13: - | AM13: - | AN13: - | AO13: - | AP13: - | AQ13: - | AR13: - | AS13: - | AT13: - | AU13: 47600016 | AV13: - | AW13: - | AX13: -
A14: =A13+1 -> 45000004 | B14: 중 캐러벨3 | C14: SK_Ship_Caravel_Body | D14: 캐러벨적흑돛 | E14: 700 | F14: 100 | G14: - | H14: - | I14: =IFERROR(INDEX(ShipPartShape!$A:$A,MATCH(D14,ShipPartShape!$B:$B,0)),"-") -> 46000005 | J14: 충각_기본 | K14: =IFERROR(INDEX(ShipPartShape!$A:$A,MATCH(J14,ShipPartShape!$B:$B,0)),"-") -> 46200001 | L14: 대포_기본 | M14: =IFERROR(INDEX(ShipPartShape!$A:$A,MATCH(L14,ShipPartShape!$B:$B,0)),"-") -> 46300001 | N14: 램프_기본 | O14: =IFERROR(INDEX(ShipPartShape!$A:$A,MATCH(N14,ShipPartShape!$B:$B,0)),"-") -> 46700001 | Q14: =IFERROR(INDEX(ShipPartShape!$A:$A,MATCH(P14,ShipPartShape!$B:$B,0)),"-") -> - | S14: =IFERROR(INDEX(ShipPartShape!$A:$A,MATCH(R14,ShipPartShape!$B:$B,0)),"-") -> - | U14: =IFERROR(INDEX(ShipPartShape!$A:$A,MATCH(T14,ShipPartShape!$B:$B,0)),"-") -> - | W14: =IFERROR(INDEX(ShipPartShape!$A:$A,MATCH(V14,ShipPartShape!$B:$B,0)),"-") -> - | Y14: =IFERROR(INDEX(ShipPartShape!$A:$A,MATCH(X14,ShipPartShape!$B:$B,0)),"-") -> - | AA14: =IFERROR(INDEX(ShipPartShape!$A:$A,MATCH(Z14,ShipPartShape!$B:$B,0)),"-") -> - | AC14: =IFERROR(INDEX(ShipPartShape!$A:$A,MATCH(AB14,ShipPartShape!$B:$B,0)),"-") -> - | AE14: =IFERROR(INDEX(ShipPartShape!$A:$A,MATCH(AD14,ShipPartShape!$B:$B,0)),"-") -> - | AG14: =IFERROR(INDEX(ShipPartShape!$A:$A,MATCH(AF14,ShipPartShape!$B:$B,0)),"-") -> - | AI14: =IFERROR(INDEX(ShipPartShape!$A:$A,MATCH(AH14,ShipPartShape!$B:$B,0)),"-") -> - | AJ14: - | AK14: - | AL14: - | AM14: - | AN14: - | AO14: - | AP14: - | AQ14: - | AR14: - | AS14: - | AT14: - | AU14: 47600016 | AV14: - | AW14: - | AX14: -
A15: =A14+1 -> 45000005 | B15: 중 캐러벨_해적1 | C15: SK_Ship_Caravel_Body | D15: 캐러벨적흑돛_해골 | E15: 700 | F15: 100 | G15: - | H15: - | I15: =IFERROR(INDEX(ShipPartShape!$A:$A,MATCH(D15,ShipPartShape!$B:$B,0)),"-") -> 46000006 | J15: 충각_기본 | K15: =IFERROR(INDEX(ShipPartShape!$A:$A,MATCH(J15,ShipPartShape!$B:$B,0)),"-") -> 46200001 | L15: 대포_기본 | M15: =IFERROR(INDEX(ShipPartShape!$A:$A,MATCH(L15,ShipPartShape!$B:$B,0)),"-") -> 46300001 | N15: 램프_기본 | O15: =IFERROR(INDEX(ShipPartShape!$A:$A,MATCH(N15,ShipPartShape!$B:$B,0)),"-") -> 46700001 | Q15: =IFERROR(INDEX(ShipPartShape!$A:$A,MATCH(P15,ShipPartShape!$B:$B,0)),"-") -> - | S15: =IFERROR(INDEX(ShipPartShape!$A:$A,MATCH(R15,ShipPartShape!$B:$B,0)),"-") -> - | U15: =IFERROR(INDEX(ShipPartShape!$A:$A,MATCH(T15,ShipPartShape!$B:$B,0)),"-") -> - | W15: =IFERROR(INDEX(ShipPartShape!$A:$A,MATCH(V15,ShipPartShape!$B:$B,0)),"-") -> - | Y15: =IFERROR(INDEX(ShipPartShape!$A:$A,MATCH(X15,ShipPartShape!$B:$B,0)),"-") -> - | AA15: =IFERROR(INDEX(ShipPartShape!$A:$A,MATCH(Z15,ShipPartShape!$B:$B,0)),"-") -> - | AC15: =IFERROR(INDEX(ShipPartShape!$A:$A,MATCH(AB15,ShipPartShape!$B:$B,0)),"-") -> - | AE15: =IFERROR(INDEX(ShipPartShape!$A:$A,MATCH(AD15,ShipPartShape!$B:$B,0)),"-") -> - | AG15: =IFERROR(INDEX(ShipPartShape!$A:$A,MATCH(AF15,ShipPartShape!$B:$B,0)),"-") -> - | AI15: =IFERROR(INDEX(ShipPartShape!$A:$A,MATCH(AH15,ShipPartShape!$B:$B,0)),"-") -> - | AJ15: - | AK15: - | AL15: - | AM15: - | AN15: - | AO15: - | AP15: - | AQ15: - | AR15: - | AS15: - | AT15: - | AU15: 47600016 | AV15: - | AW15: - | AX15: -
A16: =A15+1 -> 45000006 | B16: 중 캐러벨_스페인 | C16: SK_Ship_Caravel_Body | D16: 캐러벨무적함대돛 | E16: 700 | F16: 100 | G16: - | H16: - | I16: =IFERROR(INDEX(ShipPartShape!$A:$A,MATCH(D16,ShipPartShape!$B:$B,0)),"-") -> 46000007 | J16: 독수리상 | K16: =IFERROR(INDEX(ShipPartShape!$A:$A,MATCH(J16,ShipPartShape!$B:$B,0)),"-") -> 46100002 | L16: 충각_기본 | M16: =IFERROR(INDEX(ShipPartShape!$A:$A,MATCH(L16,ShipPartShape!$B:$B,0)),"-") -> 46200001 | N16: 대포_기본 | O16: =IFERROR(INDEX(ShipPartShape!$A:$A,MATCH(N16,ShipPartShape!$B:$B,0)),"-") -> 46300001 | P16: 램프_기본 | Q16: =IFERROR(INDEX(ShipPartShape!$A:$A,MATCH(P16,ShipPartShape!$B:$B,0)),"-") -> 46700001 | S16: =IFERROR(INDEX(ShipPartShape!$A:$A,MATCH(R16,ShipPartShape!$B:$B,0)),"-") -> - | U16: =IFERROR(INDEX(ShipPartShape!$A:$A,MATCH(T16,ShipPartShape!$B:$B,0)),"-") -> - | W16: =IFERROR(INDEX(ShipPartShape!$A:$A,MATCH(V16,ShipPartShape!$B:$B,0)),"-") -> - | Y16: =IFERROR(INDEX(ShipPartShape!$A:$A,MATCH(X16,ShipPartShape!$B:$B,0)),"-") -> - | AA16: =IFERROR(INDEX(ShipPartShape!$A:$A,MATCH(Z16,ShipPartShape!$B:$B,0)),"-") -> - | AC16: =IFERROR(INDEX(ShipPartShape!$A:$A,MATCH(AB16,ShipPartShape!$B:$B,0)),"-") -> - | AE16: =IFERROR(INDEX(ShipPartShape!$A:$A,MATCH(AD16,ShipPartShape!$B:$B,0)),"-") -> - | AG16: =IFERROR(INDEX(ShipPartShape!$A:$A,MATCH(AF16,ShipPartShape!$B:$B,0)),"-") -> - | AI16: =IFERROR(INDEX(ShipPartShape!$A:$A,MATCH(AH16,ShipPartShape!$B:$B,0)),"-") -> - | AJ16: - | AK16: - | AL16: - | AM16: - | AN16: - | AO16: - | AP16: - | AQ16: - | AR16: - | AS16: - | AT16: - | AU16: 47600016 | AV16: - | AW16: - | AX16: -
A17: =A16+1 -> 45000007 | B17: 바르카 | C17: SK_Ship_Barca_Body | D17: 바르카3흰색돛 | E17: 600 | F17: 100 | G17: 10 | H17: -10 | I17: =IFERROR(INDEX(ShipPartShape!$A:$A,MATCH(D17,ShipPartShape!$B:$B,0)),"-") -> 46000008 | J17: 램프_기본 | K17: =IFERROR(INDEX(ShipPartShape!$A:$A,MATCH(J17,ShipPartShape!$B:$B,0)),"-") -> 46700001 | L17: 대포_기본 | M17: =IFERROR(INDEX(ShipPartShape!$A:$A,MATCH(L17,ShipPartShape!$B:$B,0)),"-") -> 46300001 | O17: =IFERROR(INDEX(ShipPartShape!$A:$A,MATCH(N17,ShipPartShape!$B:$B,0)),"-") -> - | Q17: =IFERROR(INDEX(ShipPartShape!$A:$A,MATCH(P17,ShipPartShape!$B:$B,0)),"-") -> - | S17: =IFERROR(INDEX(ShipPartShape!$A:$A,MATCH(R17,ShipPartShape!$B:$B,0)),"-") -> - | T17: 선박외형장식_A | U17: =IFERROR(INDEX(ShipPartShape!$A:$A,MATCH(T17,ShipPartShape!$B:$B,0)),"-") -> 46600001 | V17: 선박외형장식_B | W17: =IFERROR(INDEX(ShipPartShape!$A:$A,MATCH(V17,ShipPartShape!$B:$B,0)),"-") -> 46600002 | X17: 선박외형장식_G | Y17: =IFERROR(INDEX(ShipPartShape!$A:$A,MATCH(X17,ShipPartShape!$B:$B,0)),"-") -> 46600007 | Z17: 선박외형장식_E | AA17: =IFERROR(INDEX(ShipPartShape!$A:$A,MATCH(Z17,ShipPartShape!$B:$B,0)),"-") -> 46600005 | AC17: =IFERROR(INDEX(ShipPartShape!$A:$A,MATCH(AB17,ShipPartShape!$B:$B,0)),"-") -> - | AE17: =IFERROR(INDEX(ShipPartShape!$A:$A,MATCH(AD17,ShipPartShape!$B:$B,0)),"-") -> - | AG17: =IFERROR(INDEX(ShipPartShape!$A:$A,MATCH(AF17,ShipPartShape!$B:$B,0)),"-") -> - | AI17: =IFERROR(INDEX(ShipPartShape!$A:$A,MATCH(AH17,ShipPartShape!$B:$B,0)),"-") -> - | AJ17: - | AK17: - | AL17: - | AM17: - | AN17: - | AO17: - | AP17: - | AQ17: - | AR17: - | AS17: - | AT17: - | AU17: 47600014 | AV17: - | AW17: - | AX17: -
A18: =A17+1 -> 45000008 | B18: 적선바르카_삼각 | C18: SK_Ship_Barca_Body | D18: 바르카3적색돛 | E18: 600 | F18: 100 | G18: - | H18: - | I18: =IFERROR(INDEX(ShipPartShape!$A:$A,MATCH(D18,ShipPartShape!$B:$B,0)),"-") -> 46000009 | J18: 대포_기본 | K18: =IFERROR(INDEX(ShipPartShape!$A:$A,MATCH(J18,ShipPartShape!$B:$B,0)),"-") -> 46300001 | L18: 램프_기본 | M18: =IFERROR(INDEX(ShipPartShape!$A:$A,MATCH(L18,ShipPartShape!$B:$B,0)),"-") -> 46700001 | O18: =IFERROR(INDEX(ShipPartShape!$A:$A,MATCH(N18,ShipPartShape!$B:$B,0)),"-") -> - | Q18: =IFERROR(INDEX(ShipPartShape!$A:$A,MATCH(P18,ShipPartShape!$B:$B,0)),"-") -> - | S18: =IFERROR(INDEX(ShipPartShape!$A:$A,MATCH(R18,ShipPartShape!$B:$B,0)),"-") -> - | U18: =IFERROR(INDEX(ShipPartShape!$A:$A,MATCH(T18,ShipPartShape!$B:$B,0)),"-") -> - | W18: =IFERROR(INDEX(ShipPartShape!$A:$A,MATCH(V18,ShipPartShape!$B:$B,0)),"-") -> - | Y18: =IFERROR(INDEX(ShipPartShape!$A:$A,MATCH(X18,ShipPartShape!$B:$B,0)),"-") -> - | AA18: =IFERROR(INDEX(ShipPartShape!$A:$A,MATCH(Z18,ShipPartShape!$B:$B,0)),"-") -> - | AC18: =IFERROR(INDEX(ShipPartShape!$A:$A,MATCH(AB18,ShipPartShape!$B:$B,0)),"-") -> - | AE18: =IFERROR(INDEX(ShipPartShape!$A:$A,MATCH(AD18,ShipPartShape!$B:$B,0)),"-") -> - | AG18: =IFERROR(INDEX(ShipPartShape!$A:$A,MATCH(AF18,ShipPartShape!$B:$B,0)),"-") -> - | AI18: =IFERROR(INDEX(ShipPartShape!$A:$A,MATCH(AH18,ShipPartShape!$B:$B,0)),"-") -> - | AJ18: - | AK18: - | AL18: - | AM18: - | AN18: - | AO18: - | AP18: - | AQ18: - | AR18: - | AS18: - | AT18: - | AU18: 47600014 | AV18: - | AW18: - | AX18: -
A19: =A18+1 -> 45000009 | B19: 유령선바르카_삼각 | C19: SK_Ship_Barca_Body | D19: 바르카3유령선돛 | E19: 600 | F19: 100 | G19: - | H19: - | I19: =IFERROR(INDEX(ShipPartShape!$A:$A,MATCH(D19,ShipPartShape!$B:$B,0)),"-") -> 46000010 | J19: 독수리상 | K19: =IFERROR(INDEX(ShipPartShape!$A:$A,MATCH(J19,ShipPartShape!$B:$B,0)),"-") -> 46100002 | L19: 충각_기본 | M19: =IFERROR(INDEX(ShipPartShape!$A:$A,MATCH(L19,ShipPartShape!$B:$B,0)),"-") -> 46200001 | N19: 대포_기본 | O19: =IFERROR(INDEX(ShipPartShape!$A:$A,MATCH(N19,ShipPartShape!$B:$B,0)),"-") -> 46300001 | Q19: =IFERROR(INDEX(ShipPartShape!$A:$A,MATCH(P19,ShipPartShape!$B:$B,0)),"-") -> - | S19: =IFERROR(INDEX(ShipPartShape!$A:$A,MATCH(R19,ShipPartShape!$B:$B,0)),"-") -> - | U19: =IFERROR(INDEX(ShipPartShape!$A:$A,MATCH(T19,ShipPartShape!$B:$B,0)),"-") -> - | W19: =IFERROR(INDEX(ShipPartShape!$A:$A,MATCH(V19,ShipPartShape!$B:$B,0)),"-") -> - | Y19: =IFERROR(INDEX(ShipPartShape!$A:$A,MATCH(X19,ShipPartShape!$B:$B,0)),"-") -> - | AA19: =IFERROR(INDEX(ShipPartShape!$A:$A,MATCH(Z19,ShipPartShape!$B:$B,0)),"-") -> - | AC19: =IFERROR(INDEX(ShipPartShape!$A:$A,MATCH(AB19,ShipPartShape!$B:$B,0)),"-") -> - | AE19: =IFERROR(INDEX(ShipPartShape!$A:$A,MATCH(AD19,ShipPartShape!$B:$B,0)),"-") -> - | AG19: =IFERROR(INDEX(ShipPartShape!$A:$A,MATCH(AF19,ShipPartShape!$B:$B,0)),"-") -> - | AI19: =IFERROR(INDEX(ShipPartShape!$A:$A,MATCH(AH19,ShipPartShape!$B:$B,0)),"-") -> - | AJ19: - | AK19: - | AL19: - | AM19: - | AN19: - | AO19: - | AP19: - | AQ19: - | AR19: - | AS19: - | AT19: - | AU19: 47600014 | AV19: - | AW19: - | AX19: -
A20: =A19+1 -> 45000010 | B20: 바르카2_삼각 | C20: SK_Ship_Barca_Body | D20: 바르카3적백돛 | E20: 600 | F20: 100 | G20: - | H20: - | I20: =IFERROR(INDEX(ShipPartShape!$A:$A,MATCH(D20,ShipPartShape!$B:$B,0)),"-") -> 46000011 | J20: 충각_기본 | K20: =IFERROR(INDEX(ShipPartShape!$A:$A,MATCH(J20,ShipPartShape!$B:$B,0)),"-") -> 46200001 | L20: 대포_기본 | M20: =IFERROR(INDEX(ShipPartShape!$A:$A,MATCH(L20,ShipPartShape!$B:$B,0)),"-") -> 46300001 | N20: 램프_기본 | O20: =IFERROR(INDEX(ShipPartShape!$A:$A,MATCH(N20,ShipPartShape!$B:$B,0)),"-") -> 46700001 | P20: 닻 | Q20: =IFERROR(INDEX(ShipPartShape!$A:$A,MATCH(P20,ShipPartShape!$B:$B,0)),"-") -> 46400001 | S20: =IFERROR(INDEX(ShipPartShape!$A:$A,MATCH(R20,ShipPartShape!$B:$B,0)),"-") -> - | U20: =IFERROR(INDEX(ShipPartShape!$A:$A,MATCH(T20,ShipPartShape!$B:$B,0)),"-") -> - | W20: =IFERROR(INDEX(ShipPartShape!$A:$A,MATCH(V20,ShipPartShape!$B:$B,0)),"-") -> - | Y20: =IFERROR(INDEX(ShipPartShape!$A:$A,MATCH(X20,ShipPartShape!$B:$B,0)),"-") -> - | AA20: =IFERROR(INDEX(ShipPartShape!$A:$A,MATCH(Z20,ShipPartShape!$B:$B,0)),"-") -> - | AC20: =IFERROR(INDEX(ShipPartShape!$A:$A,MATCH(AB20,ShipPartShape!$B:$B,0)),"-") -> - | AE20: =IFERROR(INDEX(ShipPartShape!$A:$A,MATCH(AD20,ShipPartShape!$B:$B,0)),"-") -> - | AG20: =IFERROR(INDEX(ShipPartShape!$A:$A,MATCH(AF20,ShipPartShape!$B:$B,0)),"-") -> - | AI20: =IFERROR(INDEX(ShipPartShape!$A:$A,MATCH(AH20,ShipPartShape!$B:$B,0)),"-") -> - | AJ20: - | AK20: - | AL20: - | AM20: - | AN20: - | AO20: - | AP20: - | AQ20: - | AR20: - | AS20: - | AT20: - | AU20: 47600014 | AV20: - | AW20: - | AX20: -
A21: =A20+1 -> 45000011 | B21: 바르카3_삼각 | C21: SK_Ship_Barca_Body | D21: 바르카3적흑돛 | E21: 600 | F21: 100 | G21: - | H21: - | I21: =IFERROR(INDEX(ShipPartShape!$A:$A,MATCH(D21,ShipPartShape!$B:$B,0)),"-") -> 46000012 | J21: 충각_기본 | K21: =IFERROR(INDEX(ShipPartShape!$A:$A,MATCH(J21,ShipPartShape!$B:$B,0)),"-") -> 46200001 | L21: 대포_기본 | M21: =IFERROR(INDEX(ShipPartShape!$A:$A,MATCH(L21,ShipPartShape!$B:$B,0)),"-") -> 46300001 | N21: 램프_기본 | O21: =IFERROR(INDEX(ShipPartShape!$A:$A,MATCH(N21,ShipPartShape!$B:$B,0)),"-") -> 46700001 | Q21: =IFERROR(INDEX(ShipPartShape!$A:$A,MATCH(P21,ShipPartShape!$B:$B,0)),"-") -> - | S21: =IFERROR(INDEX(ShipPartShape!$A:$A,MATCH(R21,ShipPartShape!$B:$B,0)),"-") -> - | U21: =IFERROR(INDEX(ShipPartShape!$A:$A,MATCH(T21,ShipPartShape!$B:$B,0)),"-") -> - | W21: =IFERROR(INDEX(ShipPartShape!$A:$A,MATCH(V21,ShipPartShape!$B:$B,0)),"-") -> - | Y21: =IFERROR(INDEX(ShipPartShape!$A:$A,MATCH(X21,ShipPartShape!$B:$B,0)),"-") -> - | AA21: =IFERROR(INDEX(ShipPartShape!$A:$A,MATCH(Z21,ShipPartShape!$B:$B,0)),"-") -> - | AC21: =IFERROR(INDEX(ShipPartShape!$A:$A,MATCH(AB21,ShipPartShape!$B:$B,0)),"-") -> - | AE21: =IFERROR(INDEX(ShipPartShape!$A:$A,MATCH(AD21,ShipPartShape!$B:$B,0)),"-") -> - | AG21: =IFERROR(INDEX(ShipPartShape!$A:$A,MATCH(AF21,ShipPartShape!$B:$B,0)),"-") -> - | AI21: =IFERROR(INDEX(ShipPartShape!$A:$A,MATCH(AH21,ShipPartShape!$B:$B,0)),"-") -> - | AJ21: - | AK21: - | AL21: - | AM21: - | AN21: - | AO21: - | AP21: - | AQ21: - | AR21: - | AS21: - | AT21: - | AU21: 47600014 | AV21: - | AW21: - | AX21: -
A22: =A21+1 -> 45000012 | B22: 바르카_해적1_삼각 | C22: SK_Ship_Barca_Body | D22: 바르카3적흑돛_해골 | E22: 600 | F22: 100 | G22: - | H22: - | I22: =IFERROR(INDEX(ShipPartShape!$A:$A,MATCH(D22,ShipPartShape!$B:$B,0)),"-") -> 46000013 | J22: 충각_기본 | K22: =IFERROR(INDEX(ShipPartShape!$A:$A,MATCH(J22,ShipPartShape!$B:$B,0)),"-") -> 46200001 | L22: 대포_기본 | M22: =IFERROR(INDEX(ShipPartShape!$A:$A,MATCH(L22,ShipPartShape!$B:$B,0)),"-") -> 46300001 | N22: 램프_기본 | O22: =IFERROR(INDEX(ShipPartShape!$A:$A,MATCH(N22,ShipPartShape!$B:$B,0)),"-") -> 46700001 | Q22: =IFERROR(INDEX(ShipPartShape!$A:$A,MATCH(P22,ShipPartShape!$B:$B,0)),"-") -> - | S22: =IFERROR(INDEX(ShipPartShape!$A:$A,MATCH(R22,ShipPartShape!$B:$B,0)),"-") -> - | U22: =IFERROR(INDEX(ShipPartShape!$A:$A,MATCH(T22,ShipPartShape!$B:$B,0)),"-") -> - | W22: =IFERROR(INDEX(ShipPartShape!$A:$A,MATCH(V22,ShipPartShape!$B:$B,0)),"-") -> - | Y22: =IFERROR(INDEX(ShipPartShape!$A:$A,MATCH(X22,ShipPartShape!$B:$B,0)),"-") -> - | AA22: =IFERROR(INDEX(ShipPartShape!$A:$A,MATCH(Z22,ShipPartShape!$B:$B,0)),"-") -> - | AC22: =IFERROR(INDEX(ShipPartShape!$A:$A,MATCH(AB22,ShipPartShape!$B:$B,0)),"-") -> - | AE22: =IFERROR(INDEX(ShipPartShape!$A:$A,MATCH(AD22,ShipPartShape!$B:$B,0)),"-") -> - | AG22: =IFERROR(INDEX(ShipPartShape!$A:$A,MATCH(AF22,ShipPartShape!$B:$B,0)),"-") -> - | AI22: =IFERROR(INDEX(ShipPartShape!$A:$A,MATCH(AH22,ShipPartShape!$B:$B,0)),"-") -> - | AJ22: - | AK22: - | AL22: - | AM22: - | AN22: - | AO22: - | AP22: - | AQ22: - | AR22: - | AS22: - | AT22: - | AU22: 47600014 | AV22: - | AW22: - | AX22: -
A23: =A22+1 -> 45000013 | B23: 바르카_사각 | C23: SK_Ship_Barca_Body | D23: 바르카4흰색돛 | E23: 600 | F23: 100 | G23: - | H23: - | I23: =IFERROR(INDEX(ShipPartShape!$A:$A,MATCH(D23,ShipPartShape!$B:$B,0)),"-") -> 46000014 | J23: 램프_기본 | K23: =IFERROR(INDEX(ShipPartShape!$A:$A,MATCH(J23,ShipPartShape!$B:$B,0)),"-") -> 46700001 | M23: =IFERROR(INDEX(ShipPartShape!$A:$A,MATCH(L23,ShipPartShape!$B:$B,0)),"-") -> - | O23: =IFERROR(INDEX(ShipPartShape!$A:$A,MATCH(N23,ShipPartShape!$B:$B,0)),"-") -> - | Q23: =IFERROR(INDEX(ShipPartShape!$A:$A,MATCH(P23,ShipPartShape!$B:$B,0)),"-") -> - | S23: =IFERROR(INDEX(ShipPartShape!$A:$A,MATCH(R23,ShipPartShape!$B:$B,0)),"-") -> - | U23: =IFERROR(INDEX(ShipPartShape!$A:$A,MATCH(T23,ShipPartShape!$B:$B,0)),"-") -> - | W23: =IFERROR(INDEX(ShipPartShape!$A:$A,MATCH(V23,ShipPartShape!$B:$B,0)),"-") -> - | Y23: =IFERROR(INDEX(ShipPartShape!$A:$A,MATCH(X23,ShipPartShape!$B:$B,0)),"-") -> - | AA23: =IFERROR(INDEX(ShipPartShape!$A:$A,MATCH(Z23,ShipPartShape!$B:$B,0)),"-") -> - | AC23: =IFERROR(INDEX(ShipPartShape!$A:$A,MATCH(AB23,ShipPartShape!$B:$B,0)),"-") -> - | AE23: =IFERROR(INDEX(ShipPartShape!$A:$A,MATCH(AD23,ShipPartShape!$B:$B,0)),"-") -> - | AG23: =IFERROR(INDEX(ShipPartShape!$A:$A,MATCH(AF23,ShipPartShape!$B:$B,0)),"-") -> - | AI23: =IFERROR(INDEX(ShipPartShape!$A:$A,MATCH(AH23,ShipPartShape!$B:$B,0)),"-") -> - | AJ23: - | AK23: - | AL23: - | AM23: - | AN23: - | AO23: - | AP23: - | AQ23: - | AR23: - | AS23: - | AT23: - | AU23: 47600014 | AV23: - | AW23: - | AX23: -
A24: =A23+1 -> 45000014 | B24: 바르카_사각_적선 | C24: SK_Ship_Barca_Body | D24: 바르카4적색돛 | E24: 600 | F24: 100 | G24: - | H24: - | I24: =IFERROR(INDEX(ShipPartShape!$A:$A,MATCH(D24,ShipPartShape!$B:$B,0)),"-") -> 46000015 | J24: 대포_기본 | K24: =IFERROR(INDEX(ShipPartShape!$A:$A,MATCH(J24,ShipPartShape!$B:$B,0)),"-") -> 46300001 | L24: 램프_기본 | M24: =IFERROR(INDEX(ShipPartShape!$A:$A,MATCH(L24,ShipPartShape!$B:$B,0)),"-") -> 46700001 | O24: =IFERROR(INDEX(ShipPartShape!$A:$A,MATCH(N24,ShipPartShape!$B:$B,0)),"-") -> - | Q24: =IFERROR(INDEX(ShipPartShape!$A:$A,MATCH(P24,ShipPartShape!$B:$B,0)),"-") -> - | S24: =IFERROR(INDEX(ShipPartShape!$A:$A,MATCH(R24,ShipPartShape!$B:$B,0)),"-") -> - | U24: =IFERROR(INDEX(ShipPartShape!$A:$A,MATCH(T24,ShipPartShape!$B:$B,0)),"-") -> - | W24: =IFERROR(INDEX(ShipPartShape!$A:$A,MATCH(V24,ShipPartShape!$B:$B,0)),"-") -> - | Y24: =IFERROR(INDEX(ShipPartShape!$A:$A,MATCH(X24,ShipPartShape!$B:$B,0)),"-") -> - | AA24: =IFERROR(INDEX(ShipPartShape!$A:$A,MATCH(Z24,ShipPartShape!$B:$B,0)),"-") -> - | AC24: =IFERROR(INDEX(ShipPartShape!$A:$A,MATCH(AB24,ShipPartShape!$B:$B,0)),"-") -> - | AE24: =IFERROR(INDEX(ShipPartShape!$A:$A,MATCH(AD24,ShipPartShape!$B:$B,0)),"-") -> - | AG24: =IFERROR(INDEX(ShipPartShape!$A:$A,MATCH(AF24,ShipPartShape!$B:$B,0)),"-") -> - | AI24: =IFERROR(INDEX(ShipPartShape!$A:$A,MATCH(AH24,ShipPartShape!$B:$B,0)),"-") -> - | AJ24: - | AK24: - | AL24: - | AM24: - | AN24: - | AO24: - | AP24: - | AQ24: - | AR24: - | AS24: - | AT24: - | AU24: 47600014 | AV24: - | AW24: - | AX24: -
A25: =A24+1 -> 45000015 | B25: 바르카_사각_유령선 | C25: SK_Ship_Barca_Body | D25: 바르카4유령선돛 | E25: 600 | F25: 100 | G25: - | H25: - | I25: =IFERROR(INDEX(ShipPartShape!$A:$A,MATCH(D25,ShipPartShape!$B:$B,0)),"-") -> 46000016 | J25: 독수리상 | K25: =IFERROR(INDEX(ShipPartShape!$A:$A,MATCH(J25,ShipPartShape!$B:$B,0)),"-") -> 46100002 | L25: 충각_기본 | M25: =IFERROR(INDEX(ShipPartShape!$A:$A,MATCH(L25,ShipPartShape!$B:$B,0)),"-") -> 46200001 | N25: 대포_기본 | O25: =IFERROR(INDEX(ShipPartShape!$A:$A,MATCH(N25,ShipPartShape!$B:$B,0)),"-") -> 46300001 | Q25: =IFERROR(INDEX(ShipPartShape!$A:$A,MATCH(P25,ShipPartShape!$B:$B,0)),"-") -> - | S25: =IFERROR(INDEX(ShipPartShape!$A:$A,MATCH(R25,ShipPartShape!$B:$B,0)),"-") -> - | U25: =IFERROR(INDEX(ShipPartShape!$A:$A,MATCH(T25,ShipPartShape!$B:$B,0)),"-") -> - | W25: =IFERROR(INDEX(ShipPartShape!$A:$A,MATCH(V25,ShipPartShape!$B:$B,0)),"-") -> - | Y25: =IFERROR(INDEX(ShipPartShape!$A:$A,MATCH(X25,ShipPartShape!$B:$B,0)),"-") -> - | AA25: =IFERROR(INDEX(ShipPartShape!$A:$A,MATCH(Z25,ShipPartShape!$B:$B,0)),"-") -> - | AC25: =IFERROR(INDEX(ShipPartShape!$A:$A,MATCH(AB25,ShipPartShape!$B:$B,0)),"-") -> - | AE25: =IFERROR(INDEX(ShipPartShape!$A:$A,MATCH(AD25,ShipPartShape!$B:$B,0)),"-") -> - | AG25: =IFERROR(INDEX(ShipPartShape!$A:$A,MATCH(AF25,ShipPartShape!$B:$B,0)),"-") -> - | AI25: =IFERROR(INDEX(ShipPartShape!$A:$A,MATCH(AH25,ShipPartShape!$B:$B,0)),"-") -> - | AJ25: - | AK25: - | AL25: - | AM25: - | AN25: - | AO25: - | AP25: - | AQ25: - | AR25: - | AS25: - | AT25: - | AU25: 47600014 | AV25: - | AW25: - | AX25: -
A26: =A25+1 -> 45000016 | B26: 바르카_사각2 | C26: SK_Ship_Barca_Body | D26: 바르카4적백돛 | E26: 600 | F26: 100 | G26: - | H26: - | I26: =IFERROR(INDEX(ShipPartShape!$A:$A,MATCH(D26,ShipPartShape!$B:$B,0)),"-") -> 46000017 | J26: 충각_기본 | K26: =IFERROR(INDEX(ShipPartShape!$A:$A,MATCH(J26,ShipPartShape!$B:$B,0)),"-") -> 46200001 | L26: 대포_기본 | M26: =IFERROR(INDEX(ShipPartShape!$A:$A,MATCH(L26,ShipPartShape!$B:$B,0)),"-") -> 46300001 | N26: 램프_기본 | O26: =IFERROR(INDEX(ShipPartShape!$A:$A,MATCH(N26,ShipPartShape!$B:$B,0)),"-") -> 46700001 | Q26: =IFERROR(INDEX(ShipPartShape!$A:$A,MATCH(P26,ShipPartShape!$B:$B,0)),"-") -> - | S26: =IFERROR(INDEX(ShipPartShape!$A:$A,MATCH(R26,ShipPartShape!$B:$B,0)),"-") -> - | U26: =IFERROR(INDEX(ShipPartShape!$A:$A,MATCH(T26,ShipPartShape!$B:$B,0)),"-") -> - | W26: =IFERROR(INDEX(ShipPartShape!$A:$A,MATCH(V26,ShipPartShape!$B:$B,0)),"-") -> - | Y26: =IFERROR(INDEX(ShipPartShape!$A:$A,MATCH(X26,ShipPartShape!$B:$B,0)),"-") -> - | AA26: =IFERROR(INDEX(ShipPartShape!$A:$A,MATCH(Z26,ShipPartShape!$B:$B,0)),"-") -> - | AC26: =IFERROR(INDEX(ShipPartShape!$A:$A,MATCH(AB26,ShipPartShape!$B:$B,0)),"-") -> - | AE26: =IFERROR(INDEX(ShipPartShape!$A:$A,MATCH(AD26,ShipPartShape!$B:$B,0)),"-") -> - | AG26: =IFERROR(INDEX(ShipPartShape!$A:$A,MATCH(AF26,ShipPartShape!$B:$B,0)),"-") -> - | AI26: =IFERROR(INDEX(ShipPartShape!$A:$A,MATCH(AH26,ShipPartShape!$B:$B,0)),"-") -> - | AJ26: - | AK26: - | AL26: - | AM26: - | AN26: - | AO26: - | AP26: - | AQ26: - | AR26: - | AS26: - | AT26: - | AU26: 47600014 | AV26: - | AW26: - | AX26: -
A27: =A26+1 -> 45000017 | B27: 바르카_사각3 | C27: SK_Ship_Barca_Body | D27: 바르카4적흑돛 | E27: 600 | F27: 100 | G27: - | H27: - | I27: =IFERROR(INDEX(ShipPartShape!$A:$A,MATCH(D27,ShipPartShape!$B:$B,0)),"-") -> 46000018 | J27: 충각_기본 | K27: =IFERROR(INDEX(ShipPartShape!$A:$A,MATCH(J27,ShipPartShape!$B:$B,0)),"-") -> 46200001 | L27: 대포_기본 | M27: =IFERROR(INDEX(ShipPartShape!$A:$A,MATCH(L27,ShipPartShape!$B:$B,0)),"-") -> 46300001 | N27: 램프_기본 | O27: =IFERROR(INDEX(ShipPartShape!$A:$A,MATCH(N27,ShipPartShape!$B:$B,0)),"-") -> 46700001 | Q27: =IFERROR(INDEX(ShipPartShape!$A:$A,MATCH(P27,ShipPartShape!$B:$B,0)),"-") -> - | S27: =IFERROR(INDEX(ShipPartShape!$A:$A,MATCH(R27,ShipPartShape!$B:$B,0)),"-") -> - | U27: =IFERROR(INDEX(ShipPartShape!$A:$A,MATCH(T27,ShipPartShape!$B:$B,0)),"-") -> - | W27: =IFERROR(INDEX(ShipPartShape!$A:$A,MATCH(V27,ShipPartShape!$B:$B,0)),"-") -> - | Y27: =IFERROR(INDEX(ShipPartShape!$A:$A,MATCH(X27,ShipPartShape!$B:$B,0)),"-") -> - | AA27: =IFERROR(INDEX(ShipPartShape!$A:$A,MATCH(Z27,ShipPartShape!$B:$B,0)),"-") -> - | AC27: =IFERROR(INDEX(ShipPartShape!$A:$A,MATCH(AB27,ShipPartShape!$B:$B,0)),"-") -> - | AE27: =IFERROR(INDEX(ShipPartShape!$A:$A,MATCH(AD27,ShipPartShape!$B:$B,0)),"-") -> - | AG27: =IFERROR(INDEX(ShipPartShape!$A:$A,MATCH(AF27,ShipPartShape!$B:$B,0)),"-") -> - | AI27: =IFERROR(INDEX(ShipPartShape!$A:$A,MATCH(AH27,ShipPartShape!$B:$B,0)),"-") -> - | AJ27: - | AK27: - | AL27: - | AM27: - | AN27: - | AO27: - | AP27: - | AQ27: - | AR27: - | AS27: - | AT27: - | AU27: 47600014 | AV27: - | AW27: - | AX27: -
A28: =A27+1 -> 45000018 | B28: 바르카_사각_해적1 | C28: SK_Ship_Barca_Body | D28: 바르카4적흑돛_해골 | E28: 600 | F28: 100 | G28: - | H28: - | I28: =IFERROR(INDEX(ShipPartShape!$A:$A,MATCH(D28,ShipPartShape!$B:$B,0)),"-") -> 46000019 | J28: 충각_기본 | K28: =IFERROR(INDEX(ShipPartShape!$A:$A,MATCH(J28,ShipPartShape!$B:$B,0)),"-") -> 46200001 | L28: 대포_기본 | M28: =IFERROR(INDEX(ShipPartShape!$A:$A,MATCH(L28,ShipPartShape!$B:$B,0)),"-") -> 46300001 | N28: 램프_기본 | O28: =IFERROR(INDEX(ShipPartShape!$A:$A,MATCH(N28,ShipPartShape!$B:$B,0)),"-") -> 46700001 | Q28: =IFERROR(INDEX(ShipPartShape!$A:$A,MATCH(P28,ShipPartShape!$B:$B,0)),"-") -> - | S28: =IFERROR(INDEX(ShipPartShape!$A:$A,MATCH(R28,ShipPartShape!$B:$B,0)),"-") -> - | U28: =IFERROR(INDEX(ShipPartShape!$A:$A,MATCH(T28,ShipPartShape!$B:$B,0)),"-") -> - | W28: =IFERROR(INDEX(ShipPartShape!$A:$A,MATCH(V28,ShipPartShape!$B:$B,0)),"-") -> - | Y28: =IFERROR(INDEX(ShipPartShape!$A:$A,MATCH(X28,ShipPartShape!$B:$B,0)),"-") -> - | AA28: =IFERROR(INDEX(ShipPartShape!$A:$A,MATCH(Z28,ShipPartShape!$B:$B,0)),"-") -> - | AC28: =IFERROR(INDEX(ShipPartShape!$A:$A,MATCH(AB28,ShipPartShape!$B:$B,0)),"-") -> - | AE28: =IFERROR(INDEX(ShipPartShape!$A:$A,MATCH(AD28,ShipPartShape!$B:$B,0)),"-") -> - | AG28: =IFERROR(INDEX(ShipPartShape!$A:$A,MATCH(AF28,ShipPartShape!$B:$B,0)),"-") -> - | AI28: =IFERROR(INDEX(ShipPartShape!$A:$A,MATCH(AH28,ShipPartShape!$B:$B,0)),"-") -> - | AJ28: - | AK28: - | AL28: - | AM28: - | AN28: - | AO28: - | AP28: - | AQ28: - | AR28: - | AS28: - | AT28: - | AU28: 47600014 | AV28: - | AW28: - | AX28: -
A29: =A28+1 -> 45000019 | B29: 한자 코그 | C29: SK_Ship_HansaCog_Body | D29: 한자코그흰색돛 | E29: 600 | F29: 100 | G29: 10 | H29: -20 | I29: =IFERROR(INDEX(ShipPartShape!$A:$A,MATCH(D29,ShipPartShape!$B:$B,0)),"-") -> 46000020 | J29: 서양램프_유럽3 | K29: =IFERROR(INDEX(ShipPartShape!$A:$A,MATCH(J29,ShipPartShape!$B:$B,0)),"-") -> 46700014 | L29: 대포_기본 | M29: =IFERROR(INDEX(ShipPartShape!$A:$A,MATCH(L29,ShipPartShape!$B:$B,0)),"-") -> 46300001 | O29: =IFERROR(INDEX(ShipPartShape!$A:$A,MATCH(N29,ShipPartShape!$B:$B,0)),"-") -> - | Q29: =IFERROR(INDEX(ShipPartShape!$A:$A,MATCH(P29,ShipPartShape!$B:$B,0)),"-") -> - | S29: =IFERROR(INDEX(ShipPartShape!$A:$A,MATCH(R29,ShipPartShape!$B:$B,0)),"-") -> - | T29: 선박외형장식_A | U29: =IFERROR(INDEX(ShipPartShape!$A:$A,MATCH(T29,ShipPartShape!$B:$B,0)),"-") -> 46600001 | V29: 선박외형장식_B | W29: =IFERROR(INDEX(ShipPartShape!$A:$A,MATCH(V29,ShipPartShape!$B:$B,0)),"-") -> 46600002 | X29: 선박외형장식_E | Y29: =IFERROR(INDEX(ShipPartShape!$A:$A,MATCH(X29,ShipPartShape!$B:$B,0)),"-") -> 46600005 | Z29: 선박외형장식_H | AA29: =IFERROR(INDEX(ShipPartShape!$A:$A,MATCH(Z29,ShipPartShape!$B:$B,0)),"-") -> 46600008 | AC29: =IFERROR(INDEX(ShipPartShape!$A:$A,MATCH(AB29,ShipPartShape!$B:$B,0)),"-") -> - | AE29: =IFERROR(INDEX(ShipPartShape!$A:$A,MATCH(AD29,ShipPartShape!$B:$B,0)),"-") -> - | AG29: =IFERROR(INDEX(ShipPartShape!$A:$A,MATCH(AF29,ShipPartShape!$B:$B,0)),"-") -> - | AI29: =IFERROR(INDEX(ShipPartShape!$A:$A,MATCH(AH29,ShipPartShape!$B:$B,0)),"-") -> - | AJ29: - | AK29: - | AL29: - | AM29: - | AN29: - | AO29: - | AP29: - | AQ29: - | AR29: - | AS29: - | AT29: - | AU29: 47600014 | AV29: - | AW29: - | AX29: -
A30: =A29+1 -> 45000020 | B30: 한자 코그_적선 | C30: SK_Ship_HansaCog_Body | D30: 한자코그적색돛 | E30: 600 | F30: 100 | G30: - | H30: - | I30: =IFERROR(INDEX(ShipPartShape!$A:$A,MATCH(D30,ShipPartShape!$B:$B,0)),"-") -> 46000021 | J30: 대포_기본 | K30: =IFERROR(INDEX(ShipPartShape!$A:$A,MATCH(J30,ShipPartShape!$B:$B,0)),"-") -> 46300001 | L30: 램프_기본 | M30: =IFERROR(INDEX(ShipPartShape!$A:$A,MATCH(L30,ShipPartShape!$B:$B,0)),"-") -> 46700001 | O30: =IFERROR(INDEX(ShipPartShape!$A:$A,MATCH(N30,ShipPartShape!$B:$B,0)),"-") -> - | Q30: =IFERROR(INDEX(ShipPartShape!$A:$A,MATCH(P30,ShipPartShape!$B:$B,0)),"-") -> - | S30: =IFERROR(INDEX(ShipPartShape!$A:$A,MATCH(R30,ShipPartShape!$B:$B,0)),"-") -> - | U30: =IFERROR(INDEX(ShipPartShape!$A:$A,MATCH(T30,ShipPartShape!$B:$B,0)),"-") -> - | W30: =IFERROR(INDEX(ShipPartShape!$A:$A,MATCH(V30,ShipPartShape!$B:$B,0)),"-") -> - | Y30: =IFERROR(INDEX(ShipPartShape!$A:$A,MATCH(X30,ShipPartShape!$B:$B,0)),"-") -> - | AA30: =IFERROR(INDEX(ShipPartShape!$A:$A,MATCH(Z30,ShipPartShape!$B:$B,0)),"-") -> - | AC30: =IFERROR(INDEX(ShipPartShape!$A:$A,MATCH(AB30,ShipPartShape!$B:$B,0)),"-") -> - | AE30: =IFERROR(INDEX(ShipPartShape!$A:$A,MATCH(AD30,ShipPartShape!$B:$B,0)),"-") -> - | AG30: =IFERROR(INDEX(ShipPartShape!$A:$A,MATCH(AF30,ShipPartShape!$B:$B,0)),"-") -> - | AI30: =IFERROR(INDEX(ShipPartShape!$A:$A,MATCH(AH30,ShipPartShape!$B:$B,0)),"-") -> - | AJ30: - | AK30: - | AL30: - | AM30: - | AN30: - | AO30: - | AP30: - | AQ30: - | AR30: - | AS30: - | AT30: - | AU30: 47600014 | AV30: - | AW30: - | AX30: -
A31: =A30+1 -> 45000021 | B31: 한자 코그_유령선 | C31: SK_Ship_HansaCog_Body | D31: 한자코그유령선돛 | E31: 600 | F31: 100 | G31: - | H31: - | I31: =IFERROR(INDEX(ShipPartShape!$A:$A,MATCH(D31,ShipPartShape!$B:$B,0)),"-") -> 46000022 | J31: 독수리상 | K31: =IFERROR(INDEX(ShipPartShape!$A:$A,MATCH(J31,ShipPartShape!$B:$B,0)),"-") -> 46100002 | L31: 충각_기본 | M31: =IFERROR(INDEX(ShipPartShape!$A:$A,MATCH(L31,ShipPartShape!$B:$B,0)),"-") -> 46200001 | N31: 대포_기본 | O31: =IFERROR(INDEX(ShipPartShape!$A:$A,MATCH(N31,ShipPartShape!$B:$B,0)),"-") -> 46300001 | Q31: =IFERROR(INDEX(ShipPartShape!$A:$A,MATCH(P31,ShipPartShape!$B:$B,0)),"-") -> - | S31: =IFERROR(INDEX(ShipPartShape!$A:$A,MATCH(R31,ShipPartShape!$B:$B,0)),"-") -> - | U31: =IFERROR(INDEX(ShipPartShape!$A:$A,MATCH(T31,ShipPartShape!$B:$B,0)),"-") -> - | W31: =IFERROR(INDEX(ShipPartShape!$A:$A,MATCH(V31,ShipPartShape!$B:$B,0)),"-") -> - | Y31: =IFERROR(INDEX(ShipPartShape!$A:$A,MATCH(X31,ShipPartShape!$B:$B,0)),"-") -> - | AA31: =IFERROR(INDEX(ShipPartShape!$A:$A,MATCH(Z31,ShipPartShape!$B:$B,0)),"-") -> - | AC31: =IFERROR(INDEX(ShipPartShape!$A:$A,MATCH(AB31,ShipPartShape!$B:$B,0)),"-") -> - | AE31: =IFERROR(INDEX(ShipPartShape!$A:$A,MATCH(AD31,ShipPartShape!$B:$B,0)),"-") -> - | AG31: =IFERROR(INDEX(ShipPartShape!$A:$A,MATCH(AF31,ShipPartShape!$B:$B,0)),"-") -> - | AI31: =IFERROR(INDEX(ShipPartShape!$A:$A,MATCH(AH31,ShipPartShape!$B:$B,0)),"-") -> - | AJ31: - | AK31: - | AL31: - | AM31: - | AN31: - | AO31: - | AP31: - | AQ31: - | AR31: - | AS31: - | AT31: - | AU31: 47600014 | AV31: - | AW31: - | AX31: -
A32: =A31+1 -> 45000022 | B32: 한자 코그2 | C32: SK_Ship_HansaCog_Body | D32: 한자코그적백돛 | E32: 600 | F32: 100 | G32: - | H32: - | I32: =IFERROR(INDEX(ShipPartShape!$A:$A,MATCH(D32,ShipPartShape!$B:$B,0)),"-") -> 46000023 | J32: 충각_기본 | K32: =IFERROR(INDEX(ShipPartShape!$A:$A,MATCH(J32,ShipPartShape!$B:$B,0)),"-") -> 46200001 | L32: 대포_기본 | M32: =IFERROR(INDEX(ShipPartShape!$A:$A,MATCH(L32,ShipPartShape!$B:$B,0)),"-") -> 46300001 | N32: 램프_기본 | O32: =IFERROR(INDEX(ShipPartShape!$A:$A,MATCH(N32,ShipPartShape!$B:$B,0)),"-") -> 46700001 | Q32: =IFERROR(INDEX(ShipPartShape!$A:$A,MATCH(P32,ShipPartShape!$B:$B,0)),"-") -> - | S32: =IFERROR(INDEX(ShipPartShape!$A:$A,MATCH(R32,ShipPartShape!$B:$B,0)),"-") -> - | U32: =IFERROR(INDEX(ShipPartShape!$A:$A,MATCH(T32,ShipPartShape!$B:$B,0)),"-") -> - | W32: =IFERROR(INDEX(ShipPartShape!$A:$A,MATCH(V32,ShipPartShape!$B:$B,0)),"-") -> - | Y32: =IFERROR(INDEX(ShipPartShape!$A:$A,MATCH(X32,ShipPartShape!$B:$B,0)),"-") -> - | AA32: =IFERROR(INDEX(ShipPartShape!$A:$A,MATCH(Z32,ShipPartShape!$B:$B,0)),"-") -> - | AC32: =IFERROR(INDEX(ShipPartShape!$A:$A,MATCH(AB32,ShipPartShape!$B:$B,0)),"-") -> - | AE32: =IFERROR(INDEX(ShipPartShape!$A:$A,MATCH(AD32,ShipPartShape!$B:$B,0)),"-") -> - | AG32: =IFERROR(INDEX(ShipPartShape!$A:$A,MATCH(AF32,ShipPartShape!$B:$B,0)),"-") -> - | AI32: =IFERROR(INDEX(ShipPartShape!$A:$A,MATCH(AH32,ShipPartShape!$B:$B,0)),"-") -> - | AJ32: - | AK32: - | AL32: - | AM32: - | AN32: - | AO32: - | AP32: - | AQ32: - | AR32: - | AS32: - | AT32: - | AU32: 47600014 | AV32: - | AW32: - | AX32: -
A33: =A32+1 -> 45000023 | B33: 한자 코그3 | C33: SK_Ship_HansaCog_Body | D33: 한자코그적흑돛 | E33: 600 | F33: 100 | G33: - | H33: - | I33: =IFERROR(INDEX(ShipPartShape!$A:$A,MATCH(D33,ShipPartShape!$B:$B,0)),"-") -> 46000024 | J33: 충각_기본 | K33: =IFERROR(INDEX(ShipPartShape!$A:$A,MATCH(J33,ShipPartShape!$B:$B,0)),"-") -> 46200001 | L33: 대포_기본 | M33: =IFERROR(INDEX(ShipPartShape!$A:$A,MATCH(L33,ShipPartShape!$B:$B,0)),"-") -> 46300001 | N33: 램프_기본 | O33: =IFERROR(INDEX(ShipPartShape!$A:$A,MATCH(N33,ShipPartShape!$B:$B,0)),"-") -> 46700001 | Q33: =IFERROR(INDEX(ShipPartShape!$A:$A,MATCH(P33,ShipPartShape!$B:$B,0)),"-") -> - | S33: =IFERROR(INDEX(ShipPartShape!$A:$A,MATCH(R33,ShipPartShape!$B:$B,0)),"-") -> - | U33: =IFERROR(INDEX(ShipPartShape!$A:$A,MATCH(T33,ShipPartShape!$B:$B,0)),"-") -> - | W33: =IFERROR(INDEX(ShipPartShape!$A:$A,MATCH(V33,ShipPartShape!$B:$B,0)),"-") -> - | Y33: =IFERROR(INDEX(ShipPartShape!$A:$A,MATCH(X33,ShipPartShape!$B:$B,0)),"-") -> - | AA33: =IFERROR(INDEX(ShipPartShape!$A:$A,MATCH(Z33,ShipPartShape!$B:$B,0)),"-") -> - | AC33: =IFERROR(INDEX(ShipPartShape!$A:$A,MATCH(AB33,ShipPartShape!$B:$B,0)),"-") -> - | AE33: =IFERROR(INDEX(ShipPartShape!$A:$A,MATCH(AD33,ShipPartShape!$B:$B,0)),"-") -> - | AG33: =IFERROR(INDEX(ShipPartShape!$A:$A,MATCH(AF33,ShipPartShape!$B:$B,0)),"-") -> - | AI33: =IFERROR(INDEX(ShipPartShape!$A:$A,MATCH(AH33,ShipPartShape!$B:$B,0)),"-") -> - | AJ33: - | AK33: - | AL33: - | AM33: - | AN33: - | AO33: - | AP33: - | AQ33: - | AR33: - | AS33: - | AT33: - | AU33: 47600014 | AV33: - | AW33: - | AX33: -
A34: =A33+1 -> 45000024 | B34: 한자코그_해적1 | C34: SK_Ship_HansaCog_Body | D34: 한자코그적흑돛_해골 | E34: 600 | F34: 100 | G34: - | H34: - | I34: =IFERROR(INDEX(ShipPartShape!$A:$A,MATCH(D34,ShipPartShape!$B:$B,0)),"-") -> 46000025 | J34: 충각_기본 | K34: =IFERROR(INDEX(ShipPartShape!$A:$A,MATCH(J34,ShipPartShape!$B:$B,0)),"-") -> 46200001 | L34: 대포_기본 | M34: =IFERROR(INDEX(ShipPartShape!$A:$A,MATCH(L34,ShipPartShape!$B:$B,0)),"-") -> 46300001 | N34: 램프_기본 | O34: =IFERROR(INDEX(ShipPartShape!$A:$A,MATCH(N34,ShipPartShape!$B:$B,0)),"-") -> 46700001 | Q34: =IFERROR(INDEX(ShipPartShape!$A:$A,MATCH(P34,ShipPartShape!$B:$B,0)),"-") -> - | S34: =IFERROR(INDEX(ShipPartShape!$A:$A,MATCH(R34,ShipPartShape!$B:$B,0)),"-") -> - | U34: =IFERROR(INDEX(ShipPartShape!$A:$A,MATCH(T34,ShipPartShape!$B:$B,0)),"-") -> - | W34: =IFERROR(INDEX(ShipPartShape!$A:$A,MATCH(V34,ShipPartShape!$B:$B,0)),"-") -> - | Y34: =IFERROR(INDEX(ShipPartShape!$A:$A,MATCH(X34,ShipPartShape!$B:$B,0)),"-") -> - | AA34: =IFERROR(INDEX(ShipPartShape!$A:$A,MATCH(Z34,ShipPartShape!$B:$B,0)),"-") -> - | AC34: =IFERROR(INDEX(ShipPartShape!$A:$A,MATCH(AB34,ShipPartShape!$B:$B,0)),"-") -> - | AE34: =IFERROR(INDEX(ShipPartShape!$A:$A,MATCH(AD34,ShipPartShape!$B:$B,0)),"-") -> - | AG34: =IFERROR(INDEX(ShipPartShape!$A:$A,MATCH(AF34,ShipPartShape!$B:$B,0)),"-") -> - | AI34: =IFERROR(INDEX(ShipPartShape!$A:$A,MATCH(AH34,ShipPartShape!$B:$B,0)),"-") -> - | AJ34: - | AK34: - | AL34: - | AM34: - | AN34: - | AO34: - | AP34: - | AQ34: - | AR34: - | AS34: - | AT34: - | AU34: 47600014 | AV34: - | AW34: - | AX34: -
A35: =A34+1 -> 45000025 | B35: 코그 라티나 | C35: SK_Ship_CogBig_Body | D35: 코그레티나흰색돛 | E35: 600 | F35: 100 | G35: 10 | H35: -30 | I35: =IFERROR(INDEX(ShipPartShape!$A:$A,MATCH(D35,ShipPartShape!$B:$B,0)),"-") -> 46000026 | J35: 램프_기본 | K35: =IFERROR(INDEX(ShipPartShape!$A:$A,MATCH(J35,ShipPartShape!$B:$B,0)),"-") -> 46700001 | L35: 대포_기본 | M35: =IFERROR(INDEX(ShipPartShape!$A:$A,MATCH(L35,ShipPartShape!$B:$B,0)),"-") -> 46300001 | O35: =IFERROR(INDEX(ShipPartShape!$A:$A,MATCH(N35,ShipPartShape!$B:$B,0)),"-") -> - | Q35: =IFERROR(INDEX(ShipPartShape!$A:$A,MATCH(P35,ShipPartShape!$B:$B,0)),"-") -> - | S35: =IFERROR(INDEX(ShipPartShape!$A:$A,MATCH(R35,ShipPartShape!$B:$B,0)),"-") -> - | T35: 선박외형장식_B | U35: =IFERROR(INDEX(ShipPartShape!$A:$A,MATCH(T35,ShipPartShape!$B:$B,0)),"-") -> 46600002 | V35: 선박외형장식_D | W35: =IFERROR(INDEX(ShipPartShape!$A:$A,MATCH(V35,ShipPartShape!$B:$B,0)),"-") -> 46600004 | X35: 선박외형장식_I | Y35: =IFERROR(INDEX(ShipPartShape!$A:$A,MATCH(X35,ShipPartShape!$B:$B,0)),"-") -> 46600009 | Z35: 선박외형장식_G | AA35: =IFERROR(INDEX(ShipPartShape!$A:$A,MATCH(Z35,ShipPartShape!$B:$B,0)),"-") -> 46600007 | AC35: =IFERROR(INDEX(ShipPartShape!$A:$A,MATCH(AB35,ShipPartShape!$B:$B,0)),"-") -> - | AE35: =IFERROR(INDEX(ShipPartShape!$A:$A,MATCH(AD35,ShipPartShape!$B:$B,0)),"-") -> - | AG35: =IFERROR(INDEX(ShipPartShape!$A:$A,MATCH(AF35,ShipPartShape!$B:$B,0)),"-") -> - | AI35: =IFERROR(INDEX(ShipPartShape!$A:$A,MATCH(AH35,ShipPartShape!$B:$B,0)),"-") -> - | AJ35: - | AK35: - | AL35: - | AM35: - | AN35: - | AO35: - | AP35: - | AQ35: - | AR35: - | AS35: - | AT35: - | AU35: 47600015 | AV35: - | AW35: - | AX35: -
A36: =A35+1 -> 45000026 | B36: 코그 라티나_적선 | C36: SK_Ship_CogBig_Body | D36: 코그레티나적색돛 | E36: 600 | F36: 100 | G36: - | H36: - | I36: =IFERROR(INDEX(ShipPartShape!$A:$A,MATCH(D36,ShipPartShape!$B:$B,0)),"-") -> 46000027 | J36: 대포_기본 | K36: =IFERROR(INDEX(ShipPartShape!$A:$A,MATCH(J36,ShipPartShape!$B:$B,0)),"-") -> 46300001 | L36: 램프_기본 | M36: =IFERROR(INDEX(ShipPartShape!$A:$A,MATCH(L36,ShipPartShape!$B:$B,0)),"-") -> 46700001 | O36: =IFERROR(INDEX(ShipPartShape!$A:$A,MATCH(N36,ShipPartShape!$B:$B,0)),"-") -> - | Q36: =IFERROR(INDEX(ShipPartShape!$A:$A,MATCH(P36,ShipPartShape!$B:$B,0)),"-") -> - | S36: =IFERROR(INDEX(ShipPartShape!$A:$A,MATCH(R36,ShipPartShape!$B:$B,0)),"-") -> - | U36: =IFERROR(INDEX(ShipPartShape!$A:$A,MATCH(T36,ShipPartShape!$B:$B,0)),"-") -> - | W36: =IFERROR(INDEX(ShipPartShape!$A:$A,MATCH(V36,ShipPartShape!$B:$B,0)),"-") -> - | Y36: =IFERROR(INDEX(ShipPartShape!$A:$A,MATCH(X36,ShipPartShape!$B:$B,0)),"-") -> - | AA36: =IFERROR(INDEX(ShipPartShape!$A:$A,MATCH(Z36,ShipPartShape!$B:$B,0)),"-") -> - | AC36: =IFERROR(INDEX(ShipPartShape!$A:$A,MATCH(AB36,ShipPartShape!$B:$B,0)),"-") -> - | AE36: =IFERROR(INDEX(ShipPartShape!$A:$A,MATCH(AD36,ShipPartShape!$B:$B,0)),"-") -> - | AG36: =IFERROR(INDEX(ShipPartShape!$A:$A,MATCH(AF36,ShipPartShape!$B:$B,0)),"-") -> - | AI36: =IFERROR(INDEX(ShipPartShape!$A:$A,MATCH(AH36,ShipPartShape!$B:$B,0)),"-") -> - | AJ36: - | AK36: - | AL36: - | AM36: - | AN36: - | AO36: - | AP36: - | AQ36: - | AR36: - | AS36: - | AT36: - | AU36: 47600015 | AV36: - | AW36: - | AX36: -
A37: =A36+1 -> 45000027 | B37: 코그 라티나_유령선 | C37: SK_Ship_CogBig_Body | D37: 코그레티나유령선돛 | E37: 600 | F37: 100 | G37: - | H37: - | I37: =IFERROR(INDEX(ShipPartShape!$A:$A,MATCH(D37,ShipPartShape!$B:$B,0)),"-") -> 46000028 | J37: 독수리상 | K37: =IFERROR(INDEX(ShipPartShape!$A:$A,MATCH(J37,ShipPartShape!$B:$B,0)),"-") -> 46100002 | L37: 충각_기본 | M37: =IFERROR(INDEX(ShipPartShape!$A:$A,MATCH(L37,ShipPartShape!$B:$B,0)),"-") -> 46200001 | N37: 대포_기본 | O37: =IFERROR(INDEX(ShipPartShape!$A:$A,MATCH(N37,ShipPartShape!$B:$B,0)),"-") -> 46300001 | Q37: =IFERROR(INDEX(ShipPartShape!$A:$A,MATCH(P37,ShipPartShape!$B:$B,0)),"-") -> - | S37: =IFERROR(INDEX(ShipPartShape!$A:$A,MATCH(R37,ShipPartShape!$B:$B,0)),"-") -> - | U37: =IFERROR(INDEX(ShipPartShape!$A:$A,MATCH(T37,ShipPartShape!$B:$B,0)),"-") -> - | W37: =IFERROR(INDEX(ShipPartShape!$A:$A,MATCH(V37,ShipPartShape!$B:$B,0)),"-") -> - | Y37: =IFERROR(INDEX(ShipPartShape!$A:$A,MATCH(X37,ShipPartShape!$B:$B,0)),"-") -> - | AA37: =IFERROR(INDEX(ShipPartShape!$A:$A,MATCH(Z37,ShipPartShape!$B:$B,0)),"-") -> - | AC37: =IFERROR(INDEX(ShipPartShape!$A:$A,MATCH(AB37,ShipPartShape!$B:$B,0)),"-") -> - | AE37: =IFERROR(INDEX(ShipPartShape!$A:$A,MATCH(AD37,ShipPartShape!$B:$B,0)),"-") -> - | AG37: =IFERROR(INDEX(ShipPartShape!$A:$A,MATCH(AF37,ShipPartShape!$B:$B,0)),"-") -> - | AI37: =IFERROR(INDEX(ShipPartShape!$A:$A,MATCH(AH37,ShipPartShape!$B:$B,0)),"-") -> - | AJ37: - | AK37: - | AL37: - | AM37: - | AN37: - | AO37: - | AP37: - | AQ37: - | AR37: - | AS37: - | AT37: - | AU37: 47600015 | AV37: - | AW37: - | AX37: -
A38: =A37+1 -> 45000028 | B38: 코그 라티나2 | C38: SK_Ship_CogBig_Body | D38: 코그레티나적백돛 | E38: 600 | F38: 100 | G38: - | H38: - | I38: =IFERROR(INDEX(ShipPartShape!$A:$A,MATCH(D38,ShipPartShape!$B:$B,0)),"-") -> 46000029 | J38: 충각_기본 | K38: =IFERROR(INDEX(ShipPartShape!$A:$A,MATCH(J38,ShipPartShape!$B:$B,0)),"-") -> 46200001 | L38: 대포_기본 | M38: =IFERROR(INDEX(ShipPartShape!$A:$A,MATCH(L38,ShipPartShape!$B:$B,0)),"-") -> 46300001 | N38: 램프_기본 | O38: =IFERROR(INDEX(ShipPartShape!$A:$A,MATCH(N38,ShipPartShape!$B:$B,0)),"-") -> 46700001 | Q38: =IFERROR(INDEX(ShipPartShape!$A:$A,MATCH(P38,ShipPartShape!$B:$B,0)),"-") -> - | S38: =IFERROR(INDEX(ShipPartShape!$A:$A,MATCH(R38,ShipPartShape!$B:$B,0)),"-") -> - | U38: =IFERROR(INDEX(ShipPartShape!$A:$A,MATCH(T38,ShipPartShape!$B:$B,0)),"-") -> - | W38: =IFERROR(INDEX(ShipPartShape!$A:$A,MATCH(V38,ShipPartShape!$B:$B,0)),"-") -> - | Y38: =IFERROR(INDEX(ShipPartShape!$A:$A,MATCH(X38,ShipPartShape!$B:$B,0)),"-") -> - | AA38: =IFERROR(INDEX(ShipPartShape!$A:$A,MATCH(Z38,ShipPartShape!$B:$B,0)),"-") -> - | AC38: =IFERROR(INDEX(ShipPartShape!$A:$A,MATCH(AB38,ShipPartShape!$B:$B,0)),"-") -> - | AE38: =IFERROR(INDEX(ShipPartShape!$A:$A,MATCH(AD38,ShipPartShape!$B:$B,0)),"-") -> - | AG38: =IFERROR(INDEX(ShipPartShape!$A:$A,MATCH(AF38,ShipPartShape!$B:$B,0)),"-") -> - | AI38: =IFERROR(INDEX(ShipPartShape!$A:$A,MATCH(AH38,ShipPartShape!$B:$B,0)),"-") -> - | AJ38: - | AK38: - | AL38: - | AM38: - | AN38: - | AO38: - | AP38: - | AQ38: - | AR38: - | AS38: - | AT38: - | AU38: 47600015 | AV38: - | AW38: - | AX38: -
A39: =A38+1 -> 45000029 | B39: 코그 라티나3 | C39: SK_Ship_CogBig_Body | D39: 코그레티나적흑돛 | E39: 600 | F39: 100 | G39: - | H39: - | I39: =IFERROR(INDEX(ShipPartShape!$A:$A,MATCH(D39,ShipPartShape!$B:$B,0)),"-") -> 46000030 | J39: 충각_기본 | K39: =IFERROR(INDEX(ShipPartShape!$A:$A,MATCH(J39,ShipPartShape!$B:$B,0)),"-") -> 46200001 | L39: 대포_기본 | M39: =IFERROR(INDEX(ShipPartShape!$A:$A,MATCH(L39,ShipPartShape!$B:$B,0)),"-") -> 46300001 | N39: 램프_기본 | O39: =IFERROR(INDEX(ShipPartShape!$A:$A,MATCH(N39,ShipPartShape!$B:$B,0)),"-") -> 46700001 | Q39: =IFERROR(INDEX(ShipPartShape!$A:$A,MATCH(P39,ShipPartShape!$B:$B,0)),"-") -> - | S39: =IFERROR(INDEX(ShipPartShape!$A:$A,MATCH(R39,ShipPartShape!$B:$B,0)),"-") -> - | U39: =IFERROR(INDEX(ShipPartShape!$A:$A,MATCH(T39,ShipPartShape!$B:$B,0)),"-") -> - | W39: =IFERROR(INDEX(ShipPartShape!$A:$A,MATCH(V39,ShipPartShape!$B:$B,0)),"-") -> - | Y39: =IFERROR(INDEX(ShipPartShape!$A:$A,MATCH(X39,ShipPartShape!$B:$B,0)),"-") -> - | AA39: =IFERROR(INDEX(ShipPartShape!$A:$A,MATCH(Z39,ShipPartShape!$B:$B,0)),"-") -> - | AC39: =IFERROR(INDEX(ShipPartShape!$A:$A,MATCH(AB39,ShipPartShape!$B:$B,0)),"-") -> - | AE39: =IFERROR(INDEX(ShipPartShape!$A:$A,MATCH(AD39,ShipPartShape!$B:$B,0)),"-") -> - | AG39: =IFERROR(INDEX(ShipPartShape!$A:$A,MATCH(AF39,ShipPartShape!$B:$B,0)),"-") -> - | AI39: =IFERROR(INDEX(ShipPartShape!$A:$A,MATCH(AH39,ShipPartShape!$B:$B,0)),"-") -> - | AJ39: - | AK39: - | AL39: - | AM39: - | AN39: - | AO39: - | AP39: - | AQ39: - | AR39: - | AS39: - | AT39: - | AU39: 47600015 | AV39: - | AW39: - | AX39: -
A40: =A39+1 -> 45000030 | B40: 코그 라티나_해적1 | C40: SK_Ship_CogBig_Body | D40: 코그레티나적흑돛_해골 | E40: 600 | F40: 100 | G40: - | H40: - | I40: =IFERROR(INDEX(ShipPartShape!$A:$A,MATCH(D40,ShipPartShape!$B:$B,0)),"-") -> 46000031 | J40: 충각_기본 | K40: =IFERROR(INDEX(ShipPartShape!$A:$A,MATCH(J40,ShipPartShape!$B:$B,0)),"-") -> 46200001 | L40: 대포_기본 | M40: =IFERROR(INDEX(ShipPartShape!$A:$A,MATCH(L40,ShipPartShape!$B:$B,0)),"-") -> 46300001 | N40: 램프_기본 | O40: =IFERROR(INDEX(ShipPartShape!$A:$A,MATCH(N40,ShipPartShape!$B:$B,0)),"-") -> 46700001 | Q40: =IFERROR(INDEX(ShipPartShape!$A:$A,MATCH(P40,ShipPartShape!$B:$B,0)),"-") -> - | S40: =IFERROR(INDEX(ShipPartShape!$A:$A,MATCH(R40,ShipPartShape!$B:$B,0)),"-") -> - | U40: =IFERROR(INDEX(ShipPartShape!$A:$A,MATCH(T40,ShipPartShape!$B:$B,0)),"-") -> - | W40: =IFERROR(INDEX(ShipPartShape!$A:$A,MATCH(V40,ShipPartShape!$B:$B,0)),"-") -> - | Y40: =IFERROR(INDEX(ShipPartShape!$A:$A,MATCH(X40,ShipPartShape!$B:$B,0)),"-") -> - | AA40: =IFERROR(INDEX(ShipPartShape!$A:$A,MATCH(Z40,ShipPartShape!$B:$B,0)),"-") -> - | AC40: =IFERROR(INDEX(ShipPartShape!$A:$A,MATCH(AB40,ShipPartShape!$B:$B,0)),"-") -> - | AE40: =IFERROR(INDEX(ShipPartShape!$A:$A,MATCH(AD40,ShipPartShape!$B:$B,0)),"-") -> - | AG40: =IFERROR(INDEX(ShipPartShape!$A:$A,MATCH(AF40,ShipPartShape!$B:$B,0)),"-") -> - | AI40: =IFERROR(INDEX(ShipPartShape!$A:$A,MATCH(AH40,ShipPartShape!$B:$B,0)),"-") -> - | AJ40: - | AK40: - | AL40: - | AM40: - | AN40: - | AO40: - | AP40: - | AQ40: - | AR40: - | AS40: - | AT40: - | AU40: 47600015 | AV40: - | AW40: - | AX40: -
...

Sheet ShipPartShape
A1: id | D1: partType | E1: assetName | G1: assetType | H1: socket | I1: startSocketNum | J1: endSocketNum | K1: lightBpName | L1: lightBpOffset | N1: detailMode | O1: drawDistance | Q1: sailPattern | S1: sailCrest | T1: materials[0]["index"] | U1: materials[0]["name"] | V1: materials[1]["index"] | W1: materials[1]["name"] | X1: materials[2]["index"] | Y1: materials[2]["name"] | Z1: materials[3]["index"] | AA1: materials[3]["name"]
A2: key:46000000~46999999 | D2: number | E2: string | G2: number | H2: string | I2: number | J2: number | K2: string | L2: [number] | N2: number | O2: number | Q2: number | S2: number | T2: number | U2: string | V2: number | W2: string | X2: number | Y2: string | Z2: number | AA2: string
A3: :required | B3: - | C3: - | D3: 1 | E3: 1 | F3: - | G3: 1 | H3: - | I3: - | J3: - | K3: - | L3: - | M3: - | N3: - | O3: - | Q3: - | S3: - | T3: - | U3: - | V3: - | W3: - | X3: - | Y3: - | Z3: - | AA3: -
A4: :requireedInObject | B4: - | C4: - | D4: - | E4: - | F4: - | G4: - | H4: - | I4: - | J4: - | K4: - | L4: - | M4: - | N4: - | O4: - | Q4: - | S4: - | T4: 1 | U4: 1 | V4: 1 | W4: 1 | X4: 1 | Y4: 1 | Z4: 1 | AA4: 1
A5: :min | B5: - | C5: - | D5: - | E5: - | F5: - | G5: - | H5: - | I5: - | J5: - | K5: - | L5: - | M5: - | N5: - | O5: - | Q5: - | S5: - | T5: - | U5: - | V5: - | W5: - | X5: - | Y5: - | Z5: - | AA5: -
A6: :max | B6: - | C6: - | D6: - | E6: - | F6: - | G6: - | H6: - | I6: - | J6: - | K6: - | L6: - | M6: - | N6: - | O6: - | Q6: - | S6: - | T6: - | U6: - | V6: - | W6: - | X6: - | Y6: - | Z6: - | AA6: -
A7: :enum | B7: - | C7: - | D7: - | E7: - | F7: - | G7: - | H7: - | I7: - | J7: - | K7: - | L7: - | M7: - | N7: - | O7: - | Q7: - | S7: - | T7: - | U7: - | V7: - | W7: - | X7: - | Y7: - | Z7: - | AA7: -
A8: :links | B8: - | C8: - | D8: - | E8: - | F8: - | G8: - | H8: - | I8: - | J8: - | K8: - | L8: - | M8: - | N8: - | O8: - | Q8: "SailPattern" | S8: "SailCrest" | T8: - | U8: - | V8: - | W8: - | X8: - | Y8: - | Z8: - | AA8: -
A9: :asset | B9: - | C9: - | D9: - | E9: 1 | F9: - | G9: - | H9: - | I9: - | J9: - | K9: - | L9: - | M9: - | N9: - | O9: - | Q9: - | S9: - | T9: - | U9: 1 | V9: - | W9: 1 | X9: - | Y9: 1 | Z9: - | AA9: 1
A10: 46000001 | B10: 캐러벨흰색돛 | C10: Sail | D10: =IFERROR(VLOOKUP(C10,ShipShapeEnum!$E:$F,2,FALSE),"-") -> 1 | E10: SK_Ship_Caravel_Sail | F10: SkeletalMesh | G10: =IFERROR(VLOOKUP(F10,ShipShapeEnum!$B:$C,2,FALSE),"-") -> 1 | H10: - | I10: - | J10: - | K10: - | L10: - | M10: Low | N10: =IFERROR(VLOOKUP(M10,ShipShapeEnum!$H:$I,2,FALSE),"-") -> 1 | O10: - | Q10: =IFERROR(INDEX(SailPattern!$A:$A,MATCH(P10,SailPattern!$B:$B,0)),"-") -> - | S10: =IFERROR(INDEX(SailCrest!$A:$A,MATCH(R10,SailCrest!$B:$B,0)),"-") -> - | T10: 2 | U10: M_Ship_Sail_Inst | V10: - | W10: - | X10: - | Y10: - | Z10: - | AA10: -
A11: =A10+1 -> 46000002 | B11: 캐러벨적색돛 | C11: Sail | D11: =IFERROR(VLOOKUP(C11,ShipShapeEnum!$E:$F,2,FALSE),"-") -> 1 | E11: SK_Ship_Caravel_Sail | F11: SkeletalMesh | G11: =IFERROR(VLOOKUP(F11,ShipShapeEnum!$B:$C,2,FALSE),"-") -> 1 | H11: - | I11: - | J11: - | K11: - | L11: - | M11: Low | N11: =IFERROR(VLOOKUP(M11,ShipShapeEnum!$H:$I,2,FALSE),"-") -> 1 | O11: - | Q11: =IFERROR(INDEX(SailPattern!$A:$A,MATCH(P11,SailPattern!$B:$B,0)),"-") -> - | S11: =IFERROR(INDEX(SailCrest!$A:$A,MATCH(R11,SailCrest!$B:$B,0)),"-") -> - | T11: - | U11: - | V11: - | W11: - | X11: - | Y11: - | Z11: - | AA11: -
A12: =A11+1 -> 46000003 | B12: 캐러벨유령선돛 | C12: Sail | D12: =IFERROR(VLOOKUP(C12,ShipShapeEnum!$E:$F,2,FALSE),"-") -> 1 | E12: SK_Ship_Caravel_Sail | F12: SkeletalMesh | G12: =IFERROR(VLOOKUP(F12,ShipShapeEnum!$B:$C,2,FALSE),"-") -> 1 | H12: - | I12: - | J12: - | K12: - | L12: - | M12: Low | N12: =IFERROR(VLOOKUP(M12,ShipShapeEnum!$H:$I,2,FALSE),"-") -> 1 | O12: - | Q12: =IFERROR(INDEX(SailPattern!$A:$A,MATCH(P12,SailPattern!$B:$B,0)),"-") -> - | S12: =IFERROR(INDEX(SailCrest!$A:$A,MATCH(R12,SailCrest!$B:$B,0)),"-") -> - | T12: 2 | U12: M_Ship_Sail_BlackDamaged_Inst | V12: 3 | W12: M_Ship_Sail_BlackDamaged_Inst | X12: - | Y12: - | Z12: - | AA12: -
A13: =A12+1 -> 46000004 | B13: 캐러벨적백돛 | C13: Sail | D13: =IFERROR(VLOOKUP(C13,ShipShapeEnum!$E:$F,2,FALSE),"-") -> 1 | E13: SK_Ship_Caravel_Sail | F13: SkeletalMesh | G13: =IFERROR(VLOOKUP(F13,ShipShapeEnum!$B:$C,2,FALSE),"-") -> 1 | H13: - | I13: - | J13: - | K13: - | L13: - | M13: Low | N13: =IFERROR(VLOOKUP(M13,ShipShapeEnum!$H:$I,2,FALSE),"-") -> 1 | O13: - | Q13: =IFERROR(INDEX(SailPattern!$A:$A,MATCH(P13,SailPattern!$B:$B,0)),"-") -> - | S13: =IFERROR(INDEX(SailCrest!$A:$A,MATCH(R13,SailCrest!$B:$B,0)),"-") -> - | T13: - | U13: - | V13: - | W13: - | X13: - | Y13: - | Z13: - | AA13: -
A14: =A13+1 -> 46000005 | B14: 캐러벨적흑돛 | C14: Sail | D14: =IFERROR(VLOOKUP(C14,ShipShapeEnum!$E:$F,2,FALSE),"-") -> 1 | E14: SK_Ship_Caravel_Sail | F14: SkeletalMesh | G14: =IFERROR(VLOOKUP(F14,ShipShapeEnum!$B:$C,2,FALSE),"-") -> 1 | H14: - | I14: - | J14: - | K14: - | L14: - | M14: Low | N14: =IFERROR(VLOOKUP(M14,ShipShapeEnum!$H:$I,2,FALSE),"-") -> 1 | O14: - | Q14: =IFERROR(INDEX(SailPattern!$A:$A,MATCH(P14,SailPattern!$B:$B,0)),"-") -> - | S14: =IFERROR(INDEX(SailCrest!$A:$A,MATCH(R14,SailCrest!$B:$B,0)),"-") -> - | T14: 2 | U14: M_Ship_Sail_BlackRed_Inst | V14: 3 | W14: M_Ship_Sail_BlackRed_Inst | X14: - | Y14: - | Z14: - | AA14: -
A15: =A14+1 -> 46000006 | B15: 캐러벨적흑돛_해골 | C15: Sail | D15: =IFERROR(VLOOKUP(C15,ShipShapeEnum!$E:$F,2,FALSE),"-") -> 1 | E15: SK_Ship_Caravel_Sail | F15: SkeletalMesh | G15: =IFERROR(VLOOKUP(F15,ShipShapeEnum!$B:$C,2,FALSE),"-") -> 1 | H15: - | I15: - | J15: - | K15: - | L15: - | M15: Low | N15: =IFERROR(VLOOKUP(M15,ShipShapeEnum!$H:$I,2,FALSE),"-") -> 1 | O15: - | Q15: =IFERROR(INDEX(SailPattern!$A:$A,MATCH(P15,SailPattern!$B:$B,0)),"-") -> - | S15: =IFERROR(INDEX(SailCrest!$A:$A,MATCH(R15,SailCrest!$B:$B,0)),"-") -> - | T15: - | U15: - | V15: - | W15: - | X15: - | Y15: - | Z15: - | AA15: -
A16: =A15+1 -> 46000007 | B16: 캐러벨무적함대돛 | C16: Sail | D16: =IFERROR(VLOOKUP(C16,ShipShapeEnum!$E:$F,2,FALSE),"-") -> 1 | E16: SK_Ship_Caravel_Sail | F16: SkeletalMesh | G16: =IFERROR(VLOOKUP(F16,ShipShapeEnum!$B:$C,2,FALSE),"-") -> 1 | H16: - | I16: - | J16: - | K16: - | L16: - | M16: Low | N16: =IFERROR(VLOOKUP(M16,ShipShapeEnum!$H:$I,2,FALSE),"-") -> 1 | O16: - | Q16: =IFERROR(INDEX(SailPattern!$A:$A,MATCH(P16,SailPattern!$B:$B,0)),"-") -> - | S16: =IFERROR(INDEX(SailCrest!$A:$A,MATCH(R16,SailCrest!$B:$B,0)),"-") -> - | T16: 2 | U16: M_Ship_Sail_Armada_Emblem_Inst | V16: 3 | W16: M_Ship_Sail_Triagle_Armada_Inst | X16: - | Y16: - | Z16: - | AA16: -
