Workbook
Name SailCrest: SailCrest!$A$1:$N$114
Name SailPattern: SailPattern!$A$1:$T$74
Name SailPatternColor: SailPatternColor!$A$1:$M$59
Name ShipBodyFirstColor: ShipBodyFirstColor!$A$1:$L$49
Name ShipBodySecondColor: ShipBodySecondColor!$A$1:$L$49
Name ShipBodyShape: ShipBodyShape!$A$1:$AR$115
Name ShipPartShape: ShipPartShape!$A$1:$X$268

Sheet ShipBodyShape
A1: id | C1: meshName | E1: meshDensity | F1: buoyancyRadius | G1: parts["0"] | I1: parts["1"] | K1: parts["2"] | M1: parts["3"] | O1: parts["4"] | Q1: parts["5"] | S1: parts["6"] | U1: parts["7"] | W1: parts["8"] | Y1: parts["9"] | AA1: parts["10"] | AC1: parts["11"] | AE1: parts["12"] | AG1: parts["13"] | AH1: colorTint | AI1: color1 | AJ1: color2 | AK1: materials[0]["index"] | AL1: materials[0]["name"] | AM1: materials[1]["index"] | AN1: materials[1]["name"] | AO1: materials[2]["index"] | AP1: materials[2]["name"] | AQ1: materials[3]["index"] | AR1: materials[3]["name"]
A2: key:45000000~45999999 | C2: string | E2: number | F2: number | G2: number | I2: number | K2: number | M2: number | O2: number | Q2: number | S2: number | U2: number | W2: number | Y2: number | AA2: number | AC2: number | AE2: number | AG2: number | AH2: number | AI2: number | AJ2: number | AK2: number | AL2: string | AM2: number | AN2: string | AO2: number | AP2: string | AQ2: number | AR2: string
A3: :required | B3: - | C3: 1 | D3: - | E3: - | F3: - | G3: - | H3: - | I3: - | J3: - | K3: - | L3: - | M3: - | N3: - | O3: - | P3: - | Q3: - | R3: - | S3: - | U3: - | W3: - | Y3: - | AA3: - | AC3: - | AE3: - | AG3: - | AH3: - | AI3: - | AJ3: - | AK3: - | AL3: - | AM3: - | AN3: - | AO3: - | AP3: - | AQ3: - | AR3: -
A4: :requireedInObject | B4: - | C4: - | D4: - | E4: - | F4: - | G4: 1 | H4: - | I4: 1 | J4: - | K4: 1 | L4: - | M4: 1 | N4: - | O4: 1 | P4: - | Q4: 1 | R4: - | S4: 1 | U4: 1 | W4: 1 | Y4: 1 | AA4: 1 | AC4: 1 | AE4: 1 | AG4: 1 | AH4: - | AI4: - | AJ4: - | AK4: 1 | AL4: 1 | AM4: 1 | AN4: 1 | AO4: 1 | AP4: 1 | AQ4: 1 | AR4: 1
A5: :min | B5: - | C5: - | D5: - | E5: 10 | F5: 10 | G5: - | H5: - | I5: - | J5: - | K5: - | L5: - | M5: - | N5: - | O5: - | P5: - | Q5: - | R5: - | S5: - | U5: - | W5: - | Y5: - | AA5: - | AC5: - | AE5: - | AG5: - | AH5: - | AI5: - | AJ5: - | AK5: - | AL5: - | AM5: - | AN5: - | AO5: - | AP5: - | AQ5: - | AR5: -
A6: :max | B6: - | C6: - | D6: - | E6: 1000 | F6: 1000 | G6: - | H6: - | I6: - | J6: - | K6: - | L6: - | M6: - | N6: - | O6: - | P6: - | Q6: - | R6: - | S6: - | U6: - | W6: - | Y6: - | AA6: - | AC6: - | AE6: - | AG6: - | AH6: - | AI6: - | AJ6: - | AK6: - | AL6: - | AM6: - | AN6: - | AO6: - | AP6: - | AQ6: - | AR6: -
A7: :enum | B7: - | C7: - | D7: - | E7: - | F7: - | G7: - | H7: - | I7: - | J7: - | K7: - | L7: - | M7: - | N7: - | O7: - | P7: - | Q7: - | R7: - | S7: - | U7: - | W7: - | Y7: - | AA7: - | AC7: - | AE7: - | AG7: - | AH7: - | AI7: - | AJ7: - | AK7: - | AL7: - | AM7: - | AN7: - | AO7: - | AP7: - | AQ7: - | AR7: -
A8: :links | B8: - | C8: - | D8: - | E8: - | F8: - | G8: "ShipPartShape" | H8: - | I8: "ShipPartShape" | J8: - | K8: "ShipPartShape" | L8: - | M8: "ShipPartShape" | N8: - | O8: "ShipPartShape" | P8: - | Q8: "ShipPartShape" | R8: - | S8: "ShipPartShape" | U8: "ShipPartShape" | W8: "ShipPartShape" | Y8: "ShipPartShape" | AA8: "ShipPartShape" | AC8: "ShipPartShape" | AE8: "ShipPartShape" | AG8: "ShipPartShape" | AH8: - | AI8: - | AJ8: - | AK8: - | AL8: - | AM8: - | AN8: - | AO8: - | AP8: - | AQ8: - | AR8: -
A9: :asset | B9: - | C9: 1 | D9: - | E9: - | F9: - | G9: - | H9: - | I9: - | J9: - | K9: - | L9: - | M9: - | N9: - | O9: - | P9: - | Q9: - | R9: - | S9: - | U9: - | W9: - | Y9: - | AA9: - | AC9: - | AE9: - | AG9: - | AH9: - | AI9: - | AJ9: - | AK9: - | AL9: 1 | AM9: - | AN9: 1 | AO9: - | AP9: 1 | AQ9: - | AR9: 1
A10: 45000000 | B10: 중 캐러벨 | C10: SK_Ship_Caravel_Body | D10: 캐러벨흰색돛 | E10: 700 | F10: 80 | G10: =IFERROR(INDEX(ShipPartShape!$A:$A,MATCH(D10,ShipPartShape!$B:$B,0)),"-") -> 46000001 | H10: 램프_기본 | I10: =IFERROR(INDEX(ShipPartShape!$A:$A,MATCH(H10,ShipPartShape!$B:$B,0)),"-") -> 46700001 | K10: =IFERROR(INDEX(ShipPartShape!$A:$A,MATCH(J10,ShipPartShape!$B:$B,0)),"-") -> - | M10: =IFERROR(INDEX(ShipPartShape!$A:$A,MATCH(L10,ShipPartShape!$B:$B,0)),"-") -> - | O10: =IFERROR(INDEX(ShipPartShape!$A:$A,MATCH(N10,ShipPartShape!$B:$B,0)),"-") -> - | Q10: =IFERROR(INDEX(ShipPartShape!$A:$A,MATCH(P10,ShipPartShape!$B:$B,0)),"-") -> - | R10: 선박외형장식_C | S10: =IFERROR(INDEX(ShipPartShape!$A:$A,MATCH(R10,ShipPartShape!$B:$B,0)),"-") -> 46600003 | T10: 선박외형장식_D | U10: =IFERROR(INDEX(ShipPartShape!$A:$A,MATCH(T10,ShipPartShape!$B:$B,0)),"-") -> 46600004 | V10: 선박외형장식_E | W10: =IFERROR(INDEX(ShipPartShape!$A:$A,MATCH(V10,ShipPartShape!$B:$B,0)),"-") -> 46600005 | X10: 선박외형장식_G | Y10: =IFERROR(INDEX(ShipPartShape!$A:$A,MATCH(X10,ShipPartShape!$B:$B,0)),"-") -> 46600007 | AA10: =IFERROR(INDEX(ShipPartShape!$A:$A,MATCH(Z10,ShipPartShape!$B:$B,0)),"-") -> - | AB10: 아나히타상 | AC10: =IFERROR(INDEX(ShipPartShape!$A:$A,MATCH(AB10,ShipPartShape!$B:$B,0)),"-") -> 46100019 | AE10: =IFERROR(INDEX(ShipPartShape!$A:$A,MATCH(AD10,ShipPartShape!$B:$B,0)),"-") -> - | AG10: =IFERROR(INDEX(ShipPartShape!$A:$A,MATCH(AF10,ShipPartShape!$B:$B,0)),"-") -> - | AH10: - | AI10: - | AJ10: - | AK10: - | AL10: - | AM10: - | AN10: - | AO10: - | AP10: - | AQ10: - | AR10: -
A11: =A10+1 -> 45000001 | B11: 중 캐러벨_적선 | C11: SK_Ship_Caravel_Body | D11: 캐러벨적색돛 | E11: 700 | F11: 80 | G11: =IFERROR(INDEX(ShipPartShape!$A:$A,MATCH(D11,ShipPartShape!$B:$B,0)),"-") -> 46000002 | H11: 대포_기본 | I11: =IFERROR(INDEX(ShipPartShape!$A:$A,MATCH(H11,ShipPartShape!$B:$B,0)),"-") -> 46300001 | J11: 램프_기본 | K11: =IFERROR(INDEX(ShipPartShape!$A:$A,MATCH(J11,ShipPartShape!$B:$B,0)),"-") -> 46700001 | M11: =IFERROR(INDEX(ShipPartShape!$A:$A,MATCH(L11,ShipPartShape!$B:$B,0)),"-") -> - | O11: =IFERROR(INDEX(ShipPartShape!$A:$A,MATCH(N11,ShipPartShape!$B:$B,0)),"-") -> - | Q11: =IFERROR(INDEX(ShipPartShape!$A:$A,MATCH(P11,ShipPartShape!$B:$B,0)),"-") -> - | S11: =IFERROR(INDEX(ShipPartShape!$A:$A,MATCH(R11,ShipPartShape!$B:$B,0)),"-") -> - | U11: =IFERROR(INDEX(ShipPartShape!$A:$A,MATCH(T11,ShipPartShape!$B:$B,0)),"-") -> - | W11: =IFERROR(INDEX(ShipPartShape!$A:$A,MATCH(V11,ShipPartShape!$B:$B,0)),"-") -> - | Y11: =IFERROR(INDEX(ShipPartShape!$A:$A,MATCH(X11,ShipPartShape!$B:$B,0)),"-") -> - | AA11: =IFERROR(INDEX(ShipPartShape!$A:$A,MATCH(Z11,ShipPartShape!$B:$B,0)),"-") -> - | AC11: =IFERROR(INDEX(ShipPartShape!$A:$A,MATCH(AB11,ShipPartShape!$B:$B,0)),"-") -> - | AE11: =IFERROR(INDEX(ShipPartShape!$A:$A,MATCH(AD11,ShipPartShape!$B:$B,0)),"-") -> - | AG11: =IFERROR(INDEX(ShipPartShape!$A:$A,MATCH(AF11,ShipPartShape!$B:$B,0)),"-") -> - | AH11: - | AI11: - | AJ11: - | AK11: - | AL11: - | AM11: - | AN11: - | AO11: - | AP11: - | AQ11: - | AR11: -
A12: =A11+1 -> 45000002 | B12: 중 캐러벨_유령선 | C12: SK_Ship_Caravel_Body | D12: 캐러벨유령선돛 | E12: 700 | F12: 80 | G12: =IFERROR(INDEX(ShipPartShape!$A:$A,MATCH(D12,ShipPartShape!$B:$B,0)),"-") -> 46000003 | H12: 독수리상 | I12: =IFERROR(INDEX(ShipPartShape!$A:$A,MATCH(H12,ShipPartShape!$B:$B,0)),"-") -> 46100002 | J12: 충각_기본 | K12: =IFERROR(INDEX(ShipPartShape!$A:$A,MATCH(J12,ShipPartShape!$B:$B,0)),"-") -> 46200001 | L12: 대포_기본 | M12: =IFERROR(INDEX(ShipPartShape!$A:$A,MATCH(L12,ShipPartShape!$B:$B,0)),"-") -> 46300001 | O12: =IFERROR(INDEX(ShipPartShape!$A:$A,MATCH(N12,ShipPartShape!$B:$B,0)),"-") -> - | Q12: =IFERROR(INDEX(ShipPartShape!$A:$A,MATCH(P12,ShipPartShape!$B:$B,0)),"-") -> - | S12: =IFERROR(INDEX(ShipPartShape!$A:$A,MATCH(R12,ShipPartShape!$B:$B,0)),"-") -> - | U12: =IFERROR(INDEX(ShipPartShape!$A:$A,MATCH(T12,ShipPartShape!$B:$B,0)),"-") -> - | W12: =IFERROR(INDEX(ShipPartShape!$A:$A,MATCH(V12,ShipPartShape!$B:$B,0)),"-") -> - | Y12: =IFERROR(INDEX(ShipPartShape!$A:$A,MATCH(X12,ShipPartShape!$B:$B,0)),"-") -> - | AA12: =IFERROR(INDEX(ShipPartShape!$A:$A,MATCH(Z12,ShipPartShape!$B:$B,0)),"-") -> - | AC12: =IFERROR(INDEX(ShipPartShape!$A:$A,MATCH(AB12,ShipPartShape!$B:$B,0)),"-") -> - | AE12: =IFERROR(INDEX(ShipPartShape!$A:$A,MATCH(AD12,ShipPartShape!$B:$B,0)),"-") -> - | AG12: =IFERROR(INDEX(ShipPartShape!$A:$A,MATCH(AF12,ShipPartShape!$B:$B,0)),"-") -> - | AH12: - | AI12: - | AJ12: - | AK12: - | AL12: - | AM12: - | AN12: - | AO12: - | AP12: - | AQ12: - | AR12: -
A13: =A12+1 -> 45000003 | B13: 중 캐러벨2 | C13: SK_Ship_Caravel_Body | D13: 캐러벨적백돛 | E13: 700 | F13: 80 | G13: =IFERROR(INDEX(ShipPartShape!$A:$A,MATCH(D13,ShipPartShape!$B:$B,0)),"-") -> 46000004 | H13: 충각_기본 | I13: =IFERROR(INDEX(ShipPartShape!$A:$A,MATCH(H13,ShipPartShape!$B:$B,0)),"-") -> 46200001 | J13: 대포_기본 | K13: =IFERROR(INDEX(ShipPartShape!$A:$A,MATCH(J13,ShipPartShape!$B:$B,0)),"-") -> 46300001 | L13: 램프_기본 | M13: =IFERROR(INDEX(ShipPartShape!$A:$A,MATCH(L13,ShipPartShape!$B:$B,0)),"-") -> 46700001 | O13: =IFERROR(INDEX(ShipPartShape!$A:$A,MATCH(N13,ShipPartShape!$B:$B,0)),"-") -> - | Q13: =IFERROR(INDEX(ShipPartShape!$A:$A,MATCH(P13,ShipPartShape!$B:$B,0)),"-") -> - | S13: =IFERROR(INDEX(ShipPartShape!$A:$A,MATCH(R13,ShipPartShape!$B:$B,0)),"-") -> - | U13: =IFERROR(INDEX(ShipPartShape!$A:$A,MATCH(T13,ShipPartShape!$B:$B,0)),"-") -> - | W13: =IFERROR(INDEX(ShipPartShape!$A:$A,MATCH(V13,ShipPartShape!$B:$B,0)),"-") -> - | Y13: =IFERROR(INDEX(ShipPartShape!$A:$A,MATCH(X13,ShipPartShape!$B:$B,0)),"-") -> - | AA13: =IFERROR(INDEX(ShipPartShape!$A:$A,MATCH(Z13,ShipPartShape!$B:$B,0)),"-") -> - | AC13: =IFERROR(INDEX(ShipPartShape!$A:$A,MATCH(AB13,ShipPartShape!$B:$B,0)),"-") -> - | AE13: =IFERROR(INDEX(ShipPartShape!$A:$A,MATCH(AD13,ShipPartShape!$B:$B,0)),"-") -> - | AG13: =IFERROR(INDEX(ShipPartShape!$A:$A,MATCH(AF13,ShipPartShape!$B:$B,0)),"-") -> - | AH13: - | AI13: - | AJ13: - | AK13: - | AL13: - | AM13: - | AN13: - | AO13: - | AP13: - | AQ13: - | AR13: -
A14: =A13+1 -> 45000004 | B14: 중 캐러벨3 | C14: SK_Ship_Caravel_Body | D14: 캐러벨적흑돛 | E14: 700 | F14: 80 | G14: =IFERROR(INDEX(ShipPartShape!$A:$A,MATCH(D14,ShipPartShape!$B:$B,0)),"-") -> 46000005 | H14: 충각_기본 | I14: =IFERROR(INDEX(ShipPartShape!$A:$A,MATCH(H14,ShipPartShape!$B:$B,0)),"-") -> 46200001 | J14: 대포_기본 | K14: =IFERROR(INDEX(ShipPartShape!$A:$A,MATCH(J14,ShipPartShape!$B:$B,0)),"-") -> 46300001 | L14: 램프_기본 | M14: =IFERROR(INDEX(ShipPartShape!$A:$A,MATCH(L14,ShipPartShape!$B:$B,0)),"-") -> 46700001 | O14: =IFERROR(INDEX(ShipPartShape!$A:$A,MATCH(N14,ShipPartShape!$B:$B,0)),"-") -> - | Q14: =IFERROR(INDEX(ShipPartShape!$A:$A,MATCH(P14,ShipPartShape!$B:$B,0)),"-") -> - | S14: =IFERROR(INDEX(ShipPartShape!$A:$A,MATCH(R14,ShipPartShape!$B:$B,0)),"-") -> - | U14: =IFERROR(INDEX(ShipPartShape!$A:$A,MATCH(T14,ShipPartShape!$B:$B,0)),"-") -> - | W14: =IFERROR(INDEX(ShipPartShape!$A:$A,MATCH(V14,ShipPartShape!$B:$B,0)),"-") -> - | Y14: =IFERROR(INDEX(ShipPartShape!$A:$A,MATCH(X14,ShipPartShape!$B:$B,0)),"-") -> - | AA14: =IFERROR(INDEX(ShipPartShape!$A:$A,MATCH(Z14,ShipPartShape!$B:$B,0)),"-") -> - | AC14: =IFERROR(INDEX(ShipPartShape!$A:$A,MATCH(AB14,ShipPartShape!$B:$B,0)),"-") -> - | AE14: =IFERROR(INDEX(ShipPartShape!$A:$A,MATCH(AD14,ShipPartShape!$B:$B,0)),"-") -> - | AG14: =IFERROR(INDEX(ShipPartShape!$A:$A,MATCH(AF14,ShipPartShape!$B:$B,0)),"-") -> - | AH14: - | AI14: - | AJ14: - | AK14: - | AL14: - | AM14: - | AN14: - | AO14: - | AP14: - | AQ14: - | AR14: -
A15: =A14+1 -> 45000005 | B15: 중 캐러벨_해적1 | C15: SK_Ship_Caravel_Body | D15: 캐러벨적흑돛_해골 | E15: 700 | F15: 80 | G15: =IFERROR(INDEX(ShipPartShape!$A:$A,MATCH(D15,ShipPartShape!$B:$B,0)),"-") -> 46000006 | H15: 충각_기본 | I15: =IFERROR(INDEX(ShipPartShape!$A:$A,MATCH(H15,ShipPartShape!$B:$B,0)),"-") -> 46200001 | J15: 대포_기본 | K15: =IFERROR(INDEX(ShipPartShape!$A:$A,MATCH(J15,ShipPartShape!$B:$B,0)),"-") -> 46300001 | L15: 램프_기본 | M15: =IFERROR(INDEX(ShipPartShape!$A:$A,MATCH(L15,ShipPartShape!$B:$B,0)),"-") -> 46700001 | O15: =IFERROR(INDEX(ShipPartShape!$A:$A,MATCH(N15,ShipPartShape!$B:$B,0)),"-") -> - | Q15: =IFERROR(INDEX(ShipPartShape!$A:$A,MATCH(P15,ShipPartShape!$B:$B,0)),"-") -> - | S15: =IFERROR(INDEX(ShipPartShape!$A:$A,MATCH(R15,ShipPartShape!$B:$B,0)),"-") -> - | U15: =IFERROR(INDEX(ShipPartShape!$A:$A,MATCH(T15,ShipPartShape!$B:$B,0)),"-") -> - | W15: =IFERROR(INDEX(ShipPartShape!$A:$A,MATCH(V15,ShipPartShape!$B:$B,0)),"-") -> - | Y15: =IFERROR(INDEX(ShipPartShape!$A:$A,MATCH(X15,ShipPartShape!$B:$B,0)),"-") -> - | AA15: =IFERROR(INDEX(ShipPartShape!$A:$A,MATCH(Z15,ShipPartShape!$B:$B,0)),"-") -> - | AC15: =IFERROR(INDEX(ShipPartShape!$A:$A,MATCH(AB15,ShipPartShape!$B:$B,0)),"-") -> - | AE15: =IFERROR(INDEX(ShipPartShape!$A:$A,MATCH(AD15,ShipPartShape!$B:$B,0)),"-") -> - | AG15: =IFERROR(INDEX(ShipPartShape!$A:$A,MATCH(AF15,ShipPartShape!$B:$B,0)),"-") -> - | AH15: - | AI15: - | AJ15: - | AK15: - | AL15: - | AM15: - | AN15: - | AO15: - | AP15: - | AQ15: - | AR15: -
A16: =A15+1 -> 45000006 | B16: 중 캐러벨_스페인 | C16: SK_Ship_Caravel_Body | D16: 캐러벨무적함대돛 | E16: 700 | F16: 80 | G16: =IFERROR(INDEX(ShipPartShape!$A:$A,MATCH(D16,ShipPartShape!$B:$B,0)),"-") -> 46000007 | H16: 독수리상 | I16: =IFERROR(INDEX(ShipPartShape!$A:$A,MATCH(H16,ShipPartShape!$B:$B,0)),"-") -> 46100002 | J16: 충각_기본 | K16: =IFERROR(INDEX(ShipPartShape!$A:$A,MATCH(J16,ShipPartShape!$B:$B,0)),"-") -> 46200001 | L16: 대포_기본 | M16: =IFERROR(INDEX(ShipPartShape!$A:$A,MATCH(L16,ShipPartShape!$B:$B,0)),"-") -> 46300001 | N16: 램프_기본 | O16: =IFERROR(INDEX(ShipPartShape!$A:$A,MATCH(N16,ShipPartShape!$B:$B,0)),"-") -> 46700001 | Q16: =IFERROR(INDEX(ShipPartShape!$A:$A,MATCH(P16,ShipPartShape!$B:$B,0)),"-") -> - | S16: =IFERROR(INDEX(ShipPartShape!$A:$A,MATCH(R16,ShipPartShape!$B:$B,0)),"-") -> - | U16: =IFERROR(INDEX(ShipPartShape!$A:$A,MATCH(T16,ShipPartShape!$B:$B,0)),"-") -> - | W16: =IFERROR(INDEX(ShipPartShape!$A:$A,MATCH(V16,ShipPartShape!$B:$B,0)),"-") -> - | Y16: =IFERROR(INDEX(ShipPartShape!$A:$A,MATCH(X16,ShipPartShape!$B:$B,0)),"-") -> - | AA16: =IFERROR(INDEX(ShipPartShape!$A:$A,MATCH(Z16,ShipPartShape!$B:$B,0)),"-") -> - | AC16: =IFERROR(INDEX(ShipPartShape!$A:$A,MATCH(AB16,ShipPartShape!$B:$B,0)),"-") -> - | AE16: =IFERROR(INDEX(ShipPartShape!$A:$A,MATCH(AD16,ShipPartShape!$B:$B,0)),"-") -> - | AG16: =IFERROR(INDEX(ShipPartShape!$A:$A,MATCH(AF16,ShipPartShape!$B:$B,0)),"-") -> - | AH16: - | AI16: - | AJ16: - | AK16: - | AL16: - | AM16: - | AN16: - | AO16: - | AP16: - | AQ16: - | AR16: -
A17: =A16+1 -> 45000007 | B17: 바르카 | C17: SK_Ship_Barca_Body | D17: 바르카3흰색돛 | E17: 600 | F17: 50 | G17: =IFERROR(INDEX(ShipPartShape!$A:$A,MATCH(D17,ShipPartShape!$B:$B,0)),"-") -> 46000008 | H17: 램프_기본 | I17: =IFERROR(INDEX(ShipPartShape!$A:$A,MATCH(H17,ShipPartShape!$B:$B,0)),"-") -> 46700001 | K17: =IFERROR(INDEX(ShipPartShape!$A:$A,MATCH(J17,ShipPartShape!$B:$B,0)),"-") -> - | M17: =IFERROR(INDEX(ShipPartShape!$A:$A,MATCH(L17,ShipPartShape!$B:$B,0)),"-") -> - | O17: =IFERROR(INDEX(ShipPartShape!$A:$A,MATCH(N17,ShipPartShape!$B:$B,0)),"-") -> - | Q17: =IFERROR(INDEX(ShipPartShape!$A:$A,MATCH(P17,ShipPartShape!$B:$B,0)),"-") -> - | R17: 선박외형장식_A | S17: =IFERROR(INDEX(ShipPartShape!$A:$A,MATCH(R17,ShipPartShape!$B:$B,0)),"-") -> 46600001 | T17: 선박외형장식_B | U17: =IFERROR(INDEX(ShipPartShape!$A:$A,MATCH(T17,ShipPartShape!$B:$B,0)),"-") -> 46600002 | V17: 선박외형장식_G | W17: =IFERROR(INDEX(ShipPartShape!$A:$A,MATCH(V17,ShipPartShape!$B:$B,0)),"-") -> 46600007 | X17: 선박외형장식_E | Y17: =IFERROR(INDEX(ShipPartShape!$A:$A,MATCH(X17,ShipPartShape!$B:$B,0)),"-") -> 46600005 | AA17: =IFERROR(INDEX(ShipPartShape!$A:$A,MATCH(Z17,ShipPartShape!$B:$B,0)),"-") -> - | AB17: 천사상 | AC17: =IFERROR(INDEX(ShipPartShape!$A:$A,MATCH(AB17,ShipPartShape!$B:$B,0)),"-") -> 46100020 | AE17: =IFERROR(INDEX(ShipPartShape!$A:$A,MATCH(AD17,ShipPartShape!$B:$B,0)),"-") -> - | AG17: =IFERROR(INDEX(ShipPartShape!$A:$A,MATCH(AF17,ShipPartShape!$B:$B,0)),"-") -> - | AH17: - | AI17: - | AJ17: - | AK17: - | AL17: - | AM17: - | AN17: - | AO17: - | AP17: - | AQ17: - | AR17: -
A18: =A17+1 -> 45000008 | B18: 적선바르카_삼각 | C18: SK_Ship_Barca_Body | D18: 바르카3적색돛 | E18: 600 | F18: 50 | G18: =IFERROR(INDEX(ShipPartShape!$A:$A,MATCH(D18,ShipPartShape!$B:$B,0)),"-") -> 46000009 | H18: 대포_기본 | I18: =IFERROR(INDEX(ShipPartShape!$A:$A,MATCH(H18,ShipPartShape!$B:$B,0)),"-") -> 46300001 | J18: 램프_기본 | K18: =IFERROR(INDEX(ShipPartShape!$A:$A,MATCH(J18,ShipPartShape!$B:$B,0)),"-") -> 46700001 | M18: =IFERROR(INDEX(ShipPartShape!$A:$A,MATCH(L18,ShipPartShape!$B:$B,0)),"-") -> - | O18: =IFERROR(INDEX(ShipPartShape!$A:$A,MATCH(N18,ShipPartShape!$B:$B,0)),"-") -> - | Q18: =IFERROR(INDEX(ShipPartShape!$A:$A,MATCH(P18,ShipPartShape!$B:$B,0)),"-") -> - | S18: =IFERROR(INDEX(ShipPartShape!$A:$A,MATCH(R18,ShipPartShape!$B:$B,0)),"-") -> - | U18: =IFERROR(INDEX(ShipPartShape!$A:$A,MATCH(T18,ShipPartShape!$B:$B,0)),"-") -> - | W18: =IFERROR(INDEX(ShipPartShape!$A:$A,MATCH(V18,ShipPartShape!$B:$B,0)),"-") -> - | Y18: =IFERROR(INDEX(ShipPartShape!$A:$A,MATCH(X18,ShipPartShape!$B:$B,0)),"-") -> - | AA18: =IFERROR(INDEX(ShipPartShape!$A:$A,MATCH(Z18,ShipPartShape!$B:$B,0)),"-") -> - | AC18: =IFERROR(INDEX(ShipPartShape!$A:$A,MATCH(AB18,ShipPartShape!$B:$B,0)),"-") -> - | AE18: =IFERROR(INDEX(ShipPartShape!$A:$A,MATCH(AD18,ShipPartShape!$B:$B,0)),"-") -> - | AG18: =IFERROR(INDEX(ShipPartShape!$A:$A,MATCH(AF18,ShipPartShape!$B:$B,0)),"-") -> - | AH18: - | AI18: - | AJ18: - | AK18: - | AL18: - | AM18: - | AN18: - | AO18: - | AP18: - | AQ18: - | AR18: -
A19: =A18+1 -> 45000009 | B19: 유령선바르카_삼각 | C19: SK_Ship_Barca_Body | D19: 바르카3유령선돛 | E19: 600 | F19: 50 | G19: =IFERROR(INDEX(ShipPartShape!$A:$A,MATCH(D19,ShipPartShape!$B:$B,0)),"-") -> 46000010 | H19: 독수리상 | I19: =IFERROR(INDEX(ShipPartShape!$A:$A,MATCH(H19,ShipPartShape!$B:$B,0)),"-") -> 46100002 | J19: 충각_기본 | K19: =IFERROR(INDEX(ShipPartShape!$A:$A,MATCH(J19,ShipPartShape!$B:$B,0)),"-") -> 46200001 | L19: 대포_기본 | M19: =IFERROR(INDEX(ShipPartShape!$A:$A,MATCH(L19,ShipPartShape!$B:$B,0)),"-") -> 46300001 | O19: =IFERROR(INDEX(ShipPartShape!$A:$A,MATCH(N19,ShipPartShape!$B:$B,0)),"-") -> - | Q19: =IFERROR(INDEX(ShipPartShape!$A:$A,MATCH(P19,ShipPartShape!$B:$B,0)),"-") -> - | S19: =IFERROR(INDEX(ShipPartShape!$A:$A,MATCH(R19,ShipPartShape!$B:$B,0)),"-") -> - | U19: =IFERROR(INDEX(ShipPartShape!$A:$A,MATCH(T19,ShipPartShape!$B:$B,0)),"-") -> - | W19: =IFERROR(INDEX(ShipPartShape!$A:$A,MATCH(V19,ShipPartShape!$B:$B,0)),"-") -> - | Y19: =IFERROR(INDEX(ShipPartShape!$A:$A,MATCH(X19,ShipPartShape!$B:$B,0)),"-") -> - | AA19: =IFERROR(INDEX(ShipPartShape!$A:$A,MATCH(Z19,ShipPartShape!$B:$B,0)),"-") -> - | AC19: =IFERROR(INDEX(ShipPartShape!$A:$A,MATCH(AB19,ShipPartShape!$B:$B,0)),"-") -> - | AE19: =IFERROR(INDEX(ShipPartShape!$A:$A,MATCH(AD19,ShipPartShape!$B:$B,0)),"-") -> - | AG19: =IFERROR(INDEX(ShipPartShape!$A:$A,MATCH(AF19,ShipPartShape!$B:$B,0)),"-") -> - | AH19: - | AI19: - | AJ19: - | AK19: - | AL19: - | AM19: - | AN19: - | AO19: - | AP19: - | AQ19: - | AR19: -
A20: =A19+1 -> 45000010 | B20: 바르카2_삼각 | C20: SK_Ship_Barca_Body | D20: 바르카3적백돛 | E20: 600 | F20: 50 | G20: =IFERROR(INDEX(ShipPartShape!$A:$A,MATCH(D20,ShipPartShape!$B:$B,0)),"-") -> 46000011 | H20: 충각_기본 | I20: =IFERROR(INDEX(ShipPartShape!$A:$A,MATCH(H20,ShipPartShape!$B:$B,0)),"-") -> 46200001 | J20: 대포_기본 | K20: =IFERROR(INDEX(ShipPartShape!$A:$A,MATCH(J20,ShipPartShape!$B:$B,0)),"-") -> 46300001 | L20: 램프_기본 | M20: =IFERROR(INDEX(ShipPartShape!$A:$A,MATCH(L20,ShipPartShape!$B:$B,0)),"-") -> 46700001 | N20: 닻 | O20: =IFERROR(INDEX(ShipPartShape!$A:$A,MATCH(N20,ShipPartShape!$B:$B,0)),"-") -> 46400001 | Q20: =IFERROR(INDEX(ShipPartShape!$A:$A,MATCH(P20,ShipPartShape!$B:$B,0)),"-") -> - | S20: =IFERROR(INDEX(ShipPartShape!$A:$A,MATCH(R20,ShipPartShape!$B:$B,0)),"-") -> - | U20: =IFERROR(INDEX(ShipPartShape!$A:$A,MATCH(T20,ShipPartShape!$B:$B,0)),"-") -> - | W20: =IFERROR(INDEX(ShipPartShape!$A:$A,MATCH(V20,ShipPartShape!$B:$B,0)),"-") -> - | Y20: =IFERROR(INDEX(ShipPartShape!$A:$A,MATCH(X20,ShipPartShape!$B:$B,0)),"-") -> - | AA20: =IFERROR(INDEX(ShipPartShape!$A:$A,MATCH(Z20,ShipPartShape!$B:$B,0)),"-") -> - | AC20: =IFERROR(INDEX(ShipPartShape!$A:$A,MATCH(AB20,ShipPartShape!$B:$B,0)),"-") -> - | AE20: =IFERROR(INDEX(ShipPartShape!$A:$A,MATCH(AD20,ShipPartShape!$B:$B,0)),"-") -> - | AG20: =IFERROR(INDEX(ShipPartShape!$A:$A,MATCH(AF20,ShipPartShape!$B:$B,0)),"-") -> - | AH20: - | AI20: - | AJ20: - | AK20: - | AL20: - | AM20: - | AN20: - | AO20: - | AP20: - | AQ20: - | AR20: -
A21: =A20+1 -> 45000011 | B21: 바르카3_삼각 | C21: SK_Ship_Barca_Body | D21: 바르카3적흑돛 | E21: 600 | F21: 50 | G21: =IFERROR(INDEX(ShipPartShape!$A:$A,MATCH(D21,ShipPartShape!$B:$B,0)),"-") -> 46000012 | H21: 충각_기본 | I21: =IFERROR(INDEX(ShipPartShape!$A:$A,MATCH(H21,ShipPartShape!$B:$B,0)),"-") -> 46200001 | J21: 대포_기본 | K21: =IFERROR(INDEX(ShipPartShape!$A:$A,MATCH(J21,ShipPartShape!$B:$B,0)),"-") -> 46300001 | L21: 램프_기본 | M21: =IFERROR(INDEX(ShipPartShape!$A:$A,MATCH(L21,ShipPartShape!$B:$B,0)),"-") -> 46700001 | O21: =IFERROR(INDEX(ShipPartShape!$A:$A,MATCH(N21,ShipPartShape!$B:$B,0)),"-") -> - | Q21: =IFERROR(INDEX(ShipPartShape!$A:$A,MATCH(P21,ShipPartShape!$B:$B,0)),"-") -> - | S21: =IFERROR(INDEX(ShipPartShape!$A:$A,MATCH(R21,ShipPartShape!$B:$B,0)),"-") -> - | U21: =IFERROR(INDEX(ShipPartShape!$A:$A,MATCH(T21,ShipPartShape!$B:$B,0)),"-") -> - | W21: =IFERROR(INDEX(ShipPartShape!$A:$A,MATCH(V21,ShipPartShape!$B:$B,0)),"-") -> - | Y21: =IFERROR(INDEX(ShipPartShape!$A:$A,MATCH(X21,ShipPartShape!$B:$B,0)),"-") -> - | AA21: =IFERROR(INDEX(ShipPartShape!$A:$A,MATCH(Z21,ShipPartShape!$B:$B,0)),"-") -> - | AC21: =IFERROR(INDEX(ShipPartShape!$A:$A,MATCH(AB21,ShipPartShape!$B:$B,0)),"-") -> - | AE21: =IFERROR(INDEX(ShipPartShape!$A:$A,MATCH(AD21,ShipPartShape!$B:$B,0)),"-") -> - | AG21: =IFERROR(INDEX(ShipPartShape!$A:$A,MATCH(AF21,ShipPartShape!$B:$B,0)),"-") -> - | AH21: - | AI21: - | AJ21: - | AK21: - | AL21: - | AM21: - | AN21: - | AO21: - | AP21: - | AQ21: - | AR21: -
A22: =A21+1 -> 45000012 | B22: 바르카_해적1_삼각 | C22: SK_Ship_Barca_Body | D22: 바르카3적흑돛_해골 | E22: 600 | F22: 50 | G22: =IFERROR(INDEX(ShipPartShape!$A:$A,MATCH(D22,ShipPartShape!$B:$B,0)),"-") -> 46000013 | H22: 충각_기본 | I22: =IFERROR(INDEX(ShipPartShape!$A:$A,MATCH(H22,ShipPartShape!$B:$B,0)),"-") -> 46200001 | J22: 대포_기본 | K22: =IFERROR(INDEX(ShipPartShape!$A:$A,MATCH(J22,ShipPartShape!$B:$B,0)),"-") -> 46300001 | L22: 램프_기본 | M22: =IFERROR(INDEX(ShipPartShape!$A:$A,MATCH(L22,ShipPartShape!$B:$B,0)),"-") -> 46700001 | O22: =IFERROR(INDEX(ShipPartShape!$A:$A,MATCH(N22,ShipPartShape!$B:$B,0)),"-") -> - | Q22: =IFERROR(INDEX(ShipPartShape!$A:$A,MATCH(P22,ShipPartShape!$B:$B,0)),"-") -> - | S22: =IFERROR(INDEX(ShipPartShape!$A:$A,MATCH(R22,ShipPartShape!$B:$B,0)),"-") -> - | U22: =IFERROR(INDEX(ShipPartShape!$A:$A,MATCH(T22,ShipPartShape!$B:$B,0)),"-") -> - | W22: =IFERROR(INDEX(ShipPartShape!$A:$A,MATCH(V22,ShipPartShape!$B:$B,0)),"-") -> - | Y22: =IFERROR(INDEX(ShipPartShape!$A:$A,MATCH(X22,ShipPartShape!$B:$B,0)),"-") -> - | AA22: =IFERROR(INDEX(ShipPartShape!$A:$A,MATCH(Z22,ShipPartShape!$B:$B,0)),"-") -> - | AC22: =IFERROR(INDEX(ShipPartShape!$A:$A,MATCH(AB22,ShipPartShape!$B:$B,0)),"-") -> - | AE22: =IFERROR(INDEX(ShipPartShape!$A:$A,MATCH(AD22,ShipPartShape!$B:$B,0)),"-") -> - | AG22: =IFERROR(INDEX(ShipPartShape!$A:$A,MATCH(AF22,ShipPartShape!$B:$B,0)),"-") -> - | AH22: - | AI22: - | AJ22: - | AK22: - | AL22: - | AM22: - | AN22: - | AO22: - | AP22: - | AQ22: - | AR22: -
A23: =A22+1 -> 45000013 | B23: 바르카_사각 | C23: SK_Ship_Barca_Body | D23: 바르카4흰색돛 | E23: 600 | F23: 50 | G23: =IFERROR(INDEX(ShipPartShape!$A:$A,MATCH(D23,ShipPartShape!$B:$B,0)),"-") -> 46000014 | H23: 램프_기본 | I23: =IFERROR(INDEX(ShipPartShape!$A:$A,MATCH(H23,ShipPartShape!$B:$B,0)),"-") -> 46700001 | K23: =IFERROR(INDEX(ShipPartShape!$A:$A,MATCH(J23,ShipPartShape!$B:$B,0)),"-") -> - | M23: =IFERROR(INDEX(ShipPartShape!$A:$A,MATCH(L23,ShipPartShape!$B:$B,0)),"-") -> - | O23: =IFERROR(INDEX(ShipPartShape!$A:$A,MATCH(N23,ShipPartShape!$B:$B,0)),"-") -> - | Q23: =IFERROR(INDEX(ShipPartShape!$A:$A,MATCH(P23,ShipPartShape!$B:$B,0)),"-") -> - | S23: =IFERROR(INDEX(ShipPartShape!$A:$A,MATCH(R23,ShipPartShape!$B:$B,0)),"-") -> - | U23: =IFERROR(INDEX(ShipPartShape!$A:$A,MATCH(T23,ShipPartShape!$B:$B,0)),"-") -> - | W23: =IFERROR(INDEX(ShipPartShape!$A:$A,MATCH(V23,ShipPartShape!$B:$B,0)),"-") -> - | Y23: =IFERROR(INDEX(ShipPartShape!$A:$A,MATCH(X23,ShipPartShape!$B:$B,0)),"-") -> - | AA23: =IFERROR(INDEX(ShipPartShape!$A:$A,MATCH(Z23,ShipPartShape!$B:$B,0)),"-") -> - | AC23: =IFERROR(INDEX(ShipPartShape!$A:$A,MATCH(AB23,ShipPartShape!$B:$B,0)),"-") -> - | AE23: =IFERROR(INDEX(ShipPartShape!$A:$A,MATCH(AD23,ShipPartShape!$B:$B,0)),"-") -> - | AG23: =IFERROR(INDEX(ShipPartShape!$A:$A,MATCH(AF23,ShipPartShape!$B:$B,0)),"-") -> - | AH23: - | AI23: - | AJ23: - | AK23: - | AL23: - | AM23: - | AN23: - | AO23: - | AP23: - | AQ23: - | AR23: -
A24: =A23+1 -> 45000014 | B24: 바르카_사각_적선 | C24: SK_Ship_Barca_Body | D24: 바르카4적색돛 | E24: 600 | F24: 50 | G24: =IFERROR(INDEX(ShipPartShape!$A:$A,MATCH(D24,ShipPartShape!$B:$B,0)),"-") -> 46000015 | H24: 대포_기본 | I24: =IFERROR(INDEX(ShipPartShape!$A:$A,MATCH(H24,ShipPartShape!$B:$B,0)),"-") -> 46300001 | J24: 램프_기본 | K24: =IFERROR(INDEX(ShipPartShape!$A:$A,MATCH(J24,ShipPartShape!$B:$B,0)),"-") -> 46700001 | M24: =IFERROR(INDEX(ShipPartShape!$A:$A,MATCH(L24,ShipPartShape!$B:$B,0)),"-") -> - | O24: =IFERROR(INDEX(ShipPartShape!$A:$A,MATCH(N24,ShipPartShape!$B:$B,0)),"-") -> - | Q24: =IFERROR(INDEX(ShipPartShape!$A:$A,MATCH(P24,ShipPartShape!$B:$B,0)),"-") -> - | S24: =IFERROR(INDEX(ShipPartShape!$A:$A,MATCH(R24,ShipPartShape!$B:$B,0)),"-") -> - | U24: =IFERROR(INDEX(ShipPartShape!$A:$A,MATCH(T24,ShipPartShape!$B:$B,0)),"-") -> - | W24: =IFERROR(INDEX(ShipPartShape!$A:$A,MATCH(V24,ShipPartShape!$B:$B,0)),"-") -> - | Y24: =IFERROR(INDEX(ShipPartShape!$A:$A,MATCH(X24,ShipPartShape!$B:$B,0)),"-") -> - | AA24: =IFERROR(INDEX(ShipPartShape!$A:$A,MATCH(Z24,ShipPartShape!$B:$B,0)),"-") -> - | AC24: =IFERROR(INDEX(ShipPartShape!$A:$A,MATCH(AB24,ShipPartShape!$B:$B,0)),"-") -> - | AE24: =IFERROR(INDEX(ShipPartShape!$A:$A,MATCH(AD24,ShipPartShape!$B:$B,0)),"-") -> - | AG24: =IFERROR(INDEX(ShipPartShape!$A:$A,MATCH(AF24,ShipPartShape!$B:$B,0)),"-") -> - | AH24: - | AI24: - | AJ24: - | AK24: - | AL24: - | AM24: - | AN24: - | AO24: - | AP24: - | AQ24: - | AR24: -
A25: =A24+1 -> 45000015 | B25: 바르카_사각_유령선 | C25: SK_Ship_Barca_Body | D25: 바르카4유령선돛 | E25: 600 | F25: 50 | G25: =IFERROR(INDEX(ShipPartShape!$A:$A,MATCH(D25,ShipPartShape!$B:$B,0)),"-") -> 46000016 | H25: 독수리상 | I25: =IFERROR(INDEX(ShipPartShape!$A:$A,MATCH(H25,ShipPartShape!$B:$B,0)),"-") -> 46100002 | J25: 충각_기본 | K25: =IFERROR(INDEX(ShipPartShape!$A:$A,MATCH(J25,ShipPartShape!$B:$B,0)),"-") -> 46200001 | L25: 대포_기본 | M25: =IFERROR(INDEX(ShipPartShape!$A:$A,MATCH(L25,ShipPartShape!$B:$B,0)),"-") -> 46300001 | O25: =IFERROR(INDEX(ShipPartShape!$A:$A,MATCH(N25,ShipPartShape!$B:$B,0)),"-") -> - | Q25: =IFERROR(INDEX(ShipPartShape!$A:$A,MATCH(P25,ShipPartShape!$B:$B,0)),"-") -> - | S25: =IFERROR(INDEX(ShipPartShape!$A:$A,MATCH(R25,ShipPartShape!$B:$B,0)),"-") -> - | U25: =IFERROR(INDEX(ShipPartShape!$A:$A,MATCH(T25,ShipPartShape!$B:$B,0)),"-") -> - | W25: =IFERROR(INDEX(ShipPartShape!$A:$A,MATCH(V25,ShipPartShape!$B:$B,0)),"-") -> - | Y25: =IFERROR(INDEX(ShipPartShape!$A:$A,MATCH(X25,ShipPartShape!$B:$B,0)),"-") -> - | AA25: =IFERROR(INDEX(ShipPartShape!$A:$A,MATCH(Z25,ShipPartShape!$B:$B,0)),"-") -> - | AC25: =IFERROR(INDEX(ShipPartShape!$A:$A,MATCH(AB25,ShipPartShape!$B:$B,0)),"-") -> - | AE25: =IFERROR(INDEX(ShipPartShape!$A:$A,MATCH(AD25,ShipPartShape!$B:$B,0)),"-") -> - | AG25: =IFERROR(INDEX(ShipPartShape!$A:$A,MATCH(AF25,ShipPartShape!$B:$B,0)),"-") -> - | AH25: - | AI25: - | AJ25: - | AK25: - | AL25: - | AM25: - | AN25: - | AO25: - | AP25: - | AQ25: - | AR25: -
A26: =A25+1 -> 45000016 | B26: 바르카_사각2 | C26: SK_Ship_Barca_Body | D26: 바르카4적백돛 | E26: 600 | F26: 50 | G26: =IFERROR(INDEX(ShipPartShape!$A:$A,MATCH(D26,ShipPartShape!$B:$B,0)),"-") -> 46000017 | H26: 충각_기본 | I26: =IFERROR(INDEX(ShipPartShape!$A:$A,MATCH(H26,ShipPartShape!$B:$B,0)),"-") -> 46200001 | J26: 대포_기본 | K26: =IFERROR(INDEX(ShipPartShape!$A:$A,MATCH(J26,ShipPartShape!$B:$B,0)),"-") -> 46300001 | L26: 램프_기본 | M26: =IFERROR(INDEX(ShipPartShape!$A:$A,MATCH(L26,ShipPartShape!$B:$B,0)),"-") -> 46700001 | O26: =IFERROR(INDEX(ShipPartShape!$A:$A,MATCH(N26,ShipPartShape!$B:$B,0)),"-") -> - | Q26: =IFERROR(INDEX(ShipPartShape!$A:$A,MATCH(P26,ShipPartShape!$B:$B,0)),"-") -> - | S26: =IFERROR(INDEX(ShipPartShape!$A:$A,MATCH(R26,ShipPartShape!$B:$B,0)),"-") -> - | U26: =IFERROR(INDEX(ShipPartShape!$A:$A,MATCH(T26,ShipPartShape!$B:$B,0)),"-") -> - | W26: =IFERROR(INDEX(ShipPartShape!$A:$A,MATCH(V26,ShipPartShape!$B:$B,0)),"-") -> - | Y26: =IFERROR(INDEX(ShipPartShape!$A:$A,MATCH(X26,ShipPartShape!$B:$B,0)),"-") -> - | AA26: =IFERROR(INDEX(ShipPartShape!$A:$A,MATCH(Z26,ShipPartShape!$B:$B,0)),"-") -> - | AC26: =IFERROR(INDEX(ShipPartShape!$A:$A,MATCH(AB26,ShipPartShape!$B:$B,0)),"-") -> - | AE26: =IFERROR(INDEX(ShipPartShape!$A:$A,MATCH(AD26,ShipPartShape!$B:$B,0)),"-") -> - | AG26: =IFERROR(INDEX(ShipPartShape!$A:$A,MATCH(AF26,ShipPartShape!$B:$B,0)),"-") -> - | AH26: - | AI26: - | AJ26: - | AK26: - | AL26: - | AM26: - | AN26: - | AO26: - | AP26: - | AQ26: - | AR26: -
A27: =A26+1 -> 45000017 | B27: 바르카_사각3 | C27: SK_Ship_Barca_Body | D27: 바르카4적흑돛 | E27: 600 | F27: 50 | G27: =IFERROR(INDEX(ShipPartShape!$A:$A,MATCH(D27,ShipPartShape!$B:$B,0)),"-") -> 46000018 | H27: 충각_기본 | I27: =IFERROR(INDEX(ShipPartShape!$A:$A,MATCH(H27,ShipPartShape!$B:$B,0)),"-") -> 46200001 | J27: 대포_기본 | K27: =IFERROR(INDEX(ShipPartShape!$A:$A,MATCH(J27,ShipPartShape!$B:$B,0)),"-") -> 46300001 | L27: 램프_기본 | M27: =IFERROR(INDEX(ShipPartShape!$A:$A,MATCH(L27,ShipPartShape!$B:$B,0)),"-") -> 46700001 | O27: =IFERROR(INDEX(ShipPartShape!$A:$A,MATCH(N27,ShipPartShape!$B:$B,0)),"-") -> - | Q27: =IFERROR(INDEX(ShipPartShape!$A:$A,MATCH(P27,ShipPartShape!$B:$B,0)),"-") -> - | S27: =IFERROR(INDEX(ShipPartShape!$A:$A,MATCH(R27,ShipPartShape!$B:$B,0)),"-") -> - | U27: =IFERROR(INDEX(ShipPartShape!$A:$A,MATCH(T27,ShipPartShape!$B:$B,0)),"-") -> - | W27: =IFERROR(INDEX(ShipPartShape!$A:$A,MATCH(V27,ShipPartShape!$B:$B,0)),"-") -> - | Y27: =IFERROR(INDEX(ShipPartShape!$A:$A,MATCH(X27,ShipPartShape!$B:$B,0)),"-") -> - | AA27: =IFERROR(INDEX(ShipPartShape!$A:$A,MATCH(Z27,ShipPartShape!$B:$B,0)),"-") -> - | AC27: =IFERROR(INDEX(ShipPartShape!$A:$A,MATCH(AB27,ShipPartShape!$B:$B,0)),"-") -> - | AE27: =IFERROR(INDEX(ShipPartShape!$A:$A,MATCH(AD27,ShipPartShape!$B:$B,0)),"-") -> - | AG27: =IFERROR(INDEX(ShipPartShape!$A:$A,MATCH(AF27,ShipPartShape!$B:$B,0)),"-") -> - | AH27: - | AI27: - | AJ27: - | AK27: - | AL27: - | AM27: - | AN27: - | AO27: - | AP27: - | AQ27: - | AR27: -
A28: =A27+1 -> 45000018 | B28: 바르카_사각_해적1 | C28: SK_Ship_Barca_Body | D28: 바르카4적흑돛_해골 | E28: 600 | F28: 50 | G28: =IFERROR(INDEX(ShipPartShape!$A:$A,MATCH(D28,ShipPartShape!$B:$B,0)),"-") -> 46000019 | H28: 충각_기본 | I28: =IFERROR(INDEX(ShipPartShape!$A:$A,MATCH(H28,ShipPartShape!$B:$B,0)),"-") -> 46200001 | J28: 대포_기본 | K28: =IFERROR(INDEX(ShipPartShape!$A:$A,MATCH(J28,ShipPartShape!$B:$B,0)),"-") -> 46300001 | L28: 램프_기본 | M28: =IFERROR(INDEX(ShipPartShape!$A:$A,MATCH(L28,ShipPartShape!$B:$B,0)),"-") -> 46700001 | O28: =IFERROR(INDEX(ShipPartShape!$A:$A,MATCH(N28,ShipPartShape!$B:$B,0)),"-") -> - | Q28: =IFERROR(INDEX(ShipPartShape!$A:$A,MATCH(P28,ShipPartShape!$B:$B,0)),"-") -> - | S28: =IFERROR(INDEX(ShipPartShape!$A:$A,MATCH(R28,ShipPartShape!$B:$B,0)),"-") -> - | U28: =IFERROR(INDEX(ShipPartShape!$A:$A,MATCH(T28,ShipPartShape!$B:$B,0)),"-") -> - | W28: =IFERROR(INDEX(ShipPartShape!$A:$A,MATCH(V28,ShipPartShape!$B:$B,0)),"-") -> - | Y28: =IFERROR(INDEX(ShipPartShape!$A:$A,MATCH(X28,ShipPartShape!$B:$B,0)),"-") -> - | AA28: =IFERROR(INDEX(ShipPartShape!$A:$A,MATCH(Z28,ShipPartShape!$B:$B,0)),"-") -> - | AC28: =IFERROR(INDEX(ShipPartShape!$A:$A,MATCH(AB28,ShipPartShape!$B:$B,0)),"-") -> - | AE28: =IFERROR(INDEX(ShipPartShape!$A:$A,MATCH(AD28,ShipPartShape!$B:$B,0)),"-") -> - | AG28: =IFERROR(INDEX(ShipPartShape!$A:$A,MATCH(AF28,ShipPartShape!$B:$B,0)),"-") -> - | AH28: - | AI28: - | AJ28: - | AK28: - | AL28: - | AM28: - | AN28: - | AO28: - | AP28: - | AQ28: - | AR28: -
A29: =A28+1 -> 45000019 | B29: 한자 코그 | C29: SK_Ship_HansaCog_Body | D29: 한자코그흰색돛 | E29: 600 | F29: 50 | G29: =IFERROR(INDEX(ShipPartShape!$A:$A,MATCH(D29,ShipPartShape!$B:$B,0)),"-") -> 46000020 | H29: 램프_기본 | I29: =IFERROR(INDEX(ShipPartShape!$A:$A,MATCH(H29,ShipPartShape!$B:$B,0)),"-") -> 46700001 | K29: =IFERROR(INDEX(ShipPartShape!$A:$A,MATCH(J29,ShipPartShape!$B:$B,0)),"-") -> - | M29: =IFERROR(INDEX(ShipPartShape!$A:$A,MATCH(L29,ShipPartShape!$B:$B,0)),"-") -> - | O29: =IFERROR(INDEX(ShipPartShape!$A:$A,MATCH(N29,ShipPartShape!$B:$B,0)),"-") -> - | Q29: =IFERROR(INDEX(ShipPartShape!$A:$A,MATCH(P29,ShipPartShape!$B:$B,0)),"-") -> - | R29: 선박외형장식_A | S29: =IFERROR(INDEX(ShipPartShape!$A:$A,MATCH(R29,ShipPartShape!$B:$B,0)),"-") -> 46600001 | T29: 선박외형장식_B | U29: =IFERROR(INDEX(ShipPartShape!$A:$A,MATCH(T29,ShipPartShape!$B:$B,0)),"-") -> 46600002 | V29: 선박외형장식_E | W29: =IFERROR(INDEX(ShipPartShape!$A:$A,MATCH(V29,ShipPartShape!$B:$B,0)),"-") -> 46600005 | X29: 선박외형장식_H | Y29: =IFERROR(INDEX(ShipPartShape!$A:$A,MATCH(X29,ShipPartShape!$B:$B,0)),"-") -> 46600008 | AA29: =IFERROR(INDEX(ShipPartShape!$A:$A,MATCH(Z29,ShipPartShape!$B:$B,0)),"-") -> - | AB29: 흰긴수염고래상 | AC29: =IFERROR(INDEX(ShipPartShape!$A:$A,MATCH(AB29,ShipPartShape!$B:$B,0)),"-") -> 46100021 | AE29: =IFERROR(INDEX(ShipPartShape!$A:$A,MATCH(AD29,ShipPartShape!$B:$B,0)),"-") -> - | AG29: =IFERROR(INDEX(ShipPartShape!$A:$A,MATCH(AF29,ShipPartShape!$B:$B,0)),"-") -> - | AH29: - | AI29: - | AJ29: - | AK29: - | AL29: - | AM29: - | AN29: - | AO29: - | AP29: - | AQ29: - | AR29: -
A30: =A29+1 -> 45000020 | B30: 한자 코그_적선 | C30: SK_Ship_HansaCog_Body | D30: 한자코그적색돛 | E30: 600 | F30: 50 | G30: =IFERROR(INDEX(ShipPartShape!$A:$A,MATCH(D30,ShipPartShape!$B:$B,0)),"-") -> 46000021 | H30: 대포_기본 | I30: =IFERROR(INDEX(ShipPartShape!$A:$A,MATCH(H30,ShipPartShape!$B:$B,0)),"-") -> 46300001 | J30: 램프_기본 | K30: =IFERROR(INDEX(ShipPartShape!$A:$A,MATCH(J30,ShipPartShape!$B:$B,0)),"-") -> 46700001 | M30: =IFERROR(INDEX(ShipPartShape!$A:$A,MATCH(L30,ShipPartShape!$B:$B,0)),"-") -> - | O30: =IFERROR(INDEX(ShipPartShape!$A:$A,MATCH(N30,ShipPartShape!$B:$B,0)),"-") -> - | Q30: =IFERROR(INDEX(ShipPartShape!$A:$A,MATCH(P30,ShipPartShape!$B:$B,0)),"-") -> - | S30: =IFERROR(INDEX(ShipPartShape!$A:$A,MATCH(R30,ShipPartShape!$B:$B,0)),"-") -> - | U30: =IFERROR(INDEX(ShipPartShape!$A:$A,MATCH(T30,ShipPartShape!$B:$B,0)),"-") -> - | W30: =IFERROR(INDEX(ShipPartShape!$A:$A,MATCH(V30,ShipPartShape!$B:$B,0)),"-") -> - | Y30: =IFERROR(INDEX(ShipPartShape!$A:$A,MATCH(X30,ShipPartShape!$B:$B,0)),"-") -> - | AA30: =IFERROR(INDEX(ShipPartShape!$A:$A,MATCH(Z30,ShipPartShape!$B:$B,0)),"-") -> - | AC30: =IFERROR(INDEX(ShipPartShape!$A:$A,MATCH(AB30,ShipPartShape!$B:$B,0)),"-") -> - | AE30: =IFERROR(INDEX(ShipPartShape!$A:$A,MATCH(AD30,ShipPartShape!$B:$B,0)),"-") -> - | AG30: =IFERROR(INDEX(ShipPartShape!$A:$A,MATCH(AF30,ShipPartShape!$B:$B,0)),"-") -> - | AH30: - | AI30: - | AJ30: - | AK30: - | AL30: - | AM30: - | AN30: - | AO30: - | AP30: - | AQ30: - | AR30: -
A31: =A30+1 -> 45000021 | B31: 한자 코그_유령선 | C31: SK_Ship_HansaCog_Body | D31: 한자코그유령선돛 | E31: 600 | F31: 50 | G31: =IFERROR(INDEX(ShipPartShape!$A:$A,MATCH(D31,ShipPartShape!$B:$B,0)),"-") -> 46000022 | H31: 독수리상 | I31: =IFERROR(INDEX(ShipPartShape!$A:$A,MATCH(H31,ShipPartShape!$B:$B,0)),"-") -> 46100002 | J31: 충각_기본 | K31: =IFERROR(INDEX(ShipPartShape!$A:$A,MATCH(J31,ShipPartShape!$B:$B,0)),"-") -> 46200001 | L31: 대포_기본 | M31: =IFERROR(INDEX(ShipPartShape!$A:$A,MATCH(L31,ShipPartShape!$B:$B,0)),"-") -> 46300001 | O31: =IFERROR(INDEX(ShipPartShape!$A:$A,MATCH(N31,ShipPartShape!$B:$B,0)),"-") -> - | Q31: =IFERROR(INDEX(ShipPartShape!$A:$A,MATCH(P31,ShipPartShape!$B:$B,0)),"-") -> - | S31: =IFERROR(INDEX(ShipPartShape!$A:$A,MATCH(R31,ShipPartShape!$B:$B,0)),"-") -> - | U31: =IFERROR(INDEX(ShipPartShape!$A:$A,MATCH(T31,ShipPartShape!$B:$B,0)),"-") -> - | W31: =IFERROR(INDEX(ShipPartShape!$A:$A,MATCH(V31,ShipPartShape!$B:$B,0)),"-") -> - | Y31: =IFERROR(INDEX(ShipPartShape!$A:$A,MATCH(X31,ShipPartShape!$B:$B,0)),"-") -> - | AA31: =IFERROR(INDEX(ShipPartShape!$A:$A,MATCH(Z31,ShipPartShape!$B:$B,0)),"-") -> - | AC31: =IFERROR(INDEX(ShipPartShape!$A:$A,MATCH(AB31,ShipPartShape!$B:$B,0)),"-") -> - | AE31: =IFERROR(INDEX(ShipPartShape!$A:$A,MATCH(AD31,ShipPartShape!$B:$B,0)),"-") -> - | AG31: =IFERROR(INDEX(ShipPartShape!$A:$A,MATCH(AF31,ShipPartShape!$B:$B,0)),"-") -> - | AH31: - | AI31: - | AJ31: - | AK31: - | AL31: - | AM31: - | AN31: - | AO31: - | AP31: - | AQ31: - | AR31: -
A32: =A31+1 -> 45000022 | B32: 한자 코그2 | C32: SK_Ship_HansaCog_Body | D32: 한자코그적백돛 | E32: 600 | F32: 50 | G32: =IFERROR(INDEX(ShipPartShape!$A:$A,MATCH(D32,ShipPartShape!$B:$B,0)),"-") -> 46000023 | H32: 충각_기본 | I32: =IFERROR(INDEX(ShipPartShape!$A:$A,MATCH(H32,ShipPartShape!$B:$B,0)),"-") -> 46200001 | J32: 대포_기본 | K32: =IFERROR(INDEX(ShipPartShape!$A:$A,MATCH(J32,ShipPartShape!$B:$B,0)),"-") -> 46300001 | L32: 램프_기본 | M32: =IFERROR(INDEX(ShipPartShape!$A:$A,MATCH(L32,ShipPartShape!$B:$B,0)),"-") -> 46700001 | O32: =IFERROR(INDEX(ShipPartShape!$A:$A,MATCH(N32,ShipPartShape!$B:$B,0)),"-") -> - | Q32: =IFERROR(INDEX(ShipPartShape!$A:$A,MATCH(P32,ShipPartShape!$B:$B,0)),"-") -> - | S32: =IFERROR(INDEX(ShipPartShape!$A:$A,MATCH(R32,ShipPartShape!$B:$B,0)),"-") -> - | U32: =IFERROR(INDEX(ShipPartShape!$A:$A,MATCH(T32,ShipPartShape!$B:$B,0)),"-") -> - | W32: =IFERROR(INDEX(ShipPartShape!$A:$A,MATCH(V32,ShipPartShape!$B:$B,0)),"-") -> - | Y32: =IFERROR(INDEX(ShipPartShape!$A:$A,MATCH(X32,ShipPartShape!$B:$B,0)),"-") -> - | AA32: =IFERROR(INDEX(ShipPartShape!$A:$A,MATCH(Z32,ShipPartShape!$B:$B,0)),"-") -> - | AC32: =IFERROR(INDEX(ShipPartShape!$A:$A,MATCH(AB32,ShipPartShape!$B:$B,0)),"-") -> - | AE32: =IFERROR(INDEX(ShipPartShape!$A:$A,MATCH(AD32,ShipPartShape!$B:$B,0)),"-") -> - | AG32: =IFERROR(INDEX(ShipPartShape!$A:$A,MATCH(AF32,ShipPartShape!$B:$B,0)),"-") -> - | AH32: - | AI32: - | AJ32: - | AK32: - | AL32: - | AM32: - | AN32: - | AO32: - | AP32: - | AQ32: - | AR32: -
A33: =A32+1 -> 45000023 | B33: 한자 코그3 | C33: SK_Ship_HansaCog_Body | D33: 한자코그적흑돛 | E33: 600 | F33: 50 | G33: =IFERROR(INDEX(ShipPartShape!$A:$A,MATCH(D33,ShipPartShape!$B:$B,0)),"-") -> 46000024 | H33: 충각_기본 | I33: =IFERROR(INDEX(ShipPartShape!$A:$A,MATCH(H33,ShipPartShape!$B:$B,0)),"-") -> 46200001 | J33: 대포_기본 | K33: =IFERROR(INDEX(ShipPartShape!$A:$A,MATCH(J33,ShipPartShape!$B:$B,0)),"-") -> 46300001 | L33: 램프_기본 | M33: =IFERROR(INDEX(ShipPartShape!$A:$A,MATCH(L33,ShipPartShape!$B:$B,0)),"-") -> 46700001 | O33: =IFERROR(INDEX(ShipPartShape!$A:$A,MATCH(N33,ShipPartShape!$B:$B,0)),"-") -> - | Q33: =IFERROR(INDEX(ShipPartShape!$A:$A,MATCH(P33,ShipPartShape!$B:$B,0)),"-") -> - | S33: =IFERROR(INDEX(ShipPartShape!$A:$A,MATCH(R33,ShipPartShape!$B:$B,0)),"-") -> - | U33: =IFERROR(INDEX(ShipPartShape!$A:$A,MATCH(T33,ShipPartShape!$B:$B,0)),"-") -> - | W33: =IFERROR(INDEX(ShipPartShape!$A:$A,MATCH(V33,ShipPartShape!$B:$B,0)),"-") -> - | Y33: =IFERROR(INDEX(ShipPartShape!$A:$A,MATCH(X33,ShipPartShape!$B:$B,0)),"-") -> - | AA33: =IFERROR(INDEX(ShipPartShape!$A:$A,MATCH(Z33,ShipPartShape!$B:$B,0)),"-") -> - | AC33: =IFERROR(INDEX(ShipPartShape!$A:$A,MATCH(AB33,ShipPartShape!$B:$B,0)),"-") -> - | AE33: =IFERROR(INDEX(ShipPartShape!$A:$A,MATCH(AD33,ShipPartShape!$B:$B,0)),"-") -> - | AG33: =IFERROR(INDEX(ShipPartShape!$A:$A,MATCH(AF33,ShipPartShape!$B:$B,0)),"-") -> - | AH33: - | AI33: - | AJ33: - | AK33: - | AL33: - | AM33: - | AN33: - | AO33: - | AP33: - | AQ33: - | AR33: -
A34: =A33+1 -> 45000024 | B34: 한자코그_해적1 | C34: SK_Ship_HansaCog_Body | D34: 한자코그적흑돛_해골 | E34: 600 | F34: 50 | G34: =IFERROR(INDEX(ShipPartShape!$A:$A,MATCH(D34,ShipPartShape!$B:$B,0)),"-") -> 46000025 | H34: 충각_기본 | I34: =IFERROR(INDEX(ShipPartShape!$A:$A,MATCH(H34,ShipPartShape!$B:$B,0)),"-") -> 46200001 | J34: 대포_기본 | K34: =IFERROR(INDEX(ShipPartShape!$A:$A,MATCH(J34,ShipPartShape!$B:$B,0)),"-") -> 46300001 | L34: 램프_기본 | M34: =IFERROR(INDEX(ShipPartShape!$A:$A,MATCH(L34,ShipPartShape!$B:$B,0)),"-") -> 46700001 | O34: =IFERROR(INDEX(ShipPartShape!$A:$A,MATCH(N34,ShipPartShape!$B:$B,0)),"-") -> - | Q34: =IFERROR(INDEX(ShipPartShape!$A:$A,MATCH(P34,ShipPartShape!$B:$B,0)),"-") -> - | S34: =IFERROR(INDEX(ShipPartShape!$A:$A,MATCH(R34,ShipPartShape!$B:$B,0)),"-") -> - | U34: =IFERROR(INDEX(ShipPartShape!$A:$A,MATCH(T34,ShipPartShape!$B:$B,0)),"-") -> - | W34: =IFERROR(INDEX(ShipPartShape!$A:$A,MATCH(V34,ShipPartShape!$B:$B,0)),"-") -> - | Y34: =IFERROR(INDEX(ShipPartShape!$A:$A,MATCH(X34,ShipPartShape!$B:$B,0)),"-") -> - | AA34: =IFERROR(INDEX(ShipPartShape!$A:$A,MATCH(Z34,ShipPartShape!$B:$B,0)),"-") -> - | AC34: =IFERROR(INDEX(ShipPartShape!$A:$A,MATCH(AB34,ShipPartShape!$B:$B,0)),"-") -> - | AE34: =IFERROR(INDEX(ShipPartShape!$A:$A,MATCH(AD34,ShipPartShape!$B:$B,0)),"-") -> - | AG34: =IFERROR(INDEX(ShipPartShape!$A:$A,MATCH(AF34,ShipPartShape!$B:$B,0)),"-") -> - | AH34: - | AI34: - | AJ34: - | AK34: - | AL34: - | AM34: - | AN34: - | AO34: - | AP34: - | AQ34: - | AR34: -
A35: =A34+1 -> 45000025 | B35: 코그 라티나 | C35: SK_Ship_CogBig_Body | D35: 코그레티나흰색돛 | E35: 600 | F35: 50 | G35: =IFERROR(INDEX(ShipPartShape!$A:$A,MATCH(D35,ShipPartShape!$B:$B,0)),"-") -> 46000026 | H35: 램프_기본 | I35: =IFERROR(INDEX(ShipPartShape!$A:$A,MATCH(H35,ShipPartShape!$B:$B,0)),"-") -> 46700001 | K35: =IFERROR(INDEX(ShipPartShape!$A:$A,MATCH(J35,ShipPartShape!$B:$B,0)),"-") -> - | M35: =IFERROR(INDEX(ShipPartShape!$A:$A,MATCH(L35,ShipPartShape!$B:$B,0)),"-") -> - | O35: =IFERROR(INDEX(ShipPartShape!$A:$A,MATCH(N35,ShipPartShape!$B:$B,0)),"-") -> - | Q35: =IFERROR(INDEX(ShipPartShape!$A:$A,MATCH(P35,ShipPartShape!$B:$B,0)),"-") -> - | R35: 선박외형장식_B | S35: =IFERROR(INDEX(ShipPartShape!$A:$A,MATCH(R35,ShipPartShape!$B:$B,0)),"-") -> 46600002 | T35: 선박외형장식_D | U35: =IFERROR(INDEX(ShipPartShape!$A:$A,MATCH(T35,ShipPartShape!$B:$B,0)),"-") -> 46600004 | V35: 선박외형장식_I | W35: =IFERROR(INDEX(ShipPartShape!$A:$A,MATCH(V35,ShipPartShape!$B:$B,0)),"-") -> 46600009 | X35: 선박외형장식_G | Y35: =IFERROR(INDEX(ShipPartShape!$A:$A,MATCH(X35,ShipPartShape!$B:$B,0)),"-") -> 46600007 | AA35: =IFERROR(INDEX(ShipPartShape!$A:$A,MATCH(Z35,ShipPartShape!$B:$B,0)),"-") -> - | AB35: 듀공상 | AC35: =IFERROR(INDEX(ShipPartShape!$A:$A,MATCH(AB35,ShipPartShape!$B:$B,0)),"-") -> 46100022 | AE35: =IFERROR(INDEX(ShipPartShape!$A:$A,MATCH(AD35,ShipPartShape!$B:$B,0)),"-") -> - | AG35: =IFERROR(INDEX(ShipPartShape!$A:$A,MATCH(AF35,ShipPartShape!$B:$B,0)),"-") -> - | AH35: - | AI35: - | AJ35: - | AK35: - | AL35: - | AM35: - | AN35: - | AO35: - | AP35: - | AQ35: - | AR35: -
A36: =A35+1 -> 45000026 | B36: 코그 라티나_적선 | C36: SK_Ship_CogBig_Body | D36: 코그레티나적색돛 | E36: 600 | F36: 50 | G36: =IFERROR(INDEX(ShipPartShape!$A:$A,MATCH(D36,ShipPartShape!$B:$B,0)),"-") -> 46000027 | H36: 대포_기본 | I36: =IFERROR(INDEX(ShipPartShape!$A:$A,MATCH(H36,ShipPartShape!$B:$B,0)),"-") -> 46300001 | J36: 램프_기본 | K36: =IFERROR(INDEX(ShipPartShape!$A:$A,MATCH(J36,ShipPartShape!$B:$B,0)),"-") -> 46700001 | M36: =IFERROR(INDEX(ShipPartShape!$A:$A,MATCH(L36,ShipPartShape!$B:$B,0)),"-") -> - | O36: =IFERROR(INDEX(ShipPartShape!$A:$A,MATCH(N36,ShipPartShape!$B:$B,0)),"-") -> - | Q36: =IFERROR(INDEX(ShipPartShape!$A:$A,MATCH(P36,ShipPartShape!$B:$B,0)),"-") -> - | S36: =IFERROR(INDEX(ShipPartShape!$A:$A,MATCH(R36,ShipPartShape!$B:$B,0)),"-") -> - | U36: =IFERROR(INDEX(ShipPartShape!$A:$A,MATCH(T36,ShipPartShape!$B:$B,0)),"-") -> - | W36: =IFERROR(INDEX(ShipPartShape!$A:$A,MATCH(V36,ShipPartShape!$B:$B,0)),"-") -> - | Y36: =IFERROR(INDEX(ShipPartShape!$A:$A,MATCH(X36,ShipPartShape!$B:$B,0)),"-") -> - | AA36: =IFERROR(INDEX(ShipPartShape!$A:$A,MATCH(Z36,ShipPartShape!$B:$B,0)),"-") -> - | AC36: =IFERROR(INDEX(ShipPartShape!$A:$A,MATCH(AB36,ShipPartShape!$B:$B,0)),"-") -> - | AE36: =IFERROR(INDEX(ShipPartShape!$A:$A,MATCH(AD36,ShipPartShape!$B:$B,0)),"-") -> - | AG36: =IFERROR(INDEX(ShipPartShape!$A:$A,MATCH(AF36,ShipPartShape!$B:$B,0)),"-") -> - | AH36: - | AI36: - | AJ36: - | AK36: - | AL36: - | AM36: - | AN36: - | AO36: - | AP36: - | AQ36: - | AR36: -
A37: =A36+1 -> 45000027 | B37: 코그 라티나_유령선 | C37: SK_Ship_CogBig_Body | D37: 코그레티나유령선돛 | E37: 600 | F37: 50 | G37: =IFERROR(INDEX(ShipPartShape!$A:$A,MATCH(D37,ShipPartShape!$B:$B,0)),"-") -> 46000028 | H37: 독수리상 | I37: =IFERROR(INDEX(ShipPartShape!$A:$A,MATCH(H37,ShipPartShape!$B:$B,0)),"-") -> 46100002 | J37: 충각_기본 | K37: =IFERROR(INDEX(ShipPartShape!$A:$A,MATCH(J37,ShipPartShape!$B:$B,0)),"-") -> 46200001 | L37: 대포_기본 | M37: =IFERROR(INDEX(ShipPartShape!$A:$A,MATCH(L37,ShipPartShape!$B:$B,0)),"-") -> 46300001 | O37: =IFERROR(INDEX(ShipPartShape!$A:$A,MATCH(N37,ShipPartShape!$B:$B,0)),"-") -> - | Q37: =IFERROR(INDEX(ShipPartShape!$A:$A,MATCH(P37,ShipPartShape!$B:$B,0)),"-") -> - | S37: =IFERROR(INDEX(ShipPartShape!$A:$A,MATCH(R37,ShipPartShape!$B:$B,0)),"-") -> - | U37: =IFERROR(INDEX(ShipPartShape!$A:$A,MATCH(T37,ShipPartShape!$B:$B,0)),"-") -> - | W37: =IFERROR(INDEX(ShipPartShape!$A:$A,MATCH(V37,ShipPartShape!$B:$B,0)),"-") -> - | Y37: =IFERROR(INDEX(ShipPartShape!$A:$A,MATCH(X37,ShipPartShape!$B:$B,0)),"-") -> - | AA37: =IFERROR(INDEX(ShipPartShape!$A:$A,MATCH(Z37,ShipPartShape!$B:$B,0)),"-") -> - | AC37: =IFERROR(INDEX(ShipPartShape!$A:$A,MATCH(AB37,ShipPartShape!$B:$B,0)),"-") -> - | AE37: =IFERROR(INDEX(ShipPartShape!$A:$A,MATCH(AD37,ShipPartShape!$B:$B,0)),"-") -> - | AG37: =IFERROR(INDEX(ShipPartShape!$A:$A,MATCH(AF37,ShipPartShape!$B:$B,0)),"-") -> - | AH37: - | AI37: - | AJ37: - | AK37: - | AL37: - | AM37: - | AN37: - | AO37: - | AP37: - | AQ37: - | AR37: -
A38: =A37+1 -> 45000028 | B38: 코그 라티나2 | C38: SK_Ship_CogBig_Body | D38: 코그레티나적백돛 | E38: 600 | F38: 50 | G38: =IFERROR(INDEX(ShipPartShape!$A:$A,MATCH(D38,ShipPartShape!$B:$B,0)),"-") -> 46000029 | H38: 충각_기본 | I38: =IFERROR(INDEX(ShipPartShape!$A:$A,MATCH(H38,ShipPartShape!$B:$B,0)),"-") -> 46200001 | J38: 대포_기본 | K38: =IFERROR(INDEX(ShipPartShape!$A:$A,MATCH(J38,ShipPartShape!$B:$B,0)),"-") -> 46300001 | L38: 램프_기본 | M38: =IFERROR(INDEX(ShipPartShape!$A:$A,MATCH(L38,ShipPartShape!$B:$B,0)),"-") -> 46700001 | O38: =IFERROR(INDEX(ShipPartShape!$A:$A,MATCH(N38,ShipPartShape!$B:$B,0)),"-") -> - | Q38: =IFERROR(INDEX(ShipPartShape!$A:$A,MATCH(P38,ShipPartShape!$B:$B,0)),"-") -> - | S38: =IFERROR(INDEX(ShipPartShape!$A:$A,MATCH(R38,ShipPartShape!$B:$B,0)),"-") -> - | U38: =IFERROR(INDEX(ShipPartShape!$A:$A,MATCH(T38,ShipPartShape!$B:$B,0)),"-") -> - | W38: =IFERROR(INDEX(ShipPartShape!$A:$A,MATCH(V38,ShipPartShape!$B:$B,0)),"-") -> - | Y38: =IFERROR(INDEX(ShipPartShape!$A:$A,MATCH(X38,ShipPartShape!$B:$B,0)),"-") -> - | AA38: =IFERROR(INDEX(ShipPartShape!$A:$A,MATCH(Z38,ShipPartShape!$B:$B,0)),"-") -> - | AC38: =IFERROR(INDEX(ShipPartShape!$A:$A,MATCH(AB38,ShipPartShape!$B:$B,0)),"-") -> - | AE38: =IFERROR(INDEX(ShipPartShape!$A:$A,MATCH(AD38,ShipPartShape!$B:$B,0)),"-") -> - | AG38: =IFERROR(INDEX(ShipPartShape!$A:$A,MATCH(AF38,ShipPartShape!$B:$B,0)),"-") -> - | AH38: - | AI38: - | AJ38: - | AK38: - | AL38: - | AM38: - | AN38: - | AO38: - | AP38: - | AQ38: - | AR38: -
A39: =A38+1 -> 45000029 | B39: 코그 라티나3 | C39: SK_Ship_CogBig_Body | D39: 코그레티나적흑돛 | E39: 600 | F39: 50 | G39: =IFERROR(INDEX(ShipPartShape!$A:$A,MATCH(D39,ShipPartShape!$B:$B,0)),"-") -> 46000030 | H39: 충각_기본 | I39: =IFERROR(INDEX(ShipPartShape!$A:$A,MATCH(H39,ShipPartShape!$B:$B,0)),"-") -> 46200001 | J39: 대포_기본 | K39: =IFERROR(INDEX(ShipPartShape!$A:$A,MATCH(J39,ShipPartShape!$B:$B,0)),"-") -> 46300001 | L39: 램프_기본 | M39: =IFERROR(INDEX(ShipPartShape!$A:$A,MATCH(L39,ShipPartShape!$B:$B,0)),"-") -> 46700001 | O39: =IFERROR(INDEX(ShipPartShape!$A:$A,MATCH(N39,ShipPartShape!$B:$B,0)),"-") -> - | Q39: =IFERROR(INDEX(ShipPartShape!$A:$A,MATCH(P39,ShipPartShape!$B:$B,0)),"-") -> - | S39: =IFERROR(INDEX(ShipPartShape!$A:$A,MATCH(R39,ShipPartShape!$B:$B,0)),"-") -> - | U39: =IFERROR(INDEX(ShipPartShape!$A:$A,MATCH(T39,ShipPartShape!$B:$B,0)),"-") -> - | W39: =IFERROR(INDEX(ShipPartShape!$A:$A,MATCH(V39,ShipPartShape!$B:$B,0)),"-") -> - | Y39: =IFERROR(INDEX(ShipPartShape!$A:$A,MATCH(X39,ShipPartShape!$B:$B,0)),"-") -> - | AA39: =IFERROR(INDEX(ShipPartShape!$A:$A,MATCH(Z39,ShipPartShape!$B:$B,0)),"-") -> - | AC39: =IFERROR(INDEX(ShipPartShape!$A:$A,MATCH(AB39,ShipPartShape!$B:$B,0)),"-") -> - | AE39: =IFERROR(INDEX(ShipPartShape!$A:$A,MATCH(AD39,ShipPartShape!$B:$B,0)),"-") -> - | AG39: =IFERROR(INDEX(ShipPartShape!$A:$A,MATCH(AF39,ShipPartShape!$B:$B,0)),"-") -> - | AH39: - | AI39: - | AJ39: - | AK39: - | AL39: - | AM39: - | AN39: - | AO39: - | AP39: - | AQ39: - | AR39: -
A40: =A39+1 -> 45000030 | B40: 코그 라티나_해적1 | C40: SK_Ship_CogBig_Body | D40: 코그레티나적흑돛_해골 | E40: 600 | F40: 50 | G40: =IFERROR(INDEX(ShipPartShape!$A:$A,MATCH(D40,ShipPartShape!$B:$B,0)),"-") -> 46000031 | H40: 충각_기본 | I40: =IFERROR(INDEX(ShipPartShape!$A:$A,MATCH(H40,ShipPartShape!$B:$B,0)),"-") -> 46200001 | J40: 대포_기본 | K40: =IFERROR(INDEX(ShipPartShape!$A:$A,MATCH(J40,ShipPartShape!$B:$B,0)),"-") -> 46300001 | L40: 램프_기본 | M40: =IFERROR(INDEX(ShipPartShape!$A:$A,MATCH(L40,ShipPartShape!$B:$B,0)),"-") -> 46700001 | O40: =IFERROR(INDEX(ShipPartShape!$A:$A,MATCH(N40,ShipPartShape!$B:$B,0)),"-") -> - | Q40: =IFERROR(INDEX(ShipPartShape!$A:$A,MATCH(P40,ShipPartShape!$B:$B,0)),"-") -> - | S40: =IFERROR(INDEX(ShipPartShape!$A:$A,MATCH(R40,ShipPartShape!$B:$B,0)),"-") -> - | U40: =IFERROR(INDEX(ShipPartShape!$A:$A,MATCH(T40,ShipPartShape!$B:$B,0)),"-") -> - | W40: =IFERROR(INDEX(ShipPartShape!$A:$A,MATCH(V40,ShipPartShape!$B:$B,0)),"-") -> - | Y40: =IFERROR(INDEX(ShipPartShape!$A:$A,MATCH(X40,ShipPartShape!$B:$B,0)),"-") -> - | AA40: =IFERROR(INDEX(ShipPartShape!$A:$A,MATCH(Z40,ShipPartShape!$B:$B,0)),"-") -> - | AC40: =IFERROR(INDEX(ShipPartShape!$A:$A,MATCH(AB40,ShipPartShape!$B:$B,0)),"-") -> - | AE40: =IFERROR(INDEX(ShipPartShape!$A:$A,MATCH(AD40,ShipPartShape!$B:$B,0)),"-") -> - | AG40: =IFERROR(INDEX(ShipPartShape!$A:$A,MATCH(AF40,ShipPartShape!$B:$B,0)),"-") -> - | AH40: - | AI40: - | AJ40: - | AK40: - | AL40: - | AM40: - | AN40: - | AO40: - | AP40: - | AQ40: - | AR40: -
...

Sheet ShipPartShape
A1: id | D1: partType | E1: assetName | G1: assetType | H1: socket | I1: startSocketNum | J1: endSocketNum | K1: lightBpName | L1: lightBpOffset | N1: detailMode | O1: sailPattern | P1: sailCrest | Q1: materials[0]["index"] | R1: materials[0]["name"] | S1: materials[1]["index"] | T1: materials[1]["name"] | U1: materials[2]["index"] | V1: materials[2]["name"] | W1: materials[3]["index"] | X1: materials[3]["name"]
A2: key:46000000~46999999 | D2: number | E2: string | G2: number | H2: string | I2: number | J2: number | K2: string | L2: [number] | N2: number | O2: number | P2: number | Q2: number | R2: string | S2: number | T2: string | U2: number | V2: string | W2: number | X2: string
A3: :required | B3: - | C3: - | D3: 1 | E3: 1 | F3: - | G3: 1 | H3: - | I3: - | J3: - | K3: - | L3: - | M3: - | N3: - | O3: - | P3: - | Q3: - | R3: - | S3: - | T3: - | U3: - | V3: - | W3: - | X3: -
A4: :requireedInObject | B4: - | C4: - | D4: - | E4: - | F4: - | G4: - | H4: - | I4: - | J4: - | K4: - | L4: - | M4: - | N4: - | O4: - | P4: - | Q4: 1 | R4: 1 | S4: 1 | T4: 1 | U4: 1 | V4: 1 | W4: 1 | X4: 1
A5: :min | B5: - | C5: - | D5: - | E5: - | F5: - | G5: - | H5: - | I5: - | J5: - | K5: - | L5: - | M5: - | N5: - | O5: - | P5: - | Q5: - | R5: - | S5: - | T5: - | U5: - | V5: - | W5: - | X5: -
A6: :max | B6: - | C6: - | D6: - | E6: - | F6: - | G6: - | H6: - | I6: - | J6: - | K6: - | L6: - | M6: - | N6: - | O6: - | P6: - | Q6: - | R6: - | S6: - | T6: - | U6: - | V6: - | W6: - | X6: -
A7: :enum | B7: - | C7: - | D7: - | E7: - | F7: - | G7: - | H7: - | I7: - | J7: - | K7: - | L7: - | M7: - | N7: - | O7: - | P7: - | Q7: - | R7: - | S7: - | T7: - | U7: - | V7: - | W7: - | X7: -
A8: :links | B8: - | C8: - | D8: - | E8: - | F8: - | G8: - | H8: - | I8: - | J8: - | K8: - | L8: - | M8: - | N8: - | O8: "SailPattern" | P8: "SailCrest" | Q8: - | R8: - | S8: - | T8: - | U8: - | V8: - | W8: - | X8: -
A9: :asset | B9: - | C9: - | D9: - | E9: 1 | F9: - | G9: - | H9: - | I9: - | J9: - | K9: - | L9: - | M9: - | N9: - | O9: - | P9: - | Q9: - | R9: 1 | S9: - | T9: 1 | U9: - | V9: 1 | W9: - | X9: 1
A10: 46000001 | B10: 캐러벨흰색돛 | C10: Sail | D10: =IFERROR(VLOOKUP(C10,ShipShapeEnum!$E:$F,2,FALSE),"-") -> 1 | E10: SK_Ship_Caravel_Sail | F10: SkeletalMesh | G10: =IFERROR(VLOOKUP(F10,ShipShapeEnum!$B:$C,2,FALSE),"-") -> 1 | H10: - | I10: - | J10: - | K10: - | L10: - | M10: Low | N10: =IFERROR(VLOOKUP(M10,ShipShapeEnum!$H:$I,2,FALSE),"-") -> 1 | O10: - | P10: - | Q10: 2 | R10: M_Ship_Sail_Inst | S10: - | T10: - | U10: - | V10: - | W10: - | X10: -
A11: =A10+1 -> 46000002 | B11: 캐러벨적색돛 | C11: Sail | D11: =IFERROR(VLOOKUP(C11,ShipShapeEnum!$E:$F,2,FALSE),"-") -> 1 | E11: SK_Ship_Caravel_Sail | F11: SkeletalMesh | G11: =IFERROR(VLOOKUP(F11,ShipShapeEnum!$B:$C,2,FALSE),"-") -> 1 | H11: - | I11: - | J11: - | K11: - | L11: - | M11: Low | N11: =IFERROR(VLOOKUP(M11,ShipShapeEnum!$H:$I,2,FALSE),"-") -> 1 | O11: - | P11: - | Q11: - | R11: - | S11: - | T11: - | U11: - | V11: - | W11: - | X11: -
A12: =A11+1 -> 46000003 | B12: 캐러벨유령선돛 | C12: Sail | D12: =IFERROR(VLOOKUP(C12,ShipShapeEnum!$E:$F,2,FALSE),"-") -> 1 | E12: SK_Ship_Caravel_Sail | F12: SkeletalMesh | G12: =IFERROR(VLOOKUP(F12,ShipShapeEnum!$B:$C,2,FALSE),"-") -> 1 | H12: - | I12: - | J12: - | K12: - | L12: - | M12: Low | N12: =IFERROR(VLOOKUP(M12,ShipShapeEnum!$H:$I,2,FALSE),"-") -> 1 | O12: - | P12: - | Q12: 2 | R12: M_Ship_Sail_BlackDamaged_Inst | S12: 3 | T12: M_Ship_Sail_BlackDamaged_Inst | U12: - | V12: - | W12: - | X12: -
A13: =A12+1 -> 46000004 | B13: 캐러벨적백돛 | C13: Sail | D13: =IFERROR(VLOOKUP(C13,ShipShapeEnum!$E:$F,2,FALSE),"-") -> 1 | E13: SK_Ship_Caravel_Sail | F13: SkeletalMesh | G13: =IFERROR(VLOOKUP(F13,ShipShapeEnum!$B:$C,2,FALSE),"-") -> 1 | H13: - | I13: - | J13: - | K13: - | L13: - | M13: Low | N13: =IFERROR(VLOOKUP(M13,ShipShapeEnum!$H:$I,2,FALSE),"-") -> 1 | O13: - | P13: - | Q13: 2 | R13: M_Ship_Sail02_Inst | S13: 3 | T13: M_Ship_Sail02_Inst | U13: - | V13: - | W13: - | X13: -
A14: =A13+1 -> 46000005 | B14: 캐러벨적흑돛 | C14: Sail | D14: =IFERROR(VLOOKUP(C14,ShipShapeEnum!$E:$F,2,FALSE),"-") -> 1 | E14: SK_Ship_Caravel_Sail | F14: SkeletalMesh | G14: =IFERROR(VLOOKUP(F14,ShipShapeEnum!$B:$C,2,FALSE),"-") -> 1 | H14: - | I14: - | J14: - | K14: - | L14: - | M14: Low | N14: =IFERROR(VLOOKUP(M14,ShipShapeEnum!$H:$I,2,FALSE),"-") -> 1 | O14: - | P14: - | Q14: 2 | R14: M_Ship_Sail_BlackRed_Inst | S14: 3 | T14: M_Ship_Sail_BlackRed_Inst | U14: - | V14: - | W14: - | X14: -
A15: =A14+1 -> 46000006 | B15: 캐러벨적흑돛_해골 | C15: Sail | D15: =IFERROR(VLOOKUP(C15,ShipShapeEnum!$E:$F,2,FALSE),"-") -> 1 | E15: SK_Ship_Caravel_Sail | F15: SkeletalMesh | G15: =IFERROR(VLOOKUP(F15,ShipShapeEnum!$B:$C,2,FALSE),"-") -> 1 | H15: - | I15: - | J15: - | K15: - | L15: - | M15: Low | N15: =IFERROR(VLOOKUP(M15,ShipShapeEnum!$H:$I,2,FALSE),"-") -> 1 | O15: - | P15: - | Q15: 2 | R15: M_Ship_Sail_BlackRed_SKull_Inst | S15: 3 | T15: M_Ship_Sail_Triagle_SKull_Inst | U15: - | V15: - | W15: - | X15: -
A16: =A15+1 -> 46000007 | B16: 캐러벨무적함대돛 | C16: Sail | D16: =IFERROR(VLOOKUP(C16,ShipShapeEnum!$E:$F,2,FALSE),"-") -> 1 | E16: SK_Ship_Caravel_Sail | F16: SkeletalMesh | G16: =IFERROR(VLOOKUP(F16,ShipShapeEnum!$B:$C,2,FALSE),"-") -> 1 | H16: - | I16: - | J16: - | K16: - | L16: - | M16: Low | N16: =IFERROR(VLOOKUP(M16,ShipShapeEnum!$H:$I,2,FALSE),"-") -> 1 | O16: - | P16: - | Q16: 2 | R16: M_Ship_Sail_Armada_Emblem_Inst | S16: 3 | T16: M_Ship_Sail_Triagle_Armada_Inst | U16: - | V16: - | W16: - | X16: -
A17: =A16+1 -> 46000008 | B17: 바르카3흰색돛 | C17: Sail | D17: =IFERROR(VLOOKUP(C17,ShipShapeEnum!$E:$F,2,FALSE),"-") -> 1 | E17: SK_Ship_Barca_TriangleSail | F17: SkeletalMesh | G17: =IFERROR(VLOOKUP(F17,ShipShapeEnum!$B:$C,2,FALSE),"-") -> 1 | H17: - | I17: - | J17: - | K17: - | L17: - | M17: Low | N17: =IFERROR(VLOOKUP(M17,ShipShapeEnum!$H:$I,2,FALSE),"-") -> 1 | O17: - | P17: - | Q17: 2 | R17: M_Ship_Sail_Inst | S17: - | T17: - | U17: - | V17: - | W17: - | X17: -
A18: =A17+1 -> 46000009 | B18: 바르카3적색돛 | C18: Sail | D18: =IFERROR(VLOOKUP(C18,ShipShapeEnum!$E:$F,2,FALSE),"-") -> 1 | E18: SK_Ship_Barca_TriangleSail | F18: SkeletalMesh | G18: =IFERROR(VLOOKUP(F18,ShipShapeEnum!$B:$C,2,FALSE),"-") -> 1 | H18: - | I18: - | J18: - | K18: - | L18: - | M18: Low | N18: =IFERROR(VLOOKUP(M18,ShipShapeEnum!$H:$I,2,FALSE),"-") -> 1 | O18: - | P18: - | Q18: - | R18: - | S18: - | T18: - | U18: - | V18: - | W18: - | X18: -
A19: =A18+1 -> 46000010 | B19: 바르카3유령선돛 | C19: Sail | D19: =IFERROR(VLOOKUP(C19,ShipShapeEnum!$E:$F,2,FALSE),"-") -> 1 | E19: SK_Ship_Barca_TriangleSail | F19: SkeletalMesh | G19: =IFERROR(VLOOKUP(F19,ShipShapeEnum!$B:$C,2,FALSE),"-") -> 1 | H19: - | I19: - | J19: - | K19: - | L19: - | M19: Low | N19: =IFERROR(VLOOKUP(M19,ShipShapeEnum!$H:$I,2,FALSE),"-") -> 1 | O19: - | P19: - | Q19: 2 | R19: M_Ship_Sail_BlackDamaged_Inst | S19: - | T19: - | U19: - | V19: - | W19: - | X19: -
A20: =A19+1 -> 46000011 | B20: 바르카3적백돛 | C20: Sail | D20: =IFERROR(VLOOKUP(C20,ShipShapeEnum!$E:$F,2,FALSE),"-") -> 1 | E20: SK_Ship_Barca_TriangleSail | F20: SkeletalMesh | G20: =IFERROR(VLOOKUP(F20,ShipShapeEnum!$B:$C,2,FALSE),"-") -> 1 | H20: - | I20: - | J20: - | K20: - | L20: - | M20: Low | N20: =IFERROR(VLOOKUP(M20,ShipShapeEnum!$H:$I,2,FALSE),"-") -> 1 | O20: - | P20: - | Q20: 2 | R20: M_Ship_Sail02_Inst | S20: - | T20: - | U20: - | V20: - | W20: - | X20: -
A21: =A20+1 -> 46000012 | B21: 바르카3적흑돛 | C21: Sail | D21: =IFERROR(VLOOKUP(C21,ShipShapeEnum!$E:$F,2,FALSE),"-") -> 1 | E21: SK_Ship_Barca_TriangleSail | F21: SkeletalMesh | G21: =IFERROR(VLOOKUP(F21,ShipShapeEnum!$B:$C,2,FALSE),"-") -> 1 | H21: - | I21: - | J21: - | K21: - | L21: - | M21: Low | N21: =IFERROR(VLOOKUP(M21,ShipShapeEnum!$H:$I,2,FALSE),"-") -> 1 | O21: - | P21: - | Q21: 2 | R21: M_Ship_Sail_BlackRed_Inst | S21: - | T21: - | U21: - | V21: - | W21: - | X21: -
A22: =A21+1 -> 46000013 | B22: 바르카3적흑돛_해골 | C22: Sail | D22: =IFERROR(VLOOKUP(C22,ShipShapeEnum!$E:$F,2,FALSE),"-") -> 1 | E22: SK_Ship_Barca_TriangleSail | F22: SkeletalMesh | G22: =IFERROR(VLOOKUP(F22,ShipShapeEnum!$B:$C,2,FALSE),"-") -> 1 | H22: - | I22: - | J22: - | K22: - | L22: - | M22: Low | N22: =IFERROR(VLOOKUP(M22,ShipShapeEnum!$H:$I,2,FALSE),"-") -> 1 | O22: - | P22: - | Q22: 2 | R22: M_Ship_Sail_Triagle_SKull_Inst | S22: - | T22: - | U22: - | V22: - | W22: - | X22: -
A23: =A22+1 -> 46000014 | B23: 바르카4흰색돛 | C23: Sail | D23: =IFERROR(VLOOKUP(C23,ShipShapeEnum!$E:$F,2,FALSE),"-") -> 1 | E23: SK_Ship_Barca_SquareSail | F23: SkeletalMesh | G23: =IFERROR(VLOOKUP(F23,ShipShapeEnum!$B:$C,2,FALSE),"-") -> 1 | H23: - | I23: - | J23: - | K23: - | L23: - | M23: Low | N23: =IFERROR(VLOOKUP(M23,ShipShapeEnum!$H:$I,2,FALSE),"-") -> 1 | O23: - | P23: - | Q23: 2 | R23: M_Ship_Sail_Inst | S23: - | T23: - | U23: - | V23: - | W23: - | X23: -
A24: =A23+1 -> 46000015 | B24: 바르카4적색돛 | C24: Sail | D24: =IFERROR(VLOOKUP(C24,ShipShapeEnum!$E:$F,2,FALSE),"-") -> 1 | E24: SK_Ship_Barca_SquareSail | F24: SkeletalMesh | G24: =IFERROR(VLOOKUP(F24,ShipShapeEnum!$B:$C,2,FALSE),"-") -> 1 | H24: - | I24: - | J24: - | K24: - | L24: - | M24: Low | N24: =IFERROR(VLOOKUP(M24,ShipShapeEnum!$H:$I,2,FALSE),"-") -> 1 | O24: - | P24: - | Q24: - | R24: - | S24: - | T24: - | U24: - | V24: - | W24: - | X24: -
A25: =A24+1 -> 46000016 | B25: 바르카4유령선돛 | C25: Sail | D25: =IFERROR(VLOOKUP(C25,ShipShapeEnum!$E:$F,2,FALSE),"-") -> 1 | E25: SK_Ship_Barca_SquareSail | F25: SkeletalMesh | G25: =IFERROR(VLOOKUP(F25,ShipShapeEnum!$B:$C,2,FALSE),"-") -> 1 | H25: - | I25: - | J25: - | K25: - | L25: - | M25: Low | N25: =IFERROR(VLOOKUP(M25,ShipShapeEnum!$H:$I,2,FALSE),"-") -> 1 | O25: - | P25: - | Q25: 2 | R25: M_Ship_Sail_BlackDamaged_Inst | S25: - | T25: - | U25: - | V25: - | W25: - | X25: -
