Workbook

Sheet ReadMe
B2: 발견물 관리 시트
B3: 작성일 : 2022-05-11
B5: 문서 개요
B6: 본 문서는 발견물 핸들링을 위해 작성 되었습니다.
B7: 본 문서에서는 다음과 같은 작업을 처리합니다.
C8: 1. 전체 발견물 통계
C9: 2. 배치된 발견물 현황
C11: 마크가 되어있는 시트는 구글 맵스 데이터 추출용 시트입니다.
B12: *테이블은 본 문서를 참조하지 않습니다.
B14: 문서에 대한 정보는 다음 링크에서 확인가능합니다.
B15: [모험] 발견물

Sheet 발견물
H1: 획득처
B2: ID | C2: 명칭 | D2: 대분류 | E2: 소분류 | F2: 등급 | G2: 문화권 | H2: 해양탐색 | I2: 육지탐험 | J2: 낚시 | K2: 항구 | L2: 마을 | M2: 퀘스트 | N2: 마을탐험 | O2: 사용여부
B3: =[1]Discovery!A9 -> 70401000 | C3: =[1]Discovery!B9 -> 가야 철갑옷 | D3: =[1]Discovery!E9 -> 유물 | E3: =[1]Discovery!C9 -> 역사유물 | F3: =[1]Discovery!G9 -> B | G3: =IFERROR(VLOOKUP(표1[[#This Row],[명칭]],'문화권 정리'!C:D,2,FALSE),"-") -> 동아시아 | H3: =IFERROR(COUNTIF([2]OceanDoodad!$Y:$Y,표1[[#This Row],[명칭]]),"-") -> - | I3: =IFERROR(COUNTIF([1]AdventureDiscoveryGroup!$D$8:$AW$92,표1[[#This Row],[명칭]]),"-") -> 0 | J3: =IFERROR(COUNTIF([1]FishDiscoveryGroup!$A:$X,표1[[#This Row],[명칭]]),"-") -> 0 | K3: =IFERROR(COUNTIF([2]Town!$B:$B,표1[[#This Row],[명칭]]),"-") -> - | L3: =IFERROR(COUNTIF([1]Village!$BR:$BR,표1[[#This Row],[명칭]]),"-") -> 0 | M3: =COUNTIF(퀘스트!B:B,표1[[#This Row],[명칭]]) -> 0 | N3: =COUNTIF([1]VillageDiscoveryGroup!$C:$C,표1[[#This Row],[명칭]]) -> 0 | O3: =SUM(표1[[#This Row],[해양탐색]:[마을탐험]]) -> 0
B4: =[1]Discovery!A10 -> 70401001 | C4: =[1]Discovery!B10 -> 가타멜라타 기마상 | D4: =[1]Discovery!E10 -> 유물 | E4: =[1]Discovery!C10 -> 역사유물 | F4: =[1]Discovery!G10 -> C | G4: =IFERROR(VLOOKUP(표1[[#This Row],[명칭]],'문화권 정리'!C:D,2,FALSE),"-") -> 지중해 | H4: =IFERROR(COUNTIF([2]OceanDoodad!$Y:$Y,표1[[#This Row],[명칭]]),"-") -> - | I4: =IFERROR(COUNTIF([1]AdventureDiscoveryGroup!$D$8:$AW$92,표1[[#This Row],[명칭]]),"-") -> 0 | J4: =IFERROR(COUNTIF([1]FishDiscoveryGroup!$A:$X,표1[[#This Row],[명칭]]),"-") -> 0 | K4: =IFERROR(COUNTIF([2]Town!$B:$B,표1[[#This Row],[명칭]]),"-") -> - | L4: =IFERROR(COUNTIF([1]Village!$BR:$BR,표1[[#This Row],[명칭]]),"-") -> 0 | M4: =COUNTIF(퀘스트!B:B,표1[[#This Row],[명칭]]) -> 0 | N4: =COUNTIF([1]VillageDiscoveryGroup!$C:$C,표1[[#This Row],[명칭]]) -> 0 | O4: =SUM(표1[[#This Row],[해양탐색]:[마을탐험]]) -> 0
B5: =[1]Discovery!A11 -> 70401002 | C5: =[1]Discovery!B11 -> 검투사의 투구 | D5: =[1]Discovery!E11 -> 유물 | E5: =[1]Discovery!C11 -> 역사유물 | F5: =[1]Discovery!G11 -> C | G5: =IFERROR(VLOOKUP(표1[[#This Row],[명칭]],'문화권 정리'!C:D,2,FALSE),"-") -> 지중해 | H5: =IFERROR(COUNTIF([2]OceanDoodad!$Y:$Y,표1[[#This Row],[명칭]]),"-") -> - | I5: =IFERROR(COUNTIF([1]AdventureDiscoveryGroup!$D$8:$AW$92,표1[[#This Row],[명칭]]),"-") -> 0 | J5: =IFERROR(COUNTIF([1]FishDiscoveryGroup!$A:$X,표1[[#This Row],[명칭]]),"-") -> 0 | K5: =IFERROR(COUNTIF([2]Town!$B:$B,표1[[#This Row],[명칭]]),"-") -> - | L5: =IFERROR(COUNTIF([1]Village!$BR:$BR,표1[[#This Row],[명칭]]),"-") -> 0 | M5: =COUNTIF(퀘스트!B:B,표1[[#This Row],[명칭]]) -> 0 | N5: =COUNTIF([1]VillageDiscoveryGroup!$C:$C,표1[[#This Row],[명칭]]) -> 0 | O5: =SUM(표1[[#This Row],[해양탐색]:[마을탐험]]) -> 0
B6: =[1]Discovery!A12 -> 70401003 | C6: =[1]Discovery!B12 -> 게르 | D6: =[1]Discovery!E12 -> 유물 | E6: =[1]Discovery!C12 -> 역사유물 | F6: =[1]Discovery!G12 -> B | G6: =IFERROR(VLOOKUP(표1[[#This Row],[명칭]],'문화권 정리'!C:D,2,FALSE),"-") -> 동아시아 | H6: =IFERROR(COUNTIF([2]OceanDoodad!$Y:$Y,표1[[#This Row],[명칭]]),"-") -> - | I6: =IFERROR(COUNTIF([1]AdventureDiscoveryGroup!$D$8:$AW$92,표1[[#This Row],[명칭]]),"-") -> 0 | J6: =IFERROR(COUNTIF([1]FishDiscoveryGroup!$A:$X,표1[[#This Row],[명칭]]),"-") -> 0 | K6: =IFERROR(COUNTIF([2]Town!$B:$B,표1[[#This Row],[명칭]]),"-") -> - | L6: =IFERROR(COUNTIF([1]Village!$BR:$BR,표1[[#This Row],[명칭]]),"-") -> 0 | M6: =COUNTIF(퀘스트!B:B,표1[[#This Row],[명칭]]) -> 0 | N6: =COUNTIF([1]VillageDiscoveryGroup!$C:$C,표1[[#This Row],[명칭]]) -> 1 | O6: =SUM(표1[[#This Row],[해양탐색]:[마을탐험]]) -> 1
B7: =[1]Discovery!A13 -> 70401004 | C7: =[1]Discovery!B13 -> 게클랭의 마상창 | D7: =[1]Discovery!E13 -> 보물 | E7: =[1]Discovery!C13 -> 보물 | F7: =[1]Discovery!G13 -> A | G7: =IFERROR(VLOOKUP(표1[[#This Row],[명칭]],'문화권 정리'!C:D,2,FALSE),"-") -> 지중해 | H7: =IFERROR(COUNTIF([2]OceanDoodad!$Y:$Y,표1[[#This Row],[명칭]]),"-") -> - | I7: =IFERROR(COUNTIF([1]AdventureDiscoveryGroup!$D$8:$AW$92,표1[[#This Row],[명칭]]),"-") -> 0 | J7: =IFERROR(COUNTIF([1]FishDiscoveryGroup!$A:$X,표1[[#This Row],[명칭]]),"-") -> 0 | K7: =IFERROR(COUNTIF([2]Town!$B:$B,표1[[#This Row],[명칭]]),"-") -> - | L7: =IFERROR(COUNTIF([1]Village!$BR:$BR,표1[[#This Row],[명칭]]),"-") -> 0 | M7: =COUNTIF(퀘스트!B:B,표1[[#This Row],[명칭]]) -> 0 | N7: =COUNTIF([1]VillageDiscoveryGroup!$C:$C,표1[[#This Row],[명칭]]) -> 0 | O7: =SUM(표1[[#This Row],[해양탐색]:[마을탐험]]) -> 0
B8: =[1]Discovery!A14 -> 70401006 | C8: =[1]Discovery!B14 -> 골각기 | D8: =[1]Discovery!E14 -> 유물 | E8: =[1]Discovery!C14 -> 역사유물 | F8: =[1]Discovery!G14 -> D | G8: =IFERROR(VLOOKUP(표1[[#This Row],[명칭]],'문화권 정리'!C:D,2,FALSE),"-") -> 남아시아 | H8: =IFERROR(COUNTIF([2]OceanDoodad!$Y:$Y,표1[[#This Row],[명칭]]),"-") -> - | I8: =IFERROR(COUNTIF([1]AdventureDiscoveryGroup!$D$8:$AW$92,표1[[#This Row],[명칭]]),"-") -> 0 | J8: =IFERROR(COUNTIF([1]FishDiscoveryGroup!$A:$X,표1[[#This Row],[명칭]]),"-") -> 0 | K8: =IFERROR(COUNTIF([2]Town!$B:$B,표1[[#This Row],[명칭]]),"-") -> - | L8: =IFERROR(COUNTIF([1]Village!$BR:$BR,표1[[#This Row],[명칭]]),"-") -> 0 | M8: =COUNTIF(퀘스트!B:B,표1[[#This Row],[명칭]]) -> 0 | N8: =COUNTIF([1]VillageDiscoveryGroup!$C:$C,표1[[#This Row],[명칭]]) -> 0 | O8: =SUM(표1[[#This Row],[해양탐색]:[마을탐험]]) -> 0
B9: =[1]Discovery!A15 -> 70401007 | C9: =[1]Discovery!B15 -> 관두의 | D9: =[1]Discovery!E15 -> 보물 | E9: =[1]Discovery!C15 -> 보물 | F9: =[1]Discovery!G15 -> B | G9: =IFERROR(VLOOKUP(표1[[#This Row],[명칭]],'문화권 정리'!C:D,2,FALSE),"-") -> 남아메리카 | H9: =IFERROR(COUNTIF([2]OceanDoodad!$Y:$Y,표1[[#This Row],[명칭]]),"-") -> - | I9: =IFERROR(COUNTIF([1]AdventureDiscoveryGroup!$D$8:$AW$92,표1[[#This Row],[명칭]]),"-") -> 0 | J9: =IFERROR(COUNTIF([1]FishDiscoveryGroup!$A:$X,표1[[#This Row],[명칭]]),"-") -> 0 | K9: =IFERROR(COUNTIF([2]Town!$B:$B,표1[[#This Row],[명칭]]),"-") -> - | L9: =IFERROR(COUNTIF([1]Village!$BR:$BR,표1[[#This Row],[명칭]]),"-") -> 0 | M9: =COUNTIF(퀘스트!B:B,표1[[#This Row],[명칭]]) -> 0 | N9: =COUNTIF([1]VillageDiscoveryGroup!$C:$C,표1[[#This Row],[명칭]]) -> 0 | O9: =SUM(표1[[#This Row],[해양탐색]:[마을탐험]]) -> 0
B10: =[1]Discovery!A16 -> #70401008 | C10: =[1]Discovery!B16 -> 구멍 뚫린 두개골 | D10: =[1]Discovery!E16 -> 유물 | E10: =[1]Discovery!C16 -> 역사유물 | F10: =[1]Discovery!G16 -> C | G10: =IFERROR(VLOOKUP(표1[[#This Row],[명칭]],'문화권 정리'!C:D,2,FALSE),"-") -> 북아메리카 | H10: =IFERROR(COUNTIF([2]OceanDoodad!$Y:$Y,표1[[#This Row],[명칭]]),"-") -> - | I10: =IFERROR(COUNTIF([1]AdventureDiscoveryGroup!$D$8:$AW$92,표1[[#This Row],[명칭]]),"-") -> 0 | J10: =IFERROR(COUNTIF([1]FishDiscoveryGroup!$A:$X,표1[[#This Row],[명칭]]),"-") -> 0 | K10: =IFERROR(COUNTIF([2]Town!$B:$B,표1[[#This Row],[명칭]]),"-") -> - | L10: =IFERROR(COUNTIF([1]Village!$BR:$BR,표1[[#This Row],[명칭]]),"-") -> 0 | M10: =COUNTIF(퀘스트!B:B,표1[[#This Row],[명칭]]) -> 0 | N10: =COUNTIF([1]VillageDiscoveryGroup!$C:$C,표1[[#This Row],[명칭]]) -> 0 | O10: =SUM(표1[[#This Row],[해양탐색]:[마을탐험]]) -> 0
B11: =[1]Discovery!A17 -> 70401009 | C11: =[1]Discovery!B17 -> 그리스 문자의 석판 | D11: =[1]Discovery!E17 -> 유물 | E11: =[1]Discovery!C17 -> 역사유물 | F11: =[1]Discovery!G17 -> D | G11: =IFERROR(VLOOKUP(표1[[#This Row],[명칭]],'문화권 정리'!C:D,2,FALSE),"-") -> 지중해 | H11: =IFERROR(COUNTIF([2]OceanDoodad!$Y:$Y,표1[[#This Row],[명칭]]),"-") -> - | I11: =IFERROR(COUNTIF([1]AdventureDiscoveryGroup!$D$8:$AW$92,표1[[#This Row],[명칭]]),"-") -> 1 | J11: =IFERROR(COUNTIF([1]FishDiscoveryGroup!$A:$X,표1[[#This Row],[명칭]]),"-") -> 0 | K11: =IFERROR(COUNTIF([2]Town!$B:$B,표1[[#This Row],[명칭]]),"-") -> - | L11: =IFERROR(COUNTIF([1]Village!$BR:$BR,표1[[#This Row],[명칭]]),"-") -> 0 | M11: =COUNTIF(퀘스트!B:B,표1[[#This Row],[명칭]]) -> 0 | N11: =COUNTIF([1]VillageDiscoveryGroup!$C:$C,표1[[#This Row],[명칭]]) -> 0 | O11: =SUM(표1[[#This Row],[해양탐색]:[마을탐험]]) -> 1
B12: =[1]Discovery!A18 -> 70401010 | C12: =[1]Discovery!B18 -> 그리스의 불 | D12: =[1]Discovery!E18 -> 유물 | E12: =[1]Discovery!C18 -> 역사유물 | F12: =[1]Discovery!G18 -> B | G12: =IFERROR(VLOOKUP(표1[[#This Row],[명칭]],'문화권 정리'!C:D,2,FALSE),"-") -> 지중해 | H12: =IFERROR(COUNTIF([2]OceanDoodad!$Y:$Y,표1[[#This Row],[명칭]]),"-") -> - | I12: =IFERROR(COUNTIF([1]AdventureDiscoveryGroup!$D$8:$AW$92,표1[[#This Row],[명칭]]),"-") -> 0 | J12: =IFERROR(COUNTIF([1]FishDiscoveryGroup!$A:$X,표1[[#This Row],[명칭]]),"-") -> 0 | K12: =IFERROR(COUNTIF([2]Town!$B:$B,표1[[#This Row],[명칭]]),"-") -> - | L12: =IFERROR(COUNTIF([1]Village!$BR:$BR,표1[[#This Row],[명칭]]),"-") -> 0 | M12: =COUNTIF(퀘스트!B:B,표1[[#This Row],[명칭]]) -> 1 | N12: =COUNTIF([1]VillageDiscoveryGroup!$C:$C,표1[[#This Row],[명칭]]) -> 0 | O12: =SUM(표1[[#This Row],[해양탐색]:[마을탐험]]) -> 1
B13: =[1]Discovery!A19 -> 70401011 | C13: =[1]Discovery!B19 -> 금각만의 쇠사슬 | D13: =[1]Discovery!E19 -> 유물 | E13: =[1]Discovery!C19 -> 역사유물 | F13: =[1]Discovery!G19 -> B | G13: =IFERROR(VLOOKUP(표1[[#This Row],[명칭]],'문화권 정리'!C:D,2,FALSE),"-") -> 지중해 | H13: =IFERROR(COUNTIF([2]OceanDoodad!$Y:$Y,표1[[#This Row],[명칭]]),"-") -> - | I13: =IFERROR(COUNTIF([1]AdventureDiscoveryGroup!$D$8:$AW$92,표1[[#This Row],[명칭]]),"-") -> 0 | J13: =IFERROR(COUNTIF([1]FishDiscoveryGroup!$A:$X,표1[[#This Row],[명칭]]),"-") -> 0 | K13: =IFERROR(COUNTIF([2]Town!$B:$B,표1[[#This Row],[명칭]]),"-") -> - | L13: =IFERROR(COUNTIF([1]Village!$BR:$BR,표1[[#This Row],[명칭]]),"-") -> 0 | M13: =COUNTIF(퀘스트!B:B,표1[[#This Row],[명칭]]) -> 1 | N13: =COUNTIF([1]VillageDiscoveryGroup!$C:$C,표1[[#This Row],[명칭]]) -> 0 | O13: =SUM(표1[[#This Row],[해양탐색]:[마을탐험]]) -> 1
B14: =[1]Discovery!A20 -> 70401012 | C14: =[1]Discovery!B20 -> 금루옥의 | D14: =[1]Discovery!E20 -> 유물 | E14: =[1]Discovery!C20 -> 역사유물 | F14: =[1]Discovery!G20 -> C | G14: =IFERROR(VLOOKUP(표1[[#This Row],[명칭]],'문화권 정리'!C:D,2,FALSE),"-") -> 동아시아 | H14: =IFERROR(COUNTIF([2]OceanDoodad!$Y:$Y,표1[[#This Row],[명칭]]),"-") -> - | I14: =IFERROR(COUNTIF([1]AdventureDiscoveryGroup!$D$8:$AW$92,표1[[#This Row],[명칭]]),"-") -> 0 | J14: =IFERROR(COUNTIF([1]FishDiscoveryGroup!$A:$X,표1[[#This Row],[명칭]]),"-") -> 0 | K14: =IFERROR(COUNTIF([2]Town!$B:$B,표1[[#This Row],[명칭]]),"-") -> - | L14: =IFERROR(COUNTIF([1]Village!$BR:$BR,표1[[#This Row],[명칭]]),"-") -> 0 | M14: =COUNTIF(퀘스트!B:B,표1[[#This Row],[명칭]]) -> 1 | N14: =COUNTIF([1]VillageDiscoveryGroup!$C:$C,표1[[#This Row],[명칭]]) -> 0 | O14: =SUM(표1[[#This Row],[해양탐색]:[마을탐험]]) -> 1
... B2728: =[1]Discovery!A2734 -> 0 | C2728: =[1]Discovery!B2734 -> 0 | D2728: =[1]Discovery!E2734 -> 0 | E2728: =[1]Discovery!C2734 -> 0 | F2728: =[1]Discovery!G2734 -> 0 | G2728: =IFERROR(VLOOKUP(표1[[#This Row],[명칭]],'문화권 정리'!C:D,2,FALSE),"-") -> - | H2728: =IFERROR(COUNTIF([2]OceanDoodad!$Y:$Y,표1[[#This Row],[명칭]]),"-") -> - | I2728: =IFERROR(COUNTIF([1]AdventureDiscoveryGroup!$D$8:$AW$92,표1[[#This Row],[명칭]]),"-") -> 0 | J2728: =IFERROR(COUNTIF([1]FishDiscoveryGroup!$A:$X,표1[[#This Row],[명칭]]),"-") -> 0 | K2728: =IFERROR(COUNTIF([2]Town!$B:$B,표1[[#This Row],[명칭]]),"-") -> - | L2728: =IFERROR(COUNTIF([1]Village!$BR:$BR,표1[[#This Row],[명칭]]),"-") -> 0 | M2728: =COUNTIF(퀘스트!B:B,표1[[#This Row],[명칭]]) -> 0 | N2728: =COUNTIF([1]VillageDiscoveryGroup!$C:$C,표1[[#This Row],[명칭]]) -> 0 | O2728: =SUM(표1[[#This Row],[해양탐색]:[마을탐험]]) -> 0

Sheet 문화권 정리
C1: 명칭 | D1: 문화권 | F1: 문화권을 직접 조사하여 기입하는 시트입니다.
C2: 가야 철갑옷 | D2: 동아시아 | K2: 문화권 목록
C3: 가타멜라타 기마상 | D3: 지중해 | K3: 지중해
C4: 검투사의 투구 | D4: 지중해 | K4: 북유럽
C5: 게르 | D5: 동아시아 | K5: 브리튼
C6: 게클랭의 마상창 | D6: 지중해 | K6: 북아프리카
C7: 골각기 | D7: 남아시아 | K7: 서아프리카
C8: 관두의 | D8: 남아메리카 | K8: 남아프리카
C9: 구멍 뚫린 두개골 | D9: 북아메리카 | K9: 동아프리카
C10: 그리스 문자의 석판 | D10: 지중해 | K10: 서남아시아
C11: 그리스의 불 | D11: 지중해 | K11: 남아시아
C12: 금각만의 쇠사슬 | D12: 지중해 | K12: 동남아시아
C13: 금루옥의 | D13: 동아시아 | K13: 동아시아
... C20: 다리우스 1세의 투구 | D20: 서남아시아 | K20: 극지방
C21: 다리우스 3세의 갑옷 | D21: 서남아시아
C22: 데메트리오스 1세의 갑옷 | D22: 지중해
C23: 동고 | D23: 동남아시아
C24: 라발나스왕의 검 | D24: 지중해
C25: 라브렌체프 사본 | D25: 유라시아
C26: 람세스 2세의 머리 장식 | D26: 북아프리카
C27: 람세스 2세의 벽화 | D27: 북아프리카
C28: 람캄행 대왕의 비문 | D28: 동남아시아
C29: 렙티스마그나의 비너스상 | D29: 북아프리카
C30: 로마건국사 | D30: 지중해
C31: 로제타스톤 | D31: 북아프리카
C32: 롤로의 투구 | D32: 북유럽
... C2720: 테이블 산 | D2720: 남아프리카

Sheet 발견물 통계
B2: 1. 문화권 별 마을 / 육지 개수 + 필요 발견물 + 남는 발견물 | I2: 2. 선단 LV 제한 기준 마을/육지 개수 | O2: 3. 발견물 분류별 등급 분포 | W2: 4. 문화권 별 발견물 등급 분포 | AE2: 5. 획득처 별 등급 분포 | AM2: 6. 문화권 별 획득처 분포
B3: 마을/육지 별 발견물 수 | D3: 5
B5: 문화권 | C5: 마을 | D5: 육지 | E5: 필요 발견물 | F5: 전체 발견물 | G5: 남는 발견물 | I5: 레벨 제한 | J5: 단계 | K5: 육지 | L5: 마을 | M5: 필요 발견물 | O5: 분류 | P5: D | Q5: C | R5: B | S5: A | T5: S | U5: 합계 | W5: 문화권 | X5: D | Y5: C | Z5: B | AA5: A | AB5: S | AC5: 합계 | AE5: 문화권 | AF5: D | AG5: C | AH5: B | AI5: A | AJ5: S | AK5: 합계 | AM5: 문화권 | AN5: 해양 탐색 | AO5: 육지 탐험 | AP5: 합계
B6: 지중해 | C6: =COUNTIF([1]Village!$C:$C,표2[[#This Row],[문화권]]) -> 0 | D6: =COUNTIF([1]LandExplore!$C:$C,표2[[#This Row],[문화권]]) -> 0 | E6: =(표2[[#This Row],[마을]]+표2[[#This Row],[육지]])*$D$3 -> 0 | F6: =COUNTIF(표1[문화권],표2[[#This Row],[문화권]]) -> 292 | G6: =표2[[#This Row],[전체 발견물]]-표2[[#This Row],[필요 발견물]] -> 292 | I6: 0 | J6: 1 | K6: =COUNTIF([3]!표1_6[선단 LV],표3[[#This Row],[레벨 제한]]) -> 13 | L6: =COUNTIF([3]!표8[선단 LV],표3[[#This Row],[레벨 제한]]) -> 3 | M6: =SUM(표3[[#This Row],[육지]:[마을]])*$D$3 -> 80 | O6: 동물 | P6: =COUNTIFS(표1[대분류],표4[[#This Row],[분류]],표1[등급],"D") -> 165 | Q6: =COUNTIFS(표1[대분류],표4[[#This Row],[분류]],표1[등급],"C") -> 174 | R6: =COUNTIFS(표1[대분류],표4[[#This Row],[분류]],표1[등급],"B") -> 264 | S6: =COUNTIFS(표1[대분류],표4[[#This Row],[분류]],표1[등급],"A") -> 173 | T6: =COUNTIFS(표1[대분류],표4[[#This Row],[분류]],표1[등급],"S") -> 102 | U6: =SUM(표4[[#This Row],[D]:[S]]) -> 878 | W6: 지중해 | X6: =COUNTIFS(표1[문화권],표5[[#This Row],[문화권]],표1[등급],표5[[#Headers],[D]]) -> 38 | Y6: =COUNTIFS(표1[문화권],표5[[#This Row],[문화권]],표1[등급],표5[[#Headers],[C]]) -> 60 | Z6: =COUNTIFS(표1[문화권],표5[[#This Row],[문화권]],표1[등급],표5[[#Headers],[B]]) -> 83 | AA6: =COUNTIFS(표1[문화권],표5[[#This Row],[문화권]],표1[등급],표5[[#Headers],[A]]) -> 66 | AB6: =COUNTIFS(표1[문화권],표5[[#This Row],[문화권]],표1[등급],표5[[#Headers],[S]]) -> 45 | AC6: =SUM(표5[[#This Row],[문화권]:[S]]) -> 292 | AE6: 해양탐색 | AF6: =COUNTIFS(표1[해양탐색],">=1",표1[등급],AF5) -> 0 | AG6: =COUNTIFS(표1[해양탐색],">=1",표1[등급],AG5) -> 0 | AH6: =COUNTIFS(표1[해양탐색],">=1",표1[등급],AH5) -> 0 | AI6: =COUNTIFS(표1[해양탐색],">=1",표1[등급],AI5) -> 0 | AJ6: =COUNTIFS(표1[해양탐색],">=1",표1[등급],AJ5) -> 0 | AK6: =SUM(AF6:AJ6) -> 0 | AM6: 지중해 | AN6: =COUNTIFS(표1[해양탐색],1,표1[문화권],표6[[#This Row],[문화권]]) -> 0 | AO6: =COUNTIFS(표1[육지탐험],">=1",표1[문화권],표6[[#This Row],[문화권]]) -> 44 | AP6: =SUM(표6[[#This Row],[해양 탐색]:[육지 탐험]]) -> 44
B7: 북유럽 | C7: =COUNTIF([1]Village!$C:$C,표2[[#This Row],[문화권]]) -> 3 | D7: =COUNTIF([1]LandExplore!$C:$C,표2[[#This Row],[문화권]]) -> 0 | E7: =(표2[[#This Row],[마을]]+표2[[#This Row],[육지]])*$D$3 -> 15 | F7: =COUNTIF(표1[문화권],표2[[#This Row],[문화권]]) -> 43 | G7: =표2[[#This Row],[전체 발견물]]-표2[[#This Row],[필요 발견물]] -> 28 | I7: 20 | J7: 2 | K7: =COUNTIF([3]!표1_6[선단 LV],표3[[#This Row],[레벨 제한]]) -> 8 | L7: =COUNTIF([3]!표8[선단 LV],표3[[#This Row],[레벨 제한]]) -> 10 | M7: =SUM(표3[[#This Row],[육지]:[마을]])*$D$3 -> 90 | O7: 건축 | P7: =COUNTIFS(표1[대분류],표4[[#This Row],[분류]],표1[등급],"D") -> 304 | Q7: =COUNTIFS(표1[대분류],표4[[#This Row],[분류]],표1[등급],"C") -> 30 | R7: =COUNTIFS(표1[대분류],표4[[#This Row],[분류]],표1[등급],"B") -> 46 | S7: =COUNTIFS(표1[대분류],표4[[#This Row],[분류]],표1[등급],"A") -> 34 | T7: =COUNTIFS(표1[대분류],표4[[#This Row],[분류]],표1[등급],"S") -> 19 | U7: =SUM(표4[[#This Row],[D]:[S]]) -> 433 | W7: 북유럽 | X7: =COUNTIFS(표1[문화권],표5[[#This Row],[문화권]],표1[등급],표5[[#Headers],[D]]) -> 6 | Y7: =COUNTIFS(표1[문화권],표5[[#This Row],[문화권]],표1[등급],표5[[#Headers],[C]]) -> 8 | Z7: =COUNTIFS(표1[문화권],표5[[#This Row],[문화권]],표1[등급],표5[[#Headers],[B]]) -> 14 | AA7: =COUNTIFS(표1[문화권],표5[[#This Row],[문화권]],표1[등급],표5[[#Headers],[A]]) -> 9 | AB7: =COUNTIFS(표1[문화권],표5[[#This Row],[문화권]],표1[등급],표5[[#Headers],[S]]) -> 6 | AC7: =SUM(표5[[#This Row],[문화권]:[S]]) -> 43 | AE7: 육지탐험 | AF7: =COUNTIFS(표1[육지탐험],">=1",표1[등급],AF5) -> 125 | AG7: =COUNTIFS(표1[육지탐험],">=1",표1[등급],AG5) -> 112 | AH7: =COUNTIFS(표1[육지탐험],">=1",표1[등급],AH5) -> 105 | AI7: =COUNTIFS(표1[육지탐험],">=1",표1[등급],AI5) -> 87 | AJ7: =COUNTIFS(표1[육지탐험],">=1",표1[등급],AJ5) -> 34 | AK7: =SUM(AF7:AJ7) -> 463 | AM7: 북유럽 | AN7: =COUNTIFS(표1[해양탐색],1,표1[문화권],표6[[#This Row],[문화권]]) -> 0 | AO7: =COUNTIFS(표1[육지탐험],">=1",표1[문화권],표6[[#This Row],[문화권]]) -> 19 | AP7: =SUM(표6[[#This Row],[해양 탐색]:[육지 탐험]]) -> 19
B8: 브리튼 | C8: =COUNTIF([1]Village!$C:$C,표2[[#This Row],[문화권]]) -> 0 | D8: =COUNTIF([1]LandExplore!$C:$C,표2[[#This Row],[문화권]]) -> 0 | E8: =(표2[[#This Row],[마을]]+표2[[#This Row],[육지]])*$D$3 -> 0 | F8: =COUNTIF(표1[문화권],표2[[#This Row],[문화권]]) -> 36 | G8: =표2[[#This Row],[전체 발견물]]-표2[[#This Row],[필요 발견물]] -> 36 | I8: 25 | J8: 3 | K8: =COUNTIF([3]!표1_6[선단 LV],표3[[#This Row],[레벨 제한]]) -> 2 | L8: =COUNTIF([3]!표8[선단 LV],표3[[#This Row],[레벨 제한]]) -> 3 | M8: =SUM(표3[[#This Row],[육지]:[마을]])*$D$3 -> 25 | O8: 유물 | P8: =COUNTIFS(표1[대분류],표4[[#This Row],[분류]],표1[등급],"D") -> 35 | Q8: =COUNTIFS(표1[대분류],표4[[#This Row],[분류]],표1[등급],"C") -> 57 | R8: =COUNTIFS(표1[대분류],표4[[#This Row],[분류]],표1[등급],"B") -> 85 | S8: =COUNTIFS(표1[대분류],표4[[#This Row],[분류]],표1[등급],"A") -> 67 | T8: =COUNTIFS(표1[대분류],표4[[#This Row],[분류]],표1[등급],"S") -> 60 | U8: =SUM(표4[[#This Row],[D]:[S]]) -> 304 | W8: 브리튼 | X8: =COUNTIFS(표1[문화권],표5[[#This Row],[문화권]],표1[등급],표5[[#Headers],[D]]) -> 6 | Y8: =COUNTIFS(표1[문화권],표5[[#This Row],[문화권]],표1[등급],표5[[#Headers],[C]]) -> 6 | Z8: =COUNTIFS(표1[문화권],표5[[#This Row],[문화권]],표1[등급],표5[[#Headers],[B]]) -> 12 | AA8: =COUNTIFS(표1[문화권],표5[[#This Row],[문화권]],표1[등급],표5[[#Headers],[A]]) -> 7 | AB8: =COUNTIFS(표1[문화권],표5[[#This Row],[문화권]],표1[등급],표5[[#Headers],[S]]) -> 5 | AC8: =SUM(표5[[#This Row],[문화권]:[S]]) -> 36 | AE8: 낚시 | AF8: =COUNTIFS(표1[낚시],">=1",표1[등급],AF5) -> 64 | AG8: =COUNTIFS(표1[낚시],">=1",표1[등급],AG5) -> 64 | AH8: =COUNTIFS(표1[낚시],">=1",표1[등급],AH5) -> 89 | AI8: =COUNTIFS(표1[낚시],">=1",표1[등급],AI5) -> 50 | AJ8: =COUNTIFS(표1[낚시],">=1",표1[등급],AJ5) -> 51 | AK8: =SUM(AF8:AJ8) -> 318 | AM8: 브리튼 | AN8: =COUNTIFS(표1[해양탐색],1,표1[문화권],표6[[#This Row],[문화권]]) -> 0 | AO8: =COUNTIFS(표1[육지탐험],">=1",표1[문화권],표6[[#This Row],[문화권]]) -> 9 | AP8: =SUM(표6[[#This Row],[해양 탐색]:[육지 탐험]]) -> 9
B9: 북아프리카 | C9: =COUNTIF([1]Village!$C:$C,표2[[#This Row],[문화권]]) -> 0 | D9: =COUNTIF([1]LandExplore!$C:$C,표2[[#This Row],[문화권]]) -> 0 | E9: =(표2[[#This Row],[마을]]+표2[[#This Row],[육지]])*$D$3 -> 0 | F9: =COUNTIF(표1[문화권],표2[[#This Row],[문화권]]) -> 71 | G9: =표2[[#This Row],[전체 발견물]]-표2[[#This Row],[필요 발견물]] -> 71 | I9: 30 | J9: 4 | K9: =COUNTIF([3]!표1_6[선단 LV],표3[[#This Row],[레벨 제한]]) -> 3 | L9: =COUNTIF([3]!표8[선단 LV],표3[[#This Row],[레벨 제한]]) -> 5 | M9: =SUM(표3[[#This Row],[육지]:[마을]])*$D$3 -> 40 | O9: 보물 | P9: =COUNTIFS(표1[대분류],표4[[#This Row],[분류]],표1[등급],"D") -> 25 | Q9: =COUNTIFS(표1[대분류],표4[[#This Row],[분류]],표1[등급],"C") -> 48 | R9: =COUNTIFS(표1[대분류],표4[[#This Row],[분류]],표1[등급],"B") -> 78 | S9: =COUNTIFS(표1[대분류],표4[[#This Row],[분류]],표1[등급],"A") -> 59 | T9: =COUNTIFS(표1[대분류],표4[[#This Row],[분류]],표1[등급],"S") -> 51 | U9: =SUM(표4[[#This Row],[D]:[S]]) -> 261 | W9: 북아프리카 | X9: =COUNTIFS(표1[문화권],표5[[#This Row],[문화권]],표1[등급],표5[[#Headers],[D]]) -> 11 | Y9: =COUNTIFS(표1[문화권],표5[[#This Row],[문화권]],표1[등급],표5[[#Headers],[C]]) -> 13 | Z9: =COUNTIFS(표1[문화권],표5[[#This Row],[문화권]],표1[등급],표5[[#Headers],[B]]) -> 21 | AA9: =COUNTIFS(표1[문화권],표5[[#This Row],[문화권]],표1[등급],표5[[#Headers],[A]]) -> 15 | AB9: =COUNTIFS(표1[문화권],표5[[#This Row],[문화권]],표1[등급],표5[[#Headers],[S]]) -> 11 | AC9: =SUM(표5[[#This Row],[문화권]:[S]]) -> 71 | AE9: 항구 | AF9: =COUNTIFS(표1[항구],">=1",표1[등급],AF5) -> 0 | AG9: =COUNTIFS(표1[항구],">=1",표1[등급],AG5) -> 0 | AH9: =COUNTIFS(표1[항구],">=1",표1[등급],AH5) -> 0 | AI9: =COUNTIFS(표1[항구],">=1",표1[등급],AI5) -> 0 | AJ9: =COUNTIFS(표1[항구],">=1",표1[등급],AJ5) -> 0 | AK9: =SUM(AF9:AJ9) -> 0 | AM9: 북아프리카 | AN9: =COUNTIFS(표1[해양탐색],1,표1[문화권],표6[[#This Row],[문화권]]) -> 0 | AO9: =COUNTIFS(표1[육지탐험],">=1",표1[문화권],표6[[#This Row],[문화권]]) -> 19 | AP9: =SUM(표6[[#This Row],[해양 탐색]:[육지 탐험]]) -> 19
B10: 서아프리카 | C10: =COUNTIF([1]Village!$C:$C,표2[[#This Row],[문화권]]) -> 1 | D10: =COUNTIF([1]LandExplore!$C:$C,표2[[#This Row],[문화권]]) -> 0 | E10: =(표2[[#This Row],[마을]]+표2[[#This Row],[육지]])*$D$3 -> 5 | F10: =COUNTIF(표1[문화권],표2[[#This Row],[문화권]]) -> 60 | G10: =표2[[#This Row],[전체 발견물]]-표2[[#This Row],[필요 발견물]] -> 55 | I10: 35 | J10: 5 | K10: =COUNTIF([3]!표1_6[선단 LV],표3[[#This Row],[레벨 제한]]) -> 8 | L10: =COUNTIF([3]!표8[선단 LV],표3[[#This Row],[레벨 제한]]) -> 6 | M10: =SUM(표3[[#This Row],[육지]:[마을]])*$D$3 -> 70 | O10: 식물 | P10: =COUNTIFS(표1[대분류],표4[[#This Row],[분류]],표1[등급],"D") -> 20 | Q10: =COUNTIFS(표1[대분류],표4[[#This Row],[분류]],표1[등급],"C") -> 33 | R10: =COUNTIFS(표1[대분류],표4[[#This Row],[분류]],표1[등급],"B") -> 47 | S10: =COUNTIFS(표1[대분류],표4[[#This Row],[분류]],표1[등급],"A") -> 37 | T10: =COUNTIFS(표1[대분류],표4[[#This Row],[분류]],표1[등급],"S") -> 13 | U10: =SUM(표4[[#This Row],[D]:[S]]) -> 150 | W10: 서아프리카 | X10: =COUNTIFS(표1[문화권],표5[[#This Row],[문화권]],표1[등급],표5[[#Headers],[D]]) -> 8 | Y10: =COUNTIFS(표1[문화권],표5[[#This Row],[문화권]],표1[등급],표5[[#Headers],[C]]) -> 12 | Z10: =COUNTIFS(표1[문화권],표5[[#This Row],[문화권]],표1[등급],표5[[#Headers],[B]]) -> 21 | AA10: =COUNTIFS(표1[문화권],표5[[#This Row],[문화권]],표1[등급],표5[[#Headers],[A]]) -> 13 | AB10: =COUNTIFS(표1[문화권],표5[[#This Row],[문화권]],표1[등급],표5[[#Headers],[S]]) -> 6 | AC10: =SUM(표5[[#This Row],[문화권]:[S]]) -> 60 | AE10: 마을 | AF10: =COUNTIFS(표1[마을],">=1",표1[등급],AF5) -> 0 | AG10: =COUNTIFS(표1[마을],">=1",표1[등급],AG5) -> 0 | AH10: =COUNTIFS(표1[마을],">=1",표1[등급],AH5) -> 0 | AI10: =COUNTIFS(표1[마을],">=1",표1[등급],AI5) -> 0 | AJ10: =COUNTIFS(표1[마을],">=1",표1[등급],AJ5) -> 0 | AK10: =SUM(AF10:AJ10) -> 0 | AM10: 서아프리카 | AN10: =COUNTIFS(표1[해양탐색],1,표1[문화권],표6[[#This Row],[문화권]]) -> 0 | AO10: =COUNTIFS(표1[육지탐험],">=1",표1[문화권],표6[[#This Row],[문화권]]) -> 14 | AP10: =SUM(표6[[#This Row],[해양 탐색]:[육지 탐험]]) -> 14
B11: 남아프리카 | C11: =COUNTIF([1]Village!$C:$C,표2[[#This Row],[문화권]]) -> 0 | D11: =COUNTIF([1]LandExplore!$C:$C,표2[[#This Row],[문화권]]) -> 0 | E11: =(표2[[#This Row],[마을]]+표2[[#This Row],[육지]])*$D$3 -> 0 | F11: =COUNTIF(표1[문화권],표2[[#This Row],[문화권]]) -> 56 | G11: =표2[[#This Row],[전체 발견물]]-표2[[#This Row],[필요 발견물]] -> 56 | I11: 40 | J11: 6 | K11: =COUNTIF([3]!표1_6[선단 LV],표3[[#This Row],[레벨 제한]]) -> 10 | L11: =COUNTIF([3]!표8[선단 LV],표3[[#This Row],[레벨 제한]]) -> 11 | M11: =SUM(표3[[#This Row],[육지]:[마을]])*$D$3 -> 105 | O11: 자연 | P11: =COUNTIFS(표1[대분류],표4[[#This Row],[분류]],표1[등급],"D") -> 79 | Q11: =COUNTIFS(표1[대분류],표4[[#This Row],[분류]],표1[등급],"C") -> 134 | R11: =COUNTIFS(표1[대분류],표4[[#This Row],[분류]],표1[등급],"B") -> 277 | S11: =COUNTIFS(표1[대분류],표4[[#This Row],[분류]],표1[등급],"A") -> 143 | T11: =COUNTIFS(표1[대분류],표4[[#This Row],[분류]],표1[등급],"S") -> 60 | U11: =SUM(표4[[#This Row],[D]:[S]]) -> 693 | W11: 남아프리카 | X11: =COUNTIFS(표1[문화권],표5[[#This Row],[문화권]],표1[등급],표5[[#Headers],[D]]) -> 9 | Y11: =COUNTIFS(표1[문화권],표5[[#This Row],[문화권]],표1[등급],표5[[#Headers],[C]]) -> 8 | Z11: =COUNTIFS(표1[문화권],표5[[#This Row],[문화권]],표1[등급],표5[[#Headers],[B]]) -> 23 | AA11: =COUNTIFS(표1[문화권],표5[[#This Row],[문화권]],표1[등급],표5[[#Headers],[A]]) -> 12 | AB11: =COUNTIFS(표1[문화권],표5[[#This Row],[문화권]],표1[등급],표5[[#Headers],[S]]) -> 4 | AC11: =SUM(표5[[#This Row],[문화권]:[S]]) -> 56 | AE11: 퀘스트 | AF11: =COUNTIFS(표1[퀘스트],">=1",표1[등급],AF5) -> 15 | AG11: =COUNTIFS(표1[퀘스트],">=1",표1[등급],AG5) -> 25 | AH11: =COUNTIFS(표1[퀘스트],">=1",표1[등급],AH5) -> 64 | AI11: =COUNTIFS(표1[퀘스트],">=1",표1[등급],AI5) -> 52 | AJ11: =COUNTIFS(표1[퀘스트],">=1",표1[등급],AJ5) -> 65 | AK11: =SUM(AF11:AJ11) -> 221 | AM11: 남아프리카 | AN11: =COUNTIFS(표1[해양탐색],1,표1[문화권],표6[[#This Row],[문화권]]) -> 0 | AO11: =COUNTIFS(표1[육지탐험],">=1",표1[문화권],표6[[#This Row],[문화권]]) -> 24 | AP11: =SUM(표6[[#This Row],[해양 탐색]:[육지 탐험]]) -> 24
B12: 동아프리카 | C12: =COUNTIF([1]Village!$C:$C,표2[[#This Row],[문화권]]) -> 0 | D12: =COUNTIF([1]LandExplore!$C:$C,표2[[#This Row],[문화권]]) -> 0 | E12: =(표2[[#This Row],[마을]]+표2[[#This Row],[육지]])*$D$3 -> 0 | F12: =COUNTIF(표1[문화권],표2[[#This Row],[문화권]]) -> 40 | G12: =표2[[#This Row],[전체 발견물]]-표2[[#This Row],[필요 발견물]] -> 40 | I12: 45 | J12: 7 | K12: =COUNTIF([3]!표1_6[선단 LV],표3[[#This Row],[레벨 제한]]) -> 6 | L12: =COUNTIF([3]!표8[선단 LV],표3[[#This Row],[레벨 제한]]) -> 1 | M12: =SUM(표3[[#This Row],[육지]:[마을]])*$D$3 -> 35 | O12: 합계 | P12: =SUM(표4[D]) -> 628 | Q12: =SUM(표4[C]) -> 476 | R12: =SUM(표4[B]) -> 797 | S12: =SUM(표4[A]) -> 513 | T12: =SUM(표4[S]) -> 305 | U12: =SUM(U6:U11) -> 2719 | W12: 동아프리카 | X12: =COUNTIFS(표1[문화권],표5[[#This Row],[문화권]],표1[등급],표5[[#Headers],[D]]) -> 7 | Y12: =COUNTIFS(표1[문화권],표5[[#This Row],[문화권]],표1[등급],표5[[#Headers],[C]]) -> 9 | Z12: =COUNTIFS(표1[문화권],표5[[#This Row],[문화권]],표1[등급],표5[[#Headers],[B]]) -> 13 | AA12: =COUNTIFS(표1[문화권],표5[[#This Row],[문화권]],표1[등급],표5[[#Headers],[A]]) -> 6 | AB12: =COUNTIFS(표1[문화권],표5[[#This Row],[문화권]],표1[등급],표5[[#Headers],[S]]) -> 5 | AC12: =SUM(표5[[#This Row],[문화권]:[S]]) -> 40 | AE12: 합계 | AF12: =SUM(AF6:AF11) -> 204 | AG12: =SUM(AG6:AG11) -> 201 | AH12: =SUM(AH6:AH11) -> 258 | AI12: =SUM(AI6:AI11) -> 189 | AJ12: =SUM(AJ6:AJ11) -> 150 | AK12: =SUM(AF12:AJ12) -> 1002 | AM12: 동아프리카 | AN12: =COUNTIFS(표1[해양탐색],1,표1[문화권],표6[[#This Row],[문화권]]) -> 0 | AO12: =COUNTIFS(표1[육지탐험],">=1",표1[문화권],표6[[#This Row],[문화권]]) -> 18 | AP12: =SUM(표6[[#This Row],[해양 탐색]:[육지 탐험]]) -> 18
B13: 서남아시아 | C13: =COUNTIF([1]Village!$C:$C,표2[[#This Row],[문화권]]) -> 0 | D13: =COUNTIF([1]LandExplore!$C:$C,표2[[#This Row],[문화권]]) -> 0 | E13: =(표2[[#This Row],[마을]]+표2[[#This Row],[육지]])*$D$3 -> 0 | F13: =COUNTIF(표1[문화권],표2[[#This Row],[문화권]]) -> 91 | G13: =표2[[#This Row],[전체 발견물]]-표2[[#This Row],[필요 발견물]] -> 91 | I13: 50 | J13: 8 | K13: =COUNTIF([3]!표1_6[선단 LV],표3[[#This Row],[레벨 제한]]) -> 14 | L13: =COUNTIF([3]!표8[선단 LV],표3[[#This Row],[레벨 제한]]) -> 9 | M13: =SUM(표3[[#This Row],[육지]:[마을]])*$D$3 -> 115 | W13: 서남아시아 | X13: =COUNTIFS(표1[문화권],표5[[#This Row],[문화권]],표1[등급],표5[[#Headers],[D]]) -> 5 | Y13: =COUNTIFS(표1[문화권],표5[[#This Row],[문화권]],표1[등급],표5[[#Headers],[C]]) -> 14 | Z13: =COUNTIFS(표1[문화권],표5[[#This Row],[문화권]],표1[등급],표5[[#Headers],[B]]) -> 28 | AA13: =COUNTIFS(표1[문화권],표5[[#This Row],[문화권]],표1[등급],표5[[#Headers],[A]]) -> 21 | AB13: =COUNTIFS(표1[문화권],표5[[#This Row],[문화권]],표1[등급],표5[[#Headers],[S]]) -> 23 | AC13: =SUM(표5[[#This Row],[문화권]:[S]]) -> 91 | AM13: 서남아시아 | AN13: =COUNTIFS(표1[해양탐색],1,표1[문화권],표6[[#This Row],[문화권]]) -> 0 | AO13: =COUNTIFS(표1[육지탐험],">=1",표1[문화권],표6[[#This Row],[문화권]]) -> 13 | AP13: =SUM(표6[[#This Row],[해양 탐색]:[육지 탐험]]) -> 13
B14: 남아시아 | C14: =COUNTIF([1]Village!$C:$C,표2[[#This Row],[문화권]]) -> 2 | D14: =COUNTIF([1]LandExplore!$C:$C,표2[[#This Row],[문화권]]) -> 0 | E14: =(표2[[#This Row],[마을]]+표2[[#This Row],[육지]])*$D$3 -> 10 | F14: =COUNTIF(표1[문화권],표2[[#This Row],[문화권]]) -> 65 | G14: =표2[[#This Row],[전체 발견물]]-표2[[#This Row],[필요 발견물]] -> 55 | I14: 55 | J14: 9 | K14: =COUNTIF([3]!표1_6[선단 LV],표3[[#This Row],[레벨 제한]]) -> 2 | L14: =COUNTIF([3]!표8[선단 LV],표3[[#This Row],[레벨 제한]]) -> 3 | M14: =SUM(표3[[#This Row],[육지]:[마을]])*$D$3 -> 25 | W14: 남아시아 | X14: =COUNTIFS(표1[문화권],표5[[#This Row],[문화권]],표1[등급],표5[[#Headers],[D]]) -> 6 | Y14: =COUNTIFS(표1[문화권],표5[[#This Row],[문화권]],표1[등급],표5[[#Headers],[C]]) -> 11 | Z14: =COUNTIFS(표1[문화권],표5[[#This Row],[문화권]],표1[등급],표5[[#Headers],[B]]) -> 24 | AA14: =COUNTIFS(표1[문화권],표5[[#This Row],[문화권]],표1[등급],표5[[#Headers],[A]]) -> 14 | AB14: =COUNTIFS(표1[문화권],표5[[#This Row],[문화권]],표1[등급],표5[[#Headers],[S]]) -> 10 | AC14: =SUM(표5[[#This Row],[문화권]:[S]]) -> 65 | AM14: 남아시아 | AN14: =COUNTIFS(표1[해양탐색],1,표1[문화권],표6[[#This Row],[문화권]]) -> 0 | AO14: =COUNTIFS(표1[육지탐험],">=1",표1[문화권],표6[[#This Row],[문화권]]) -> 14 | AP14: =SUM(표6[[#This Row],[해양 탐색]:[육지 탐험]]) -> 14
B15: 동남아시아 | C15: =COUNTIF([1]Village!$C:$C,표2[[#This Row],[문화권]]) -> 4 | D15: =COUNTIF([1]LandExplore!$C:$C,표2[[#This Row],[문화권]]) -> 0 | E15: =(표2[[#This Row],[마을]]+표2[[#This Row],[육지]])*$D$3 -> 20 | F15: =COUNTIF(표1[문화권],표2[[#This Row],[문화권]]) -> 141 | G15: =표2[[#This Row],[전체 발견물]]-표2[[#This Row],[필요 발견물]] -> 121 | I15: 80 | J15: 10 | K15: =COUNTIF([3]!표1_6[선단 LV],표3[[#This Row],[레벨 제한]]) -> 18 | L15: =COUNTIF([3]!표8[선단 LV],표3[[#This Row],[레벨 제한]]) -> 14 | M15: =SUM(표3[[#This Row],[육지]:[마을]])*$D$3 -> 160 | W15: 동남아시아 | X15: =COUNTIFS(표1[문화권],표5[[#This Row],[문화권]],표1[등급],표5[[#Headers],[D]]) -> 18 | Y15: =COUNTIFS(표1[문화권],표5[[#This Row],[문화권]],표1[등급],표5[[#Headers],[C]]) -> 32 | Z15: =COUNTIFS(표1[문화권],표5[[#This Row],[문화권]],표1[등급],표5[[#Headers],[B]]) -> 43 | AA15: =COUNTIFS(표1[문화권],표5[[#This Row],[문화권]],표1[등급],표5[[#Headers],[A]]) -> 33 | AB15: =COUNTIFS(표1[문화권],표5[[#This Row],[문화권]],표1[등급],표5[[#Headers],[S]]) -> 15 | AC15: =SUM(표5[[#This Row],[문화권]:[S]]) -> 141 | AM15: 동남아시아 | AN15: =COUNTIFS(표1[해양탐색],1,표1[문화권],표6[[#This Row],[문화권]]) -> 0 | AO15: =COUNTIFS(표1[육지탐험],">=1",표1[문화권],표6[[#This Row],[문화권]]) -> 43 | AP15: =SUM(표6[[#This Row],[해양 탐색]:[육지 탐험]]) -> 43
B16: 동아시아 | C16: =COUNTIF([1]Village!$C:$C,표2[[#This Row],[문화권]]) -> 15 | D16: =COUNTIF([1]LandExplore!$C:$C,표2[[#This Row],[문화권]]) -> 0 | E16: =(표2[[#This Row],[마을]]+표2[[#This Row],[육지]])*$D$3 -> 75 | F16: =COUNTIF(표1[문화권],표2[[#This Row],[문화권]]) -> 330 | G16: =표2[[#This Row],[전체 발견물]]-표2[[#This Row],[필요 발견물]] -> 255 | I16: 80 | J16: 11 | K16: =COUNTIF([3]!표1_6[선단 LV],표3[[#This Row],[레벨 제한]]) -> 18 | L16: =COUNTIF([3]!표8[선단 LV],표3[[#This Row],[레벨 제한]]) -> 14 | M16: =SUM(표3[[#This Row],[육지]:[마을]])*$D$3 -> 160 | W16: 동아시아 | X16: =COUNTIFS(표1[문화권],표5[[#This Row],[문화권]],표1[등급],표5[[#Headers],[D]]) -> 43 | Y16: =COUNTIFS(표1[문화권],표5[[#This Row],[문화권]],표1[등급],표5[[#Headers],[C]]) -> 77 | Z16: =COUNTIFS(표1[문화권],표5[[#This Row],[문화권]],표1[등급],표5[[#Headers],[B]]) -> 111 | AA16: =COUNTIFS(표1[문화권],표5[[#This Row],[문화권]],표1[등급],표5[[#Headers],[A]]) -> 65 | AB16: =COUNTIFS(표1[문화권],표5[[#This Row],[문화권]],표1[등급],표5[[#Headers],[S]]) -> 34 | AC16: =SUM(표5[[#This Row],[문화권]:[S]]) -> 330 | AM16: 동아시아 | AN16: =COUNTIFS(표1[해양탐색],1,표1[문화권],표6[[#This Row],[문화권]]) -> 0 | AO16: =COUNTIFS(표1[육지탐험],">=1",표1[문화권],표6[[#This Row],[문화권]]) -> 84 | AP16: =SUM(표6[[#This Row],[해양 탐색]:[육지 탐험]]) -> 84
B17: 오세아니아 | C17: =COUNTIF([1]Village!$C:$C,표2[[#This Row],[문화권]]) -> 6 | D17: =COUNTIF([1]LandExplore!$C:$C,표2[[#This Row],[문화권]]) -> 0 | E17: =(표2[[#This Row],[마을]]+표2[[#This Row],[육지]])*$D$3 -> 30 | F17: =COUNTIF(표1[문화권],표2[[#This Row],[문화권]]) -> 84 | G17: =표2[[#This Row],[전체 발견물]]-표2[[#This Row],[필요 발견물]] -> 54 | I17: 80 | J17: 12 | K17: =COUNTIF([3]!표1_6[선단 LV],표3[[#This Row],[레벨 제한]]) -> 18 | L17: =COUNTIF([3]!표8[선단 LV],표3[[#This Row],[레벨 제한]]) -> 14 | M17: =SUM(표3[[#This Row],[육지]:[마을]])*$D$3 -> 160 | W17: 오세아니아 | X17: =COUNTIFS(표1[문화권],표5[[#This Row],[문화권]],표1[등급],표5[[#Headers],[D]]) -> 19 | Y17: =COUNTIFS(표1[문화권],표5[[#This Row],[문화권]],표1[등급],표5[[#Headers],[C]]) -> 16 | Z17: =COUNTIFS(표1[문화권],표5[[#This Row],[문화권]],표1[등급],표5[[#Headers],[B]]) -> 23 | AA17: =COUNTIFS(표1[문화권],표5[[#This Row],[문화권]],표1[등급],표5[[#Headers],[A]]) -> 17 | AB17: =COUNTIFS(표1[문화권],표5[[#This Row],[문화권]],표1[등급],표5[[#Headers],[S]]) -> 9 | AC17: =SUM(표5[[#This Row],[문화권]:[S]]) -> 84 | AM17: 오세아니아 | AN17: =COUNTIFS(표1[해양탐색],1,표1[문화권],표6[[#This Row],[문화권]]) -> 0 | AO17: =COUNTIFS(표1[육지탐험],">=1",표1[문화권],표6[[#This Row],[문화권]]) -> 24 | AP17: =SUM(표6[[#This Row],[해양 탐색]:[육지 탐험]]) -> 24
B18: 태평양 | C18: =COUNTIF([1]Village!$C:$C,표2[[#This Row],[문화권]]) -> 3 | D18: =COUNTIF([1]LandExplore!$C:$C,표2[[#This Row],[문화권]]) -> 0 | E18: =(표2[[#This Row],[마을]]+표2[[#This Row],[육지]])*$D$3 -> 15 | F18: =COUNTIF(표1[문화권],표2[[#This Row],[문화권]]) -> 37 | G18: =표2[[#This Row],[전체 발견물]]-표2[[#This Row],[필요 발견물]] -> 22 | I18: 합계 | J18: - | K18: =SUM(표3[육지])-SUM(K16:K17) -> 84 | L18: =SUM(표3[마을])-SUM(L16:L17) -> 65 | M18: =SUM(표3[필요 발견물])-SUM(M16:M17) -> 745 | W18: 태평양 | X18: =COUNTIFS(표1[문화권],표5[[#This Row],[문화권]],표1[등급],표5[[#Headers],[D]]) -> 4 | Y18: =COUNTIFS(표1[문화권],표5[[#This Row],[문화권]],표1[등급],표5[[#Headers],[C]]) -> 5 | Z18: =COUNTIFS(표1[문화권],표5[[#This Row],[문화권]],표1[등급],표5[[#Headers],[B]]) -> 14 | AA18: =COUNTIFS(표1[문화권],표5[[#This Row],[문화권]],표1[등급],표5[[#Headers],[A]]) -> 7 | AB18: =COUNTIFS(표1[문화권],표5[[#This Row],[문화권]],표1[등급],표5[[#Headers],[S]]) -> 7 | AC18: =SUM(표5[[#This Row],[문화권]:[S]]) -> 37 | AM18: 태평양 | AN18: =COUNTIFS(표1[해양탐색],1,표1[문화권],표6[[#This Row],[문화권]]) -> 0 | AO18: =COUNTIFS(표1[육지탐험],">=1",표1[문화권],표6[[#This Row],[문화권]]) -> 6 | AP18: =SUM(표6[[#This Row],[해양 탐색]:[육지 탐험]]) -> 6
B19: 유라시아 | C19: =COUNTIF([1]Village!$C:$C,표2[[#This Row],[문화권]]) -> 5 | D19: =COUNTIF([1]LandExplore!$C:$C,표2[[#This Row],[문화권]]) -> 0 | E19: =(표2[[#This Row],[마을]]+표2[[#This Row],[육지]])*$D$3 -> 25 | F19: =COUNTIF(표1[문화권],표2[[#This Row],[문화권]]) -> 29 | G19: =표2[[#This Row],[전체 발견물]]-표2[[#This Row],[필요 발견물]] -> 4 | W19: 유라시아 | X19: =COUNTIFS(표1[문화권],표5[[#This Row],[문화권]],표1[등급],표5[[#Headers],[D]]) -> 2 | Y19: =COUNTIFS(표1[문화권],표5[[#This Row],[문화권]],표1[등급],표5[[#Headers],[C]]) -> 4 | Z19: =COUNTIFS(표1[문화권],표5[[#This Row],[문화권]],표1[등급],표5[[#Headers],[B]]) -> 13 | AA19: =COUNTIFS(표1[문화권],표5[[#This Row],[문화권]],표1[등급],표5[[#Headers],[A]]) -> 7 | AB19: =COUNTIFS(표1[문화권],표5[[#This Row],[문화권]],표1[등급],표5[[#Headers],[S]]) -> 3 | AC19: =SUM(표5[[#This Row],[문화권]:[S]]) -> 29 | AM19: 유라시아 | AN19: =COUNTIFS(표1[해양탐색],1,표1[문화권],표6[[#This Row],[문화권]]) -> 0 | AO19: =COUNTIFS(표1[육지탐험],">=1",표1[문화권],표6[[#This Row],[문화권]]) -> 11 | AP19: =SUM(표6[[#This Row],[해양 탐색]:[육지 탐험]]) -> 11
B20: 북아메리카 | C20: =COUNTIF([1]Village!$C:$C,표2[[#This Row],[문화권]]) -> 11 | D20: =COUNTIF([1]LandExplore!$C:$C,표2[[#This Row],[문화권]]) -> 0 | E20: =(표2[[#This Row],[마을]]+표2[[#This Row],[육지]])*$D$3 -> 55 | F20: =COUNTIF(표1[문화권],표2[[#This Row],[문화권]]) -> 131 | G20: =표2[[#This Row],[전체 발견물]]-표2[[#This Row],[필요 발견물]] -> 76 | W20: 북아메리카 | X20: =COUNTIFS(표1[문화권],표5[[#This Row],[문화권]],표1[등급],표5[[#Headers],[D]]) -> 12 | Y20: =COUNTIFS(표1[문화권],표5[[#This Row],[문화권]],표1[등급],표5[[#Headers],[C]]) -> 26 | Z20: =COUNTIFS(표1[문화권],표5[[#This Row],[문화권]],표1[등급],표5[[#Headers],[B]]) -> 56 | AA20: =COUNTIFS(표1[문화권],표5[[#This Row],[문화권]],표1[등급],표5[[#Headers],[A]]) -> 31 | AB20: =COUNTIFS(표1[문화권],표5[[#This Row],[문화권]],표1[등급],표5[[#Headers],[S]]) -> 6 | AC20: =SUM(표5[[#This Row],[문화권]:[S]]) -> 131 | AM20: 북아메리카 | AN20: =COUNTIFS(표1[해양탐색],1,표1[문화권],표6[[#This Row],[문화권]]) -> 0 | AO20: =COUNTIFS(표1[육지탐험],">=1",표1[문화권],표6[[#This Row],[문화권]]) -> 35 | AP20: =SUM(표6[[#This Row],[해양 탐색]:[육지 탐험]]) -> 35
B21: 중앙아메리카 | C21: =COUNTIF([1]Village!$C:$C,표2[[#This Row],[문화권]]) -> 3 | D21: =COUNTIF([1]LandExplore!$C:$C,표2[[#This Row],[문화권]]) -> 0 | E21: =(표2[[#This Row],[마을]]+표2[[#This Row],[육지]])*$D$3 -> 15 | F21: =COUNTIF(표1[문화권],표2[[#This Row],[문화권]]) -> 86 | G21: =표2[[#This Row],[전체 발견물]]-표2[[#This Row],[필요 발견물]] -> 71 | W21: 중앙아메리카 | X21: =COUNTIFS(표1[문화권],표5[[#This Row],[문화권]],표1[등급],표5[[#Headers],[D]]) -> 10 | Y21: =COUNTIFS(표1[문화권],표5[[#This Row],[문화권]],표1[등급],표5[[#Headers],[C]]) -> 12 | Z21: =COUNTIFS(표1[문화권],표5[[#This Row],[문화권]],표1[등급],표5[[#Headers],[B]]) -> 34 | AA21: =COUNTIFS(표1[문화권],표5[[#This Row],[문화권]],표1[등급],표5[[#Headers],[A]]) -> 22 | AB21: =COUNTIFS(표1[문화권],표5[[#This Row],[문화권]],표1[등급],표5[[#Headers],[S]]) -> 8 | AC21: =SUM(표5[[#This Row],[문화권]:[S]]) -> 86 | AM21: 중앙아메리카 | AN21: =COUNTIFS(표1[해양탐색],1,표1[문화권],표6[[#This Row],[문화권]]) -> 0 | AO21: =COUNTIFS(표1[육지탐험],">=1",표1[문화권],표6[[#This Row],[문화권]]) -> 18 | AP21: =SUM(표6[[#This Row],[해양 탐색]:[육지 탐험]]) -> 18
B22: 남아메리카 | C22: =COUNTIF([1]Village!$C:$C,표2[[#This Row],[문화권]]) -> 7 | D22: =COUNTIF([1]LandExplore!$C:$C,표2[[#This Row],[문화권]]) -> 0 | E22: =(표2[[#This Row],[마을]]+표2[[#This Row],[육지]])*$D$3 -> 35 | F22: =COUNTIF(표1[문화권],표2[[#This Row],[문화권]]) -> 164 | G22: =표2[[#This Row],[전체 발견물]]-표2[[#This Row],[필요 발견물]] -> 129 | W22: 남아메리카 | X22: =COUNTIFS(표1[문화권],표5[[#This Row],[문화권]],표1[등급],표5[[#Headers],[D]]) -> 20 | Y22: =COUNTIFS(표1[문화권],표5[[#This Row],[문화권]],표1[등급],표5[[#Headers],[C]]) -> 34 | Z22: =COUNTIFS(표1[문화권],표5[[#This Row],[문화권]],표1[등급],표5[[#Headers],[B]]) -> 53 | AA22: =COUNTIFS(표1[문화권],표5[[#This Row],[문화권]],표1[등급],표5[[#Headers],[A]]) -> 41 | AB22: =COUNTIFS(표1[문화권],표5[[#This Row],[문화권]],표1[등급],표5[[#Headers],[S]]) -> 16 | AC22: =SUM(표5[[#This Row],[문화권]:[S]]) -> 164 | AM22: 남아메리카 | AN22: =COUNTIFS(표1[해양탐색],1,표1[문화권],표6[[#This Row],[문화권]]) -> 0 | AO22: =COUNTIFS(표1[육지탐험],">=1",표1[문화권],표6[[#This Row],[문화권]]) -> 53 | AP22: =SUM(표6[[#This Row],[해양 탐색]:[육지 탐험]]) -> 53
B23: 극지방 | C23: =COUNTIF([1]Village!$C:$C,표2[[#This Row],[문화권]]) -> 6 | D23: =COUNTIF([1]LandExplore!$C:$C,표2[[#This Row],[문화권]]) -> 0 | E23: =(표2[[#This Row],[마을]]+표2[[#This Row],[육지]])*$D$3 -> 30 | F23: =COUNTIF(표1[문화권],표2[[#This Row],[문화권]]) -> 74 | G23: =표2[[#This Row],[전체 발견물]]-표2[[#This Row],[필요 발견물]] -> 44 | W23: 극지방 | X23: =COUNTIFS(표1[문화권],표5[[#This Row],[문화권]],표1[등급],표5[[#Headers],[D]]) -> 1 | Y23: =COUNTIFS(표1[문화권],표5[[#This Row],[문화권]],표1[등급],표5[[#Headers],[C]]) -> 12 | Z23: =COUNTIFS(표1[문화권],표5[[#This Row],[문화권]],표1[등급],표5[[#Headers],[B]]) -> 37 | AA23: =COUNTIFS(표1[문화권],표5[[#This Row],[문화권]],표1[등급],표5[[#Headers],[A]]) -> 19 | AB23: =COUNTIFS(표1[문화권],표5[[#This Row],[문화권]],표1[등급],표5[[#Headers],[S]]) -> 5 | AC23: =SUM(표5[[#This Row],[문화권]:[S]]) -> 74 | AM23: 극지방 | AN23: =COUNTIFS(표1[해양탐색],1,표1[문화권],표6[[#This Row],[문화권]]) -> 0 | AO23: =COUNTIFS(표1[육지탐험],">=1",표1[문화권],표6[[#This Row],[문화권]]) -> 8 | AP23: =SUM(표6[[#This Row],[해양 탐색]:[육지 탐험]]) -> 8
B24: 마을 | C24: =COUNTIF([1]Village!$C:$C,표2[[#This Row],[문화권]]) -> 0 | D24: =COUNTIF([1]LandExplore!$C:$C,표2[[#This Row],[문화권]]) -> 0 | E24: =(표2[[#This Row],[마을]]+표2[[#This Row],[육지]])*$D$3 -> 0 | F24: =COUNTIF(표1[문화권],표2[[#This Row],[문화권]]) -> 66 | G24: =표2[[#This Row],[전체 발견물]]-표2[[#This Row],[필요 발견물]] -> 66 | W24: 마을 | X24: =COUNTIFS(표1[문화권],표5[[#This Row],[문화권]],표1[등급],표5[[#Headers],[D]]) -> 66 | Y24: =COUNTIFS(표1[문화권],표5[[#This Row],[문화권]],표1[등급],표5[[#Headers],[C]]) -> 0 | Z24: =COUNTIFS(표1[문화권],표5[[#This Row],[문화권]],표1[등급],표5[[#Headers],[B]]) -> 0 | AA24: =COUNTIFS(표1[문화권],표5[[#This Row],[문화권]],표1[등급],표5[[#Headers],[A]]) -> 0 | AB24: =COUNTIFS(표1[문화권],표5[[#This Row],[문화권]],표1[등급],표5[[#Headers],[S]]) -> 0 | AC24: =SUM(표5[[#This Row],[문화권]:[S]]) -> 66 | AM24: 합계 | AN24: =SUM(표6[해양 탐색]) -> 0 | AO24: =SUM(표6[육지 탐험]) -> 456 | AP24: =SUM(AN24:AO24) -> 456
B25: 항구 | C25: =COUNTIF([1]Village!$C:$C,표2[[#This Row],[문화권]]) -> 0 | D25: =COUNTIF([1]LandExplore!$C:$C,표2[[#This Row],[문화권]]) -> 0 | E25: =(표2[[#This Row],[마을]]+표2[[#This Row],[육지]])*$D$3 -> 0 | F25: =COUNTIF(표1[문화권],표2[[#This Row],[문화권]]) -> 218 | G25: =표2[[#This Row],[전체 발견물]]-표2[[#This Row],[필요 발견물]] -> 218 | W25: 항구 | X25: =COUNTIFS(표1[문화권],표5[[#This Row],[문화권]],표1[등급],표5[[#Headers],[D]]) -> 218 | Y25: =COUNTIFS(표1[문화권],표5[[#This Row],[문화권]],표1[등급],표5[[#Headers],[C]]) -> 0 | Z25: =COUNTIFS(표1[문화권],표5[[#This Row],[문화권]],표1[등급],표5[[#Headers],[B]]) -> 0 | AA25: =COUNTIFS(표1[문화권],표5[[#This Row],[문화권]],표1[등급],표5[[#Headers],[A]]) -> 0 | AB25: =COUNTIFS(표1[문화권],표5[[#This Row],[문화권]],표1[등급],표5[[#Headers],[S]]) -> 0 | AC25: =SUM(표5[[#This Row],[문화권]:[S]]) -> 218
B26: 어류 | C26: =COUNTIF([1]Village!$C:$C,표2[[#This Row],[문화권]]) -> 0 | D26: =COUNTIF([1]LandExplore!$C:$C,표2[[#This Row],[문화권]]) -> 0 | E26: =(표2[[#This Row],[마을]]+표2[[#This Row],[육지]])*$D$3 -> 0 | F26: =COUNTIF(표1[문화권],표2[[#This Row],[문화권]]) -> 425 | G26: =표2[[#This Row],[전체 발견물]]-표2[[#This Row],[필요 발견물]] -> 425 | W26: 어류 | X26: =COUNTIFS(표1[문화권],표5[[#This Row],[문화권]],표1[등급],표5[[#Headers],[D]]) -> 79 | Y26: =COUNTIFS(표1[문화권],표5[[#This Row],[문화권]],표1[등급],표5[[#Headers],[C]]) -> 84 | Z26: =COUNTIFS(표1[문화권],표5[[#This Row],[문화권]],표1[등급],표5[[#Headers],[B]]) -> 129 | AA26: =COUNTIFS(표1[문화권],표5[[#This Row],[문화권]],표1[등급],표5[[#Headers],[A]]) -> 64 | AB26: =COUNTIFS(표1[문화권],표5[[#This Row],[문화권]],표1[등급],표5[[#Headers],[S]]) -> 69 | AC26: =SUM(표5[[#This Row],[문화권]:[S]]) -> 425
B27: 천문 | C27: =COUNTIF([1]Village!$C:$C,표2[[#This Row],[문화권]]) -> 0 | D27: =COUNTIF([1]LandExplore!$C:$C,표2[[#This Row],[문화권]]) -> 0 | E27: =(표2[[#This Row],[마을]]+표2[[#This Row],[육지]])*$D$3 -> 0 | F27: =COUNTIF(표1[문화권],표2[[#This Row],[문화권]]) -> 145 | G27: =표2[[#This Row],[전체 발견물]]-표2[[#This Row],[필요 발견물]] -> 145 | W27: 천문 | X27: =COUNTIFS(표1[문화권],표5[[#This Row],[문화권]],표1[등급],표5[[#Headers],[D]]) -> 35 | Y27: =COUNTIFS(표1[문화권],표5[[#This Row],[문화권]],표1[등급],표5[[#Headers],[C]]) -> 24 | Z27: =COUNTIFS(표1[문화권],표5[[#This Row],[문화권]],표1[등급],표5[[#Headers],[B]]) -> 34 | AA27: =COUNTIFS(표1[문화권],표5[[#This Row],[문화권]],표1[등급],표5[[#Headers],[A]]) -> 35 | AB27: =COUNTIFS(표1[문화권],표5[[#This Row],[문화권]],표1[등급],표5[[#Headers],[S]]) -> 17 | AC27: =SUM(표5[[#This Row],[문화권]:[S]]) -> 145
B28: 화석 | C28: =COUNTIF([1]Village!$C:$C,표2[[#This Row],[문화권]]) -> 0 | D28: =COUNTIF([1]LandExplore!$C:$C,표2[[#This Row],[문화권]]) -> 0 | E28: =(표2[[#This Row],[마을]]+표2[[#This Row],[육지]])*$D$3 -> 0 | F28: =COUNTIF(표1[문화권],표2[[#This Row],[문화권]]) -> 34 | G28: =표2[[#This Row],[전체 발견물]]-표2[[#This Row],[필요 발견물]] -> 34 | W28: 화석 | X28: =COUNTIFS(표1[문화권],표5[[#This Row],[문화권]],표1[등급],표5[[#Headers],[D]]) -> 4 | Y28: =COUNTIFS(표1[문화권],표5[[#This Row],[문화권]],표1[등급],표5[[#Headers],[C]]) -> 9 | Z28: =COUNTIFS(표1[문화권],표5[[#This Row],[문화권]],표1[등급],표5[[#Headers],[B]]) -> 11 | AA28: =COUNTIFS(표1[문화권],표5[[#This Row],[문화권]],표1[등급],표5[[#Headers],[A]]) -> 9 | AB28: =COUNTIFS(표1[문화권],표5[[#This Row],[문화권]],표1[등급],표5[[#Headers],[S]]) -> 1 | AC28: =SUM(표5[[#This Row],[문화권]:[S]]) -> 34
B29: 합계 | C29: =SUM(표2[마을]) -> 66 | D29: =SUM(표2[육지]) -> 0 | E29: =SUM(표2[필요 발견물]) -> 330 | F29: =SUM(표2[전체 발견물]) -> 2718 | W29: 합계 | X29: =SUM(표5[D]) -> 627 | Y29: =SUM(표5[C]) -> 476 | Z29: =SUM(표5[B]) -> 797 | AA29: =SUM(표5[A]) -> 513 | AB29: =SUM(표5[S]) -> 305 | AC29: =SUM(X29:AB29) -> 2718
B31: *육지 등급에 따른 발견물 상한등급
B32: 단계 | C32: 상한등급
B33: 1 | C33: B
B34: 2 | C34: B
B35: 3 | C35: B
B36: 4 | C36: B
B37: 5 | C37: B
B38: 6 | C38: B
B39: 7 | C39: A
B40: 8 | C40: A
B41: 9 | C41: A
B42: 10 | C42: S
B43: 11 | C43: S
...

Sheet 해양 오브젝트 배치
B2: 해양 오브젝트 | C2: 레벨 제한 | D2: 위도 | E2: 경도 | F2: Contentsterms[]["id"] | G2: Contentsterms[]["Target"] | H2: Contentsterms[]["Count"]
B3: =[2]OceanDoodad!Z8 -> 0 | C3: =IFERROR(VLOOKUP(표11[[#This Row],[해양 오브젝트]],[3]!표1[[이름]:[선단 LV]],6,FALSE),"-") -> - | D3: =IFERROR(VLOOKUP(표11[[#This Row],[해양 오브젝트]],[3]!표1[[이름]:[위도]],3,FALSE),"-") -> - | E3: =IFERROR(VLOOKUP(표11[[#This Row],[해양 오브젝트]],[3]!표1[[이름]:[위도]],2,FALSE),"-") -> - | F3: =IFERROR(INDEX([1]Discovery!$AW:$AW,MATCH(표11[[#This Row],[해양 오브젝트]],[1]Discovery!$B:$B,0)),"-") -> - | G3: =IFERROR(INDEX([1]Discovery!$AY:$AY,MATCH(표11[[#This Row],[해양 오브젝트]],[1]Discovery!$B:$B,0)),"-") -> - | H3: =IFERROR(INDEX([1]Discovery!$BA:$BA,MATCH(표11[[#This Row],[해양 오브젝트]],[1]Discovery!$B:$B,0)),"-") -> -
B4: =[2]OceanDoodad!Z9 -> 0 | C4: =IFERROR(VLOOKUP(표11[[#This Row],[해양 오브젝트]],[3]!표1[[이름]:[선단 LV]],6,FALSE),"-") -> - | D4: =IFERROR(VLOOKUP(표11[[#This Row],[해양 오브젝트]],[3]!표1[[이름]:[위도]],3,FALSE),"-") -> - | E4: =IFERROR(VLOOKUP(표11[[#This Row],[해양 오브젝트]],[3]!표1[[이름]:[위도]],2,FALSE),"-") -> - | F4: =IFERROR(INDEX([1]Discovery!$AW:$AW,MATCH(표11[[#This Row],[해양 오브젝트]],[1]Discovery!$B:$B,0)),"-") -> - | G4: =IFERROR(INDEX([1]Discovery!$AY:$AY,MATCH(표11[[#This Row],[해양 오브젝트]],[1]Discovery!$B:$B,0)),"-") -> - | H4: =IFERROR(INDEX([1]Discovery!$BA:$BA,MATCH(표11[[#This Row],[해양 오브젝트]],[1]Discovery!$B:$B,0)),"-") -> -
B5: =[2]OceanDoodad!Z10 -> 0 | C5: =IFERROR(VLOOKUP(표11[[#This Row],[해양 오브젝트]],[3]!표1[[이름]:[선단 LV]],6,FALSE),"-") -> - | D5: =IFERROR(VLOOKUP(표11[[#This Row],[해양 오브젝트]],[3]!표1[[이름]:[위도]],3,FALSE),"-") -> - | E5: =IFERROR(VLOOKUP(표11[[#This Row],[해양 오브젝트]],[3]!표1[[이름]:[위도]],2,FALSE),"-") -> - | F5: =IFERROR(INDEX([1]Discovery!$AW:$AW,MATCH(표11[[#This Row],[해양 오브젝트]],[1]Discovery!$B:$B,0)),"-") -> - | G5: =IFERROR(INDEX([1]Discovery!$AY:$AY,MATCH(표11[[#This Row],[해양 오브젝트]],[1]Discovery!$B:$B,0)),"-") -> - | H5: =IFERROR(INDEX([1]Discovery!$BA:$BA,MATCH(표11[[#This Row],[해양 오브젝트]],[1]Discovery!$B:$B,0)),"-") -> -
B6: =[2]OceanDoodad!Z11 -> 0 | C6: =IFERROR(VLOOKUP(표11[[#This Row],[해양 오브젝트]],[3]!표1[[이름]:[선단 LV]],6,FALSE),"-") -> - | D6: =IFERROR(VLOOKUP(표11[[#This Row],[해양 오브젝트]],[3]!표1[[이름]:[위도]],3,FALSE),"-") -> - | E6: =IFERROR(VLOOKUP(표11[[#This Row],[해양 오브젝트]],[3]!표1[[이름]:[위도]],2,FALSE),"-") -> - | F6: =IFERROR(INDEX([1]Discovery!$AW:$AW,MATCH(표11[[#This Row],[해양 오브젝트]],[1]Discovery!$B:$B,0)),"-") -> - | G6: =IFERROR(INDEX([1]Discovery!$AY:$AY,MATCH(표11[[#This Row],[해양 오브젝트]],[1]Discovery!$B:$B,0)),"-") -> - | H6: =IFERROR(INDEX([1]Discovery!$BA:$BA,MATCH(표11[[#This Row],[해양 오브젝트]],[1]Discovery!$B:$B,0)),"-") -> -
B7: =[2]OceanDoodad!Z12 -> 0 | C7: =IFERROR(VLOOKUP(표11[[#This Row],[해양 오브젝트]],[3]!표1[[이름]:[선단 LV]],6,FALSE),"-") -> - | D7: =IFERROR(VLOOKUP(표11[[#This Row],[해양 오브젝트]],[3]!표1[[이름]:[위도]],3,FALSE),"-") -> - | E7: =IFERROR(VLOOKUP(표11[[#This Row],[해양 오브젝트]],[3]!표1[[이름]:[위도]],2,FALSE),"-") -> - | F7: =IFERROR(INDEX([1]Discovery!$AW:$AW,MATCH(표11[[#This Row],[해양 오브젝트]],[1]Discovery!$B:$B,0)),"-") -> - | G7: =IFERROR(INDEX([1]Discovery!$AY:$AY,MATCH(표11[[#This Row],[해양 오브젝트]],[1]Discovery!$B:$B,0)),"-") -> - | H7: =IFERROR(INDEX([1]Discovery!$BA:$BA,MATCH(표11[[#This Row],[해양 오브젝트]],[1]Discovery!$B:$B,0)),"-") -> -
B8: =[2]OceanDoodad!Z13 -> 0 | C8: =IFERROR(VLOOKUP(표11[[#This Row],[해양 오브젝트]],[3]!표1[[이름]:[선단 LV]],6,FALSE),"-") -> - | D8: =IFERROR(VLOOKUP(표11[[#This Row],[해양 오브젝트]],[3]!표1[[이름]:[위도]],3,FALSE),"-") -> - | E8: =IFERROR(VLOOKUP(표11[[#This Row],[해양 오브젝트]],[3]!표1[[이름]:[위도]],2,FALSE),"-") -> - | F8: =IFERROR(INDEX([1]Discovery!$AW:$AW,MATCH(표11[[#This Row],[해양 오브젝트]],[1]Discovery!$B:$B,0)),"-") -> - | G8: =IFERROR(INDEX([1]Discovery!$AY:$AY,MATCH(표11[[#This Row],[해양 오브젝트]],[1]Discovery!$B:$B,0)),"-") -> - | H8: =IFERROR(INDEX([1]Discovery!$BA:$BA,MATCH(표11[[#This Row],[해양 오브젝트]],[1]Discovery!$B:$B,0)),"-") -> -
B9: =[2]OceanDoodad!Z14 -> 0 | C9: =IFERROR(VLOOKUP(표11[[#This Row],[해양 오브젝트]],[3]!표1[[이름]:[선단 LV]],6,FALSE),"-") -> - | D9: =IFERROR(VLOOKUP(표11[[#This Row],[해양 오브젝트]],[3]!표1[[이름]:[위도]],3,FALSE),"-") -> - | E9: =IFERROR(VLOOKUP(표11[[#This Row],[해양 오브젝트]],[3]!표1[[이름]:[위도]],2,FALSE),"-") -> - | F9: =IFERROR(INDEX([1]Discovery!$AW:$AW,MATCH(표11[[#This Row],[해양 오브젝트]],[1]Discovery!$B:$B,0)),"-") -> - | G9: =IFERROR(INDEX([1]Discovery!$AY:$AY,MATCH(표11[[#This Row],[해양 오브젝트]],[1]Discovery!$B:$B,0)),"-") -> - | H9: =IFERROR(INDEX([1]Discovery!$BA:$BA,MATCH(표11[[#This Row],[해양 오브젝트]],[1]Discovery!$B:$B,0)),"-") -> -
B10: =[2]OceanDoodad!Z15 -> 0 | C10: =IFERROR(VLOOKUP(표11[[#This Row],[해양 오브젝트]],[3]!표1[[이름]:[선단 LV]],6,FALSE),"-") -> - | D10: =IFERROR(VLOOKUP(표11[[#This Row],[해양 오브젝트]],[3]!표1[[이름]:[위도]],3,FALSE),"-") -> - | E10: =IFERROR(VLOOKUP(표11[[#This Row],[해양 오브젝트]],[3]!표1[[이름]:[위도]],2,FALSE),"-") -> - | F10: =IFERROR(INDEX([1]Discovery!$AW:$AW,MATCH(표11[[#This Row],[해양 오브젝트]],[1]Discovery!$B:$B,0)),"-") -> - | G10: =IFERROR(INDEX([1]Discovery!$AY:$AY,MATCH(표11[[#This Row],[해양 오브젝트]],[1]Discovery!$B:$B,0)),"-") -> - | H10: =IFERROR(INDEX([1]Discovery!$BA:$BA,MATCH(표11[[#This Row],[해양 오브젝트]],[1]Discovery!$B:$B,0)),"-") -> -
B11: =[2]OceanDoodad!Z16 -> 0 | C11: =IFERROR(VLOOKUP(표11[[#This Row],[해양 오브젝트]],[3]!표1[[이름]:[선단 LV]],6,FALSE),"-") -> - | D11: =IFERROR(VLOOKUP(표11[[#This Row],[해양 오브젝트]],[3]!표1[[이름]:[위도]],3,FALSE),"-") -> - | E11: =IFERROR(VLOOKUP(표11[[#This Row],[해양 오브젝트]],[3]!표1[[이름]:[위도]],2,FALSE),"-") -> - | F11: =IFERROR(INDEX([1]Discovery!$AW:$AW,MATCH(표11[[#This Row],[해양 오브젝트]],[1]Discovery!$B:$B,0)),"-") -> - | G11: =IFERROR(INDEX([1]Discovery!$AY:$AY,MATCH(표11[[#This Row],[해양 오브젝트]],[1]Discovery!$B:$B,0)),"-") -> - | H11: =IFERROR(INDEX([1]Discovery!$BA:$BA,MATCH(표11[[#This Row],[해양 오브젝트]],[1]Discovery!$B:$B,0)),"-") -> -
B12: =[2]OceanDoodad!Z17 -> 0 | C12: =IFERROR(VLOOKUP(표11[[#This Row],[해양 오브젝트]],[3]!표1[[이름]:[선단 LV]],6,FALSE),"-") -> - | D12: =IFERROR(VLOOKUP(표11[[#This Row],[해양 오브젝트]],[3]!표1[[이름]:[위도]],3,FALSE),"-") -> - | E12: =IFERROR(VLOOKUP(표11[[#This Row],[해양 오브젝트]],[3]!표1[[이름]:[위도]],2,FALSE),"-") -> - | F12: =IFERROR(INDEX([1]Discovery!$AW:$AW,MATCH(표11[[#This Row],[해양 오브젝트]],[1]Discovery!$B:$B,0)),"-") -> - | G12: =IFERROR(INDEX([1]Discovery!$AY:$AY,MATCH(표11[[#This Row],[해양 오브젝트]],[1]Discovery!$B:$B,0)),"-") -> - | H12: =IFERROR(INDEX([1]Discovery!$BA:$BA,MATCH(표11[[#This Row],[해양 오브젝트]],[1]Discovery!$B:$B,0)),"-") -> -
B13: =[2]OceanDoodad!Z18 -> 0 | C13: =IFERROR(VLOOKUP(표11[[#This Row],[해양 오브젝트]],[3]!표1[[이름]:[선단 LV]],6,FALSE),"-") -> - | D13: =IFERROR(VLOOKUP(표11[[#This Row],[해양 오브젝트]],[3]!표1[[이름]:[위도]],3,FALSE),"-") -> - | E13: =IFERROR(VLOOKUP(표11[[#This Row],[해양 오브젝트]],[3]!표1[[이름]:[위도]],2,FALSE),"-") -> - | F13: =IFERROR(INDEX([1]Discovery!$AW:$AW,MATCH(표11[[#This Row],[해양 오브젝트]],[1]Discovery!$B:$B,0)),"-") -> - | G13: =IFERROR(INDEX([1]Discovery!$AY:$AY,MATCH(표11[[#This Row],[해양 오브젝트]],[1]Discovery!$B:$B,0)),"-") -> - | H13: =IFERROR(INDEX([1]Discovery!$BA:$BA,MATCH(표11[[#This Row],[해양 오브젝트]],[1]Discovery!$B:$B,0)),"-") -> -
B14: =[2]OceanDoodad!Z19 -> 0 | C14: =IFERROR(VLOOKUP(표11[[#This Row],[해양 오브젝트]],[3]!표1[[이름]:[선단 LV]],6,FALSE),"-") -> - | D14: =IFERROR(VLOOKUP(표11[[#This Row],[해양 오브젝트]],[3]!표1[[이름]:[위도]],3,FALSE),"-") -> - | E14: =IFERROR(VLOOKUP(표11[[#This Row],[해양 오브젝트]],[3]!표1[[이름]:[위도]],2,FALSE),"-") -> - | F14: =IFERROR(INDEX([1]Discovery!$AW:$AW,MATCH(표11[[#This Row],[해양 오브젝트]],[1]Discovery!$B:$B,0)),"-") -> - | G14: =IFERROR(INDEX([1]Discovery!$AY:$AY,MATCH(표11[[#This Row],[해양 오브젝트]],[1]Discovery!$B:$B,0)),"-") -> - | H14: =IFERROR(INDEX([1]Discovery!$BA:$BA,MATCH(표11[[#This Row],[해양 오브젝트]],[1]Discovery!$B:$B,0)),"-") -> -
... B307: =[2]OceanDoodad!Z312 -> 신비한 장벽 | C307: =IFERROR(VLOOKUP(표11[[#This Row],[해양 오브젝트]],[3]!표1[[이름]:[선단 LV]],6,FALSE),"-") -> - | D307: =IFERROR(VLOOKUP(표11[[#This Row],[해양 오브젝트]],[3]!표1[[이름]:[위도]],3,FALSE),"-") -> - | E307: =IFERROR(VLOOKUP(표11[[#This Row],[해양 오브젝트]],[3]!표1[[이름]:[위도]],2,FALSE),"-") -> - | F307: =IFERROR(INDEX([1]Discovery!$AW:$AW,MATCH(표11[[#This Row],[해양 오브젝트]],[1]Discovery!$B:$B,0)),"-") -> 무조건 실패 | G307: =IFERROR(INDEX([1]Discovery!$AY:$AY,MATCH(표11[[#This Row],[해양 오브젝트]],[1]Discovery!$B:$B,0)),"-") -> 0 | H307: =IFERROR(INDEX([1]Discovery!$BA:$BA,MATCH(표11[[#This Row],[해양 오브젝트]],[1]Discovery!$B:$B,0)),"-") -> 1

Sheet 육지 배치
B2: 육지 | C2: 열1 | D2: 레벨 제한 | E2: 위도 | F2: 경도 | G2: 발견물[0] | H2: 배당[0] | I2: 확률[0] | J2: 발견물[1] | K2: 배당[1] | L2: 확률[1] | M2: 발견물[2] | N2: 배당[2] | O2: 확률[2] | P2: 발견물[3] | Q2: 배당[3] | R2: 확률[3] | S2: 발견물[4] | T2: 배당[4] | U2: 확률[4] | V2: 발견물[5] | W2: 배당[5] | X2: 확률[5] | Y2: 발견물[6] | Z2: 배당[6] | AA2: 배당[7]
B3: =[1]LandExplore!E9 -> 리스보아 부근 | C3: =INDEX([1]LandExplore!$B:$B,MATCH(표8[[#This Row],[육지]],[1]LandExplore!$E:$E,0)) -> ##이베리아 | D3: =IFERROR(VLOOKUP(표8[[#This Row],[육지]],[3]!표1_6[[이름]:[선단 LV]],6,FALSE),"-") -> - | E3: =IFERROR(VLOOKUP(표8[[#This Row],[육지]],[3]!표1_6[[이름]:[위도]],3,FALSE),"-") -> - | F3: =IFERROR(VLOOKUP(표8[[#This Row],[육지]],[3]!표1_6[[이름]:[위도]],2,FALSE),"-") -> - | G3: =INDEX([1]AdventureDiscoveryGroup!$D:$D,MATCH(표8[[#This Row],[열1]],[1]AdventureDiscoveryGroup!$B:$B,0)) -> 리스보아 부근 | H3: =IFERROR(INT(1000/POWER(1.5,VLOOKUP(G3,[1]Discovery!$B:$H,7,FALSE)^1.6)),"-") -> - | I3: =IFERROR(표8[[#This Row],[배당'[0']]]/$AB3,"-") -> - | J3: =INDEX([1]AdventureDiscoveryGroup!$I:$I,MATCH(표8[[#This Row],[열1]],[1]AdventureDiscoveryGroup!$B:$B,0)) -> FALSE | K3: =IFERROR(INT(1000/POWER(1.5,VLOOKUP(J3,[1]Discovery!$B:$H,7,FALSE)^1.6)),"-") -> - | L3: =IFERROR(표8[[#This Row],[배당'[1']]]/$AB3,"-") -> - | M3: =INDEX([1]AdventureDiscoveryGroup!$N:$N,MATCH(표8[[#This Row],[열1]],[1]AdventureDiscoveryGroup!$B:$B,0)) -> FALSE | N3: =IFERROR(INT(1000/POWER(1.5,VLOOKUP(M3,[1]Discovery!$B:$H,7,FALSE)^1.6)),"-") -> - | O3: =IFERROR(표8[[#This Row],[배당'[2']]]/$AB3,"-") -> - | P3: =INDEX([1]AdventureDiscoveryGroup!$S:$S,MATCH(표8[[#This Row],[열1]],[1]AdventureDiscoveryGroup!$B:$B,0)) -> FALSE | Q3: =IFERROR(INT(1000/POWER(1.5,VLOOKUP(P3,[1]Discovery!$B:$H,7,FALSE)^1.6)),"-") -> - | R3: =IFERROR(표8[[#This Row],[배당'[3']]]/$AB3,"-") -> - | S3: =INDEX([1]AdventureDiscoveryGroup!$X:$X,MATCH(표8[[#This Row],[열1]],[1]AdventureDiscoveryGroup!$B:$B,0)) -> FALSE | T3: =IFERROR(INT(1000/POWER(1.5,VLOOKUP(S3,[1]Discovery!$B:$H,7,FALSE)^1.6)),"-") -> - | U3: =IFERROR(표8[[#This Row],[배당'[4']]]/$AB3,"-") -> - | V3: =INDEX([1]AdventureDiscoveryGroup!$AC:$AC,MATCH(표8[[#This Row],[열1]],[1]AdventureDiscoveryGroup!$B:$B,0)) -> FALSE | W3: =IFERROR(INT(1000/POWER(1.5,VLOOKUP(V3,[1]Discovery!$B:$H,7,FALSE)^1.6)),"-") -> - | X3: =IFERROR(표8[[#This Row],[배당'[5']]]/$AB3,"-") -> - | Y3: =INDEX([1]AdventureDiscoveryGroup!$AH:$AH,MATCH(표8[[#This Row],[열1]],[1]AdventureDiscoveryGroup!$B:$B,0)) -> FALSE | Z3: =IFERROR(INT(1000/POWER(1.5,VLOOKUP(Y3,[1]Discovery!$B:$H,7,FALSE)^1.6)),"-") -> - | AA3: =IFERROR(표8[[#This Row],[배당'[6']]]/$AB3,"-") -> - | AB3: =SUM(표8[[#This Row],[배당'[0']]],표8[[#This Row],[배당'[1']]],표8[[#This Row],[배당'[2']]],표8[[#This Row],[배당'[3']]],표8[[#This Row],[배당'[4']]],표8[[#This Row],[배당'[5']]],표8[[#This Row],[배당'[6']]]) -> 0
B4: =[1]LandExplore!E10 -> 마르세유 부근 | C4: =INDEX([1]LandExplore!$B:$B,MATCH(표8[[#This Row],[육지]],[1]LandExplore!$E:$E,0)) -> ##남프랑스 | D4: =IFERROR(VLOOKUP(표8[[#This Row],[육지]],[3]!표1_6[[이름]:[선단 LV]],6,FALSE),"-") -> - | E4: =IFERROR(VLOOKUP(표8[[#This Row],[육지]],[3]!표1_6[[이름]:[위도]],3,FALSE),"-") -> - | F4: =IFERROR(VLOOKUP(표8[[#This Row],[육지]],[3]!표1_6[[이름]:[위도]],2,FALSE),"-") -> - | G4: =INDEX([1]AdventureDiscoveryGroup!$D:$D,MATCH(표8[[#This Row],[열1]],[1]AdventureDiscoveryGroup!$B:$B,0)) -> 마르세유 부근 | H4: =IFERROR(INT(1000/POWER(1.5,VLOOKUP(G4,[1]Discovery!$B:$H,7,FALSE)^1.6)),"-") -> - | I4: =IFERROR(표8[[#This Row],[배당'[0']]]/$AB4,"-") -> - | J4: =INDEX([1]AdventureDiscoveryGroup!$I:$I,MATCH(표8[[#This Row],[열1]],[1]AdventureDiscoveryGroup!$B:$B,0)) -> FALSE | K4: =IFERROR(INT(1000/POWER(1.5,VLOOKUP(J4,[1]Discovery!$B:$H,7,FALSE)^1.6)),"-") -> - | L4: =IFERROR(표8[[#This Row],[배당'[1']]]/$AB4,"-") -> - | M4: =INDEX([1]AdventureDiscoveryGroup!$N:$N,MATCH(표8[[#This Row],[열1]],[1]AdventureDiscoveryGroup!$B:$B,0)) -> FALSE | N4: =IFERROR(INT(1000/POWER(1.5,VLOOKUP(M4,[1]Discovery!$B:$H,7,FALSE)^1.6)),"-") -> - | O4: =IFERROR(표8[[#This Row],[배당'[2']]]/$AB4,"-") -> - | P4: =INDEX([1]AdventureDiscoveryGroup!$S:$S,MATCH(표8[[#This Row],[열1]],[1]AdventureDiscoveryGroup!$B:$B,0)) -> FALSE | Q4: =IFERROR(INT(1000/POWER(1.5,VLOOKUP(P4,[1]Discovery!$B:$H,7,FALSE)^1.6)),"-") -> - | R4: =IFERROR(표8[[#This Row],[배당'[3']]]/$AB4,"-") -> - | S4: =INDEX([1]AdventureDiscoveryGroup!$X:$X,MATCH(표8[[#This Row],[열1]],[1]AdventureDiscoveryGroup!$B:$B,0)) -> FALSE | T4: =IFERROR(INT(1000/POWER(1.5,VLOOKUP(S4,[1]Discovery!$B:$H,7,FALSE)^1.6)),"-") -> - | U4: =IFERROR(표8[[#This Row],[배당'[4']]]/$AB4,"-") -> - | V4: =INDEX([1]AdventureDiscoveryGroup!$AC:$AC,MATCH(표8[[#This Row],[열1]],[1]AdventureDiscoveryGroup!$B:$B,0)) -> FALSE | W4: =IFERROR(INT(1000/POWER(1.5,VLOOKUP(V4,[1]Discovery!$B:$H,7,FALSE)^1.6)),"-") -> - | X4: =IFERROR(표8[[#This Row],[배당'[5']]]/$AB4,"-") -> - | Y4: =INDEX([1]AdventureDiscoveryGroup!$AH:$AH,MATCH(표8[[#This Row],[열1]],[1]AdventureDiscoveryGroup!$B:$B,0)) -> FALSE | Z4: =IFERROR(INT(1000/POWER(1.5,VLOOKUP(Y4,[1]Discovery!$B:$H,7,FALSE)^1.6)),"-") -> - | AA4: =IFERROR(표8[[#This Row],[배당'[6']]]/$AB4,"-") -> - | AB4: =SUM(표8[[#This Row],[배당'[0']]],표8[[#This Row],[배당'[1']]],표8[[#This Row],[배당'[2']]],표8[[#This Row],[배당'[3']]],표8[[#This Row],[배당'[4']]],표8[[#This Row],[배당'[5']]],표8[[#This Row],[배당'[6']]]) -> 0
B5: =[1]LandExplore!E11 -> 나폴리 부근 | C5: =INDEX([1]LandExplore!$B:$B,MATCH(표8[[#This Row],[육지]],[1]LandExplore!$E:$E,0)) -> ##이탈리아 | D5: =IFERROR(VLOOKUP(표8[[#This Row],[육지]],[3]!표1_6[[이름]:[선단 LV]],6,FALSE),"-") -> - | E5: =IFERROR(VLOOKUP(표8[[#This Row],[육지]],[3]!표1_6[[이름]:[위도]],3,FALSE),"-") -> - | F5: =IFERROR(VLOOKUP(표8[[#This Row],[육지]],[3]!표1_6[[이름]:[위도]],2,FALSE),"-") -> - | G5: =INDEX([1]AdventureDiscoveryGroup!$D:$D,MATCH(표8[[#This Row],[열1]],[1]AdventureDiscoveryGroup!$B:$B,0)) -> 나폴리 부근 | H5: =IFERROR(INT(1000/POWER(1.5,VLOOKUP(G5,[1]Discovery!$B:$H,7,FALSE)^1.6)),"-") -> - | I5: =IFERROR(표8[[#This Row],[배당'[0']]]/$AB5,"-") -> - | J5: =INDEX([1]AdventureDiscoveryGroup!$I:$I,MATCH(표8[[#This Row],[열1]],[1]AdventureDiscoveryGroup!$B:$B,0)) -> FALSE | K5: =IFERROR(INT(1000/POWER(1.5,VLOOKUP(J5,[1]Discovery!$B:$H,7,FALSE)^1.6)),"-") -> - | L5: =IFERROR(표8[[#This Row],[배당'[1']]]/$AB5,"-") -> - | M5: =INDEX([1]AdventureDiscoveryGroup!$N:$N,MATCH(표8[[#This Row],[열1]],[1]AdventureDiscoveryGroup!$B:$B,0)) -> FALSE | N5: =IFERROR(INT(1000/POWER(1.5,VLOOKUP(M5,[1]Discovery!$B:$H,7,FALSE)^1.6)),"-") -> - | O5: =IFERROR(표8[[#This Row],[배당'[2']]]/$AB5,"-") -> - | P5: =INDEX([1]AdventureDiscoveryGroup!$S:$S,MATCH(표8[[#This Row],[열1]],[1]AdventureDiscoveryGroup!$B:$B,0)) -> FALSE | Q5: =IFERROR(INT(1000/POWER(1.5,VLOOKUP(P5,[1]Discovery!$B:$H,7,FALSE)^1.6)),"-") -> - | R5: =IFERROR(표8[[#This Row],[배당'[3']]]/$AB5,"-") -> - | S5: =INDEX([1]AdventureDiscoveryGroup!$X:$X,MATCH(표8[[#This Row],[열1]],[1]AdventureDiscoveryGroup!$B:$B,0)) -> FALSE | T5: =IFERROR(INT(1000/POWER(1.5,VLOOKUP(S5,[1]Discovery!$B:$H,7,FALSE)^1.6)),"-") -> - | U5: =IFERROR(표8[[#This Row],[배당'[4']]]/$AB5,"-") -> - | V5: =INDEX([1]AdventureDiscoveryGroup!$AC:$AC,MATCH(표8[[#This Row],[열1]],[1]AdventureDiscoveryGroup!$B:$B,0)) -> FALSE | W5: =IFERROR(INT(1000/POWER(1.5,VLOOKUP(V5,[1]Discovery!$B:$H,7,FALSE)^1.6)),"-") -> - | X5: =IFERROR(표8[[#This Row],[배당'[5']]]/$AB5,"-") -> - | Y5: =INDEX([1]AdventureDiscoveryGroup!$AH:$AH,MATCH(표8[[#This Row],[열1]],[1]AdventureDiscoveryGroup!$B:$B,0)) -> FALSE | Z5: =IFERROR(INT(1000/POWER(1.5,VLOOKUP(Y5,[1]Discovery!$B:$H,7,FALSE)^1.6)),"-") -> - | AA5: =IFERROR(표8[[#This Row],[배당'[6']]]/$AB5,"-") -> - | AB5: =SUM(표8[[#This Row],[배당'[0']]],표8[[#This Row],[배당'[1']]],표8[[#This Row],[배당'[2']]],표8[[#This Row],[배당'[3']]],표8[[#This Row],[배당'[4']]],표8[[#This Row],[배당'[5']]],표8[[#This Row],[배당'[6']]]) -> 0
B6: =[1]LandExplore!E12 -> 아티나 부근 | C6: =INDEX([1]LandExplore!$B:$B,MATCH(표8[[#This Row],[육지]],[1]LandExplore!$E:$E,0)) -> ##발칸 | D6: =IFERROR(VLOOKUP(표8[[#This Row],[육지]],[3]!표1_6[[이름]:[선단 LV]],6,FALSE),"-") -> - | E6: =IFERROR(VLOOKUP(표8[[#This Row],[육지]],[3]!표1_6[[이름]:[위도]],3,FALSE),"-") -> - | F6: =IFERROR(VLOOKUP(표8[[#This Row],[육지]],[3]!표1_6[[이름]:[위도]],2,FALSE),"-") -> - | G6: =INDEX([1]AdventureDiscoveryGroup!$D:$D,MATCH(표8[[#This Row],[열1]],[1]AdventureDiscoveryGroup!$B:$B,0)) -> 아티나 부근 | H6: =IFERROR(INT(1000/POWER(1.5,VLOOKUP(G6,[1]Discovery!$B:$H,7,FALSE)^1.6)),"-") -> - | I6: =IFERROR(표8[[#This Row],[배당'[0']]]/$AB6,"-") -> - | J6: =INDEX([1]AdventureDiscoveryGroup!$I:$I,MATCH(표8[[#This Row],[열1]],[1]AdventureDiscoveryGroup!$B:$B,0)) -> FALSE | K6: =IFERROR(INT(1000/POWER(1.5,VLOOKUP(J6,[1]Discovery!$B:$H,7,FALSE)^1.6)),"-") -> - | L6: =IFERROR(표8[[#This Row],[배당'[1']]]/$AB6,"-") -> - | M6: =INDEX([1]AdventureDiscoveryGroup!$N:$N,MATCH(표8[[#This Row],[열1]],[1]AdventureDiscoveryGroup!$B:$B,0)) -> FALSE | N6: =IFERROR(INT(1000/POWER(1.5,VLOOKUP(M6,[1]Discovery!$B:$H,7,FALSE)^1.6)),"-") -> - | O6: =IFERROR(표8[[#This Row],[배당'[2']]]/$AB6,"-") -> - | P6: =INDEX([1]AdventureDiscoveryGroup!$S:$S,MATCH(표8[[#This Row],[열1]],[1]AdventureDiscoveryGroup!$B:$B,0)) -> FALSE | Q6: =IFERROR(INT(1000/POWER(1.5,VLOOKUP(P6,[1]Discovery!$B:$H,7,FALSE)^1.6)),"-") -> - | R6: =IFERROR(표8[[#This Row],[배당'[3']]]/$AB6,"-") -> - | S6: =INDEX([1]AdventureDiscoveryGroup!$X:$X,MATCH(표8[[#This Row],[열1]],[1]AdventureDiscoveryGroup!$B:$B,0)) -> FALSE | T6: =IFERROR(INT(1000/POWER(1.5,VLOOKUP(S6,[1]Discovery!$B:$H,7,FALSE)^1.6)),"-") -> - | U6: =IFERROR(표8[[#This Row],[배당'[4']]]/$AB6,"-") -> - | V6: =INDEX([1]AdventureDiscoveryGroup!$AC:$AC,MATCH(표8[[#This Row],[열1]],[1]AdventureDiscoveryGroup!$B:$B,0)) -> FALSE | W6: =IFERROR(INT(1000/POWER(1.5,VLOOKUP(V6,[1]Discovery!$B:$H,7,FALSE)^1.6)),"-") -> - | X6: =IFERROR(표8[[#This Row],[배당'[5']]]/$AB6,"-") -> - | Y6: =INDEX([1]AdventureDiscoveryGroup!$AH:$AH,MATCH(표8[[#This Row],[열1]],[1]AdventureDiscoveryGroup!$B:$B,0)) -> FALSE | Z6: =IFERROR(INT(1000/POWER(1.5,VLOOKUP(Y6,[1]Discovery!$B:$H,7,FALSE)^1.6)),"-") -> - | AA6: =IFERROR(표8[[#This Row],[배당'[6']]]/$AB6,"-") -> - | AB6: =SUM(표8[[#This Row],[배당'[0']]],표8[[#This Row],[배당'[1']]],표8[[#This Row],[배당'[2']]],표8[[#This Row],[배당'[3']]],표8[[#This Row],[배당'[4']]],표8[[#This Row],[배당'[5']]],표8[[#This Row],[배당'[6']]]) -> 0
